{
  "version": 8,
  "blockIdVersion": 11,
  "anchorX": 0,
  "anchorY": 0,
  "anchorZ": 0,
  "blocks": [
    {
      "x": -11,
      "y": 28,
      "z": -6,
      "name": "Cloth_Block_Wool_White_Half",
      "rotation": 7
    },
    {
      "x": -11,
      "y": 29,
      "z": -6,
      "name": "Cloth_Block_Wool_White_Half",
      "rotation": 7
    },
    {
      "x": -11,
      "y": 30,
      "z": -6,
      "name": "Cloth_Block_Wool_White_Half",
      "rotation": 7
    },
    {
      "x": -10,
      "y": 28,
      "z": -9,
      "name": "Cloth_Block_Wool_Green"
    },
    {
      "x": -10,
      "y": 29,
      "z": -9,
      "name": "Cloth_Block_Wool_Green"
    },
    {
      "x": -10,
      "y": 30,
      "z": -9,
      "name": "Cloth_Block_Wool_Green"
    },
    {
      "x": -10,
      "y": 27,
      "z": -8,
      "name": "Cloth_Block_Wool_Green"
    },
    {
      "x": -10,
      "y": 28,
      "z": -8,
      "name": "Cloth_Block_Wool_Green"
    },
    {
      "x": -10,
      "y": 29,
      "z": -8,
      "name": "Cloth_Block_Wool_Green"
    },
    {
      "x": -10,
      "y": 30,
      "z": -8,
      "name": "Cloth_Block_Wool_Green"
    },
    {
      "x": -10,
      "y": 31,
      "z": -8,
      "name": "Cloth_Block_Wool_Green"
    },
    {
      "x": -10,
      "y": 26,
      "z": -7,
      "name": "Cloth_Block_Wool_White"
    },
    {
      "x": -10,
      "y": 27,
      "z": -7,
      "name": "Cloth_Block_Wool_White"
    },
    {
      "x": -10,
      "y": 28,
      "z": -7,
      "name": "Cloth_Block_Wool_White"
    },
    {
      "x": -10,
      "y": 29,
      "z": -7,
      "name": "Cloth_Block_Wool_White"
    },
    {
      "x": -10,
      "y": 30,
      "z": -7,
      "name": "Cloth_Block_Wool_White"
    },
    {
      "x": -10,
      "y": 31,
      "z": -7,
      "name": "Cloth_Block_Wool_White"
    },
    {
      "x": -10,
      "y": 32,
      "z": -7,
      "name": "Cloth_Block_Wool_White"
    },
    {
      "x": -10,
      "y": 26,
      "z": -6,
      "name": "Cloth_Block_Wool_White"
    },
    {
      "x": -10,
      "y": 27,
      "z": -6,
      "name": "Cloth_Block_Wool_White"
    },
    {
      "x": -10,
      "y": 31,
      "z": -6,
      "name": "Cloth_Block_Wool_White"
    },
    {
      "x": -10,
      "y": 32,
      "z": -6,
      "name": "Cloth_Block_Wool_White"
    },
    {
      "x": -10,
      "y": 26,
      "z": -5,
      "name": "Cloth_Block_Wool_White"
    },
    {
      "x": -10,
      "y": 27,
      "z": -5,
      "name": "Cloth_Block_Wool_White"
    },
    {
      "x": -10,
      "y": 28,
      "z": -5,
      "name": "Cloth_Block_Wool_White"
    },
    {
      "x": -10,
      "y": 29,
      "z": -5,
      "name": "Cloth_Block_Wool_White"
    },
    {
      "x": -10,
      "y": 30,
      "z": -5,
      "name": "Cloth_Block_Wool_White"
    },
    {
      "x": -10,
      "y": 31,
      "z": -5,
      "name": "Cloth_Block_Wool_White"
    },
    {
      "x": -10,
      "y": 32,
      "z": -5,
      "name": "Cloth_Block_Wool_White"
    },
    {
      "x": -10,
      "y": 27,
      "z": -4,
      "name": "Cloth_Block_Wool_Green"
    },
    {
      "x": -10,
      "y": 28,
      "z": -4,
      "name": "Cloth_Block_Wool_Green"
    },
    {
      "x": -10,
      "y": 29,
      "z": -4,
      "name": "Cloth_Block_Wool_Green"
    },
    {
      "x": -10,
      "y": 30,
      "z": -4,
      "name": "Cloth_Block_Wool_Green"
    },
    {
      "x": -10,
      "y": 31,
      "z": -4,
      "name": "Cloth_Block_Wool_Green"
    },
    {
      "x": -10,
      "y": 28,
      "z": -3,
      "name": "Cloth_Block_Wool_Green"
    },
    {
      "x": -10,
      "y": 29,
      "z": -3,
      "name": "Cloth_Block_Wool_Green"
    },
    {
      "x": -10,
      "y": 30,
      "z": -3,
      "name": "Cloth_Block_Wool_Green"
    },
    {
      "x": -9,
      "y": 27,
      "z": -11,
      "name": "Cloth_Block_Wool_Green"
    },
    {
      "x": -9,
      "y": 28,
      "z": -11,
      "name": "Cloth_Block_Wool_Green"
    },
    {
      "x": -9,
      "y": 29,
      "z": -11,
      "name": "Cloth_Block_Wool_Green"
    },
    {
      "x": -9,
      "y": 30,
      "z": -11,
      "name": "Cloth_Block_Wool_Green"
    },
    {
      "x": -9,
      "y": 31,
      "z": -11,
      "name": "Cloth_Block_Wool_Green"
    },
    {
      "x": -9,
      "y": 26,
      "z": -10,
      "name": "Cloth_Block_Wool_Green"
    },
    {
      "x": -9,
      "y": 27,
      "z": -10,
      "name": "Cloth_Block_Wool_Green"
    },
    {
      "x": -9,
      "y": 28,
      "z": -10,
      "name": "Cloth_Block_Wool_Green"
    },
    {
      "x": -9,
      "y": 29,
      "z": -10,
      "name": "Cloth_Block_Wool_Green"
    },
    {
      "x": -9,
      "y": 30,
      "z": -10,
      "name": "Cloth_Block_Wool_Green"
    },
    {
      "x": -9,
      "y": 31,
      "z": -10,
      "name": "Cloth_Block_Wool_Green"
    },
    {
      "x": -9,
      "y": 32,
      "z": -10,
      "name": "Cloth_Block_Wool_Green"
    },
    {
      "x": -9,
      "y": 25,
      "z": -9,
      "name": "Cloth_Block_Wool_Green"
    },
    {
      "x": -9,
      "y": 26,
      "z": -9,
      "name": "Cloth_Block_Wool_Green"
    },
    {
      "x": -9,
      "y": 27,
      "z": -9,
      "name": "Cloth_Block_Wool_Green"
    },
    {
      "x": -9,
      "y": 31,
      "z": -9,
      "name": "Cloth_Block_Wool_Green"
    },
    {
      "x": -9,
      "y": 32,
      "z": -9,
      "name": "Cloth_Block_Wool_Green"
    },
    {
      "x": -9,
      "y": 33,
      "z": -9,
      "name": "Cloth_Block_Wool_Green"
    },
    {
      "x": -9,
      "y": 24,
      "z": -8,
      "name": "Cloth_Block_Wool_Green"
    },
    {
      "x": -9,
      "y": 25,
      "z": -8,
      "name": "Cloth_Block_Wool_Green"
    },
    {
      "x": -9,
      "y": 26,
      "z": -8,
      "name": "Cloth_Block_Wool_Green"
    },
    {
      "x": -9,
      "y": 32,
      "z": -8,
      "name": "Cloth_Block_Wool_Green"
    },
    {
      "x": -9,
      "y": 33,
      "z": -8,
      "name": "Cloth_Block_Wool_Green"
    },
    {
      "x": -9,
      "y": 34,
      "z": -8,
      "name": "Cloth_Block_Wool_Green"
    },
    {
      "x": -9,
      "y": 24,
      "z": -7,
      "name": "Cloth_Block_Wool_White"
    },
    {
      "x": -9,
      "y": 25,
      "z": -7,
      "name": "Cloth_Block_Wool_White"
    },
    {
      "x": -9,
      "y": 33,
      "z": -7,
      "name": "Cloth_Block_Wool_White"
    },
    {
      "x": -9,
      "y": 34,
      "z": -7,
      "name": "Cloth_Block_Wool_White"
    },
    {
      "x": -9,
      "y": 24,
      "z": -6,
      "name": "Cloth_Block_Wool_White"
    },
    {
      "x": -9,
      "y": 25,
      "z": -6,
      "name": "Cloth_Block_Wool_White"
    },
    {
      "x": -9,
      "y": 33,
      "z": -6,
      "name": "Cloth_Block_Wool_White"
    },
    {
      "x": -9,
      "y": 34,
      "z": -6,
      "name": "Cloth_Block_Wool_White"
    },
    {
      "x": -9,
      "y": 24,
      "z": -5,
      "name": "Cloth_Block_Wool_White"
    },
    {
      "x": -9,
      "y": 25,
      "z": -5,
      "name": "Cloth_Block_Wool_White"
    },
    {
      "x": -9,
      "y": 33,
      "z": -5,
      "name": "Cloth_Block_Wool_White"
    },
    {
      "x": -9,
      "y": 34,
      "z": -5,
      "name": "Cloth_Block_Wool_White"
    },
    {
      "x": -9,
      "y": 24,
      "z": -4,
      "name": "Cloth_Block_Wool_Green"
    },
    {
      "x": -9,
      "y": 25,
      "z": -4,
      "name": "Cloth_Block_Wool_Green"
    },
    {
      "x": -9,
      "y": 26,
      "z": -4,
      "name": "Cloth_Block_Wool_Green"
    },
    {
      "x": -9,
      "y": 32,
      "z": -4,
      "name": "Cloth_Block_Wool_Green"
    },
    {
      "x": -9,
      "y": 33,
      "z": -4,
      "name": "Cloth_Block_Wool_Green"
    },
    {
      "x": -9,
      "y": 34,
      "z": -4,
      "name": "Cloth_Block_Wool_Green"
    },
    {
      "x": -9,
      "y": 25,
      "z": -3,
      "name": "Cloth_Block_Wool_Green"
    },
    {
      "x": -9,
      "y": 26,
      "z": -3,
      "name": "Cloth_Block_Wool_Green"
    },
    {
      "x": -9,
      "y": 27,
      "z": -3,
      "name": "Cloth_Block_Wool_Green"
    },
    {
      "x": -9,
      "y": 31,
      "z": -3,
      "name": "Cloth_Block_Wool_Green"
    },
    {
      "x": -9,
      "y": 32,
      "z": -3,
      "name": "Cloth_Block_Wool_Green"
    },
    {
      "x": -9,
      "y": 33,
      "z": -3,
      "name": "Cloth_Block_Wool_Green"
    },
    {
      "x": -9,
      "y": 26,
      "z": -2,
      "name": "Cloth_Block_Wool_Green"
    },
    {
      "x": -9,
      "y": 27,
      "z": -2,
      "name": "Cloth_Block_Wool_Green"
    },
    {
      "x": -9,
      "y": 28,
      "z": -2,
      "name": "Cloth_Block_Wool_Green"
    },
    {
      "x": -9,
      "y": 29,
      "z": -2,
      "name": "Cloth_Block_Wool_Green"
    },
    {
      "x": -9,
      "y": 30,
      "z": -2,
      "name": "Cloth_Block_Wool_Green"
    },
    {
      "x": -9,
      "y": 31,
      "z": -2,
      "name": "Cloth_Block_Wool_Green"
    },
    {
      "x": -9,
      "y": 32,
      "z": -2,
      "name": "Cloth_Block_Wool_Green"
    },
    {
      "x": -9,
      "y": 27,
      "z": -1,
      "name": "Cloth_Block_Wool_Green"
    },
    {
      "x": -9,
      "y": 28,
      "z": -1,
      "name": "Cloth_Block_Wool_Green"
    },
    {
      "x": -9,
      "y": 29,
      "z": -1,
      "name": "Cloth_Block_Wool_Green"
    },
    {
      "x": -9,
      "y": 30,
      "z": -1,
      "name": "Cloth_Block_Wool_Green"
    },
    {
      "x": -9,
      "y": 31,
      "z": -1,
      "name": "Cloth_Block_Wool_Green"
    },
    {
      "x": -8,
      "y": 26,
      "z": -12,
      "name": "Cloth_Block_Wool_White"
    },
    {
      "x": -8,
      "y": 27,
      "z": -12,
      "name": "Cloth_Block_Wool_White"
    },
    {
      "x": -8,
      "y": 28,
      "z": -12,
      "name": "Cloth_Block_Wool_White"
    },
    {
      "x": -8,
      "y": 29,
      "z": -12,
      "name": "Cloth_Block_Wool_White"
    },
    {
      "x": -8,
      "y": 30,
      "z": -12,
      "name": "Cloth_Block_Wool_White"
    },
    {
      "x": -8,
      "y": 31,
      "z": -12,
      "name": "Cloth_Block_Wool_White"
    },
    {
      "x": -8,
      "y": 32,
      "z": -12,
      "name": "Cloth_Block_Wool_White"
    },
    {
      "x": -8,
      "y": 25,
      "z": -11,
      "name": "Cloth_Block_Wool_Green"
    },
    {
      "x": -8,
      "y": 26,
      "z": -11,
      "name": "Cloth_Block_Wool_Green"
    },
    {
      "x": -8,
      "y": 32,
      "z": -11,
      "name": "Cloth_Block_Wool_Green"
    },
    {
      "x": -8,
      "y": 33,
      "z": -11,
      "name": "Cloth_Block_Wool_Green"
    },
    {
      "x": -8,
      "y": 24,
      "z": -10,
      "name": "Cloth_Block_Wool_Green"
    },
    {
      "x": -8,
      "y": 25,
      "z": -10,
      "name": "Cloth_Block_Wool_Green"
    },
    {
      "x": -8,
      "y": 33,
      "z": -10,
      "name": "Cloth_Block_Wool_Green"
    },
    {
      "x": -8,
      "y": 34,
      "z": -10,
      "name": "Cloth_Block_Wool_Green"
    },
    {
      "x": -8,
      "y": 23,
      "z": -9,
      "name": "Cloth_Block_Wool_Green"
    },
    {
      "x": -8,
      "y": 24,
      "z": -9,
      "name": "Cloth_Block_Wool_Green"
    },
    {
      "x": -8,
      "y": 34,
      "z": -9,
      "name": "Cloth_Block_Wool_Green"
    },
    {
      "x": -8,
      "y": 35,
      "z": -9,
      "name": "Cloth_Block_Wool_Green"
    },
    {
      "x": -8,
      "y": 23,
      "z": -8,
      "name": "Cloth_Block_Wool_Green"
    },
    {
      "x": -8,
      "y": 35,
      "z": -8,
      "name": "Cloth_Block_Wool_Green"
    },
    {
      "x": -8,
      "y": 23,
      "z": -7,
      "name": "Cloth_Block_Wool_White"
    },
    {
      "x": -8,
      "y": 35,
      "z": -7,
      "name": "Cloth_Block_Wool_White"
    },
    {
      "x": -8,
      "y": 23,
      "z": -6,
      "name": "Cloth_Block_Wool_White"
    },
    {
      "x": -8,
      "y": 35,
      "z": -6,
      "name": "Cloth_Block_Wool_White"
    },
    {
      "x": -8,
      "y": 23,
      "z": -5,
      "name": "Cloth_Block_Wool_White"
    },
    {
      "x": -8,
      "y": 35,
      "z": -5,
      "name": "Cloth_Block_Wool_White"
    },
    {
      "x": -8,
      "y": 23,
      "z": -4,
      "name": "Cloth_Block_Wool_Green"
    },
    {
      "x": -8,
      "y": 35,
      "z": -4,
      "name": "Cloth_Block_Wool_Green"
    },
    {
      "x": -8,
      "y": 23,
      "z": -3,
      "name": "Cloth_Block_Wool_Green"
    },
    {
      "x": -8,
      "y": 24,
      "z": -3,
      "name": "Cloth_Block_Wool_Green"
    },
    {
      "x": -8,
      "y": 34,
      "z": -3,
      "name": "Cloth_Block_Wool_Green"
    },
    {
      "x": -8,
      "y": 35,
      "z": -3,
      "name": "Cloth_Block_Wool_Green"
    },
    {
      "x": -8,
      "y": 24,
      "z": -2,
      "name": "Cloth_Block_Wool_Green"
    },
    {
      "x": -8,
      "y": 25,
      "z": -2,
      "name": "Cloth_Block_Wool_Green"
    },
    {
      "x": -8,
      "y": 33,
      "z": -2,
      "name": "Cloth_Block_Wool_Green"
    },
    {
      "x": -8,
      "y": 34,
      "z": -2,
      "name": "Cloth_Block_Wool_Green"
    },
    {
      "x": -8,
      "y": 25,
      "z": -1,
      "name": "Cloth_Block_Wool_Green"
    },
    {
      "x": -8,
      "y": 26,
      "z": -1,
      "name": "Cloth_Block_Wool_Green"
    },
    {
      "x": -8,
      "y": 32,
      "z": -1,
      "name": "Cloth_Block_Wool_Green"
    },
    {
      "x": -8,
      "y": 33,
      "z": -1,
      "name": "Cloth_Block_Wool_Green"
    },
    {
      "x": -8,
      "y": 26,
      "z": 0,
      "name": "Cloth_Block_Wool_White"
    },
    {
      "x": -8,
      "y": 27,
      "z": 0,
      "name": "Cloth_Block_Wool_White"
    },
    {
      "x": -8,
      "y": 28,
      "z": 0,
      "name": "Cloth_Block_Wool_White"
    },
    {
      "x": -8,
      "y": 29,
      "z": 0,
      "name": "Cloth_Block_Wool_White"
    },
    {
      "x": -8,
      "y": 30,
      "z": 0,
      "name": "Cloth_Block_Wool_White"
    },
    {
      "x": -8,
      "y": 31,
      "z": 0,
      "name": "Cloth_Block_Wool_White"
    },
    {
      "x": -8,
      "y": 32,
      "z": 0,
      "name": "Cloth_Block_Wool_White"
    },
    {
      "x": -7,
      "y": 26,
      "z": -13,
      "name": "Cloth_Block_Wool_White"
    },
    {
      "x": -7,
      "y": 27,
      "z": -13,
      "name": "Cloth_Block_Wool_White"
    },
    {
      "x": -7,
      "y": 28,
      "z": -13,
      "name": "Cloth_Block_Wool_White"
    },
    {
      "x": -7,
      "y": 29,
      "z": -13,
      "name": "Cloth_Block_Wool_White"
    },
    {
      "x": -7,
      "y": 30,
      "z": -13,
      "name": "Cloth_Block_Wool_White"
    },
    {
      "x": -7,
      "y": 31,
      "z": -13,
      "name": "Cloth_Block_Wool_White"
    },
    {
      "x": -7,
      "y": 32,
      "z": -13,
      "name": "Cloth_Block_Wool_White"
    },
    {
      "x": -7,
      "y": 24,
      "z": -12,
      "name": "Cloth_Block_Wool_White"
    },
    {
      "x": -7,
      "y": 25,
      "z": -12,
      "name": "Cloth_Block_Wool_White"
    },
    {
      "x": -7,
      "y": 33,
      "z": -12,
      "name": "Cloth_Block_Wool_White"
    },
    {
      "x": -7,
      "y": 34,
      "z": -12,
      "name": "Cloth_Block_Wool_White"
    },
    {
      "x": -7,
      "y": 23,
      "z": -11,
      "name": "Cloth_Block_Wool_White"
    },
    {
      "x": -7,
      "y": 24,
      "z": -11,
      "name": "Cloth_Block_Wool_Green"
    },
    {
      "x": -7,
      "y": 25,
      "z": -11,
      "name": "Cloth_Block_Wool_White"
    },
    {
      "x": -7,
      "y": 34,
      "z": -11,
      "name": "Cloth_Block_Wool_Green"
    },
    {
      "x": -7,
      "y": 35,
      "z": -11,
      "name": "Cloth_Block_Wool_White"
    },
    {
      "x": -7,
      "y": 23,
      "z": -10,
      "name": "Cloth_Block_Wool_Green"
    },
    {
      "x": -7,
      "y": 35,
      "z": -10,
      "name": "Cloth_Block_Wool_Green"
    },
    {
      "x": -7,
      "y": 22,
      "z": -9,
      "name": "Cloth_Block_Wool_Green"
    },
    {
      "x": -7,
      "y": 36,
      "z": -9,
      "name": "Cloth_Block_Wool_Green"
    },
    {
      "x": -7,
      "y": 22,
      "z": -8,
      "name": "Cloth_Block_Wool_Green"
    },
    {
      "x": -7,
      "y": 36,
      "z": -8,
      "name": "Cloth_Block_Wool_Green"
    },
    {
      "x": -7,
      "y": 22,
      "z": -7,
      "name": "Cloth_Block_Wool_White"
    },
    {
      "x": -7,
      "y": 36,
      "z": -7,
      "name": "Cloth_Block_Wool_White"
    },
    {
      "x": -7,
      "y": 22,
      "z": -6,
      "name": "Cloth_Block_Wool_White"
    },
    {
      "x": -7,
      "y": 36,
      "z": -6,
      "name": "Cloth_Block_Wool_White"
    },
    {
      "x": -7,
      "y": 22,
      "z": -5,
      "name": "Cloth_Block_Wool_White"
    },
    {
      "x": -7,
      "y": 36,
      "z": -5,
      "name": "Cloth_Block_Wool_White"
    },
    {
      "x": -7,
      "y": 22,
      "z": -4,
      "name": "Cloth_Block_Wool_Green"
    },
    {
      "x": -7,
      "y": 36,
      "z": -4,
      "name": "Cloth_Block_Wool_Green"
    },
    {
      "x": -7,
      "y": 22,
      "z": -3,
      "name": "Cloth_Block_Wool_Green"
    },
    {
      "x": -7,
      "y": 36,
      "z": -3,
      "name": "Cloth_Block_Wool_Green"
    },
    {
      "x": -7,
      "y": 23,
      "z": -2,
      "name": "Cloth_Block_Wool_Green"
    },
    {
      "x": -7,
      "y": 35,
      "z": -2,
      "name": "Cloth_Block_Wool_Green"
    },
    {
      "x": -7,
      "y": 23,
      "z": -1,
      "name": "Cloth_Block_Wool_White"
    },
    {
      "x": -7,
      "y": 24,
      "z": -1,
      "name": "Cloth_Block_Wool_Green"
    },
    {
      "x": -7,
      "y": 25,
      "z": -1,
      "name": "Cloth_Block_Wool_White"
    },
    {
      "x": -7,
      "y": 34,
      "z": -1,
      "name": "Cloth_Block_Wool_Green"
    },
    {
      "x": -7,
      "y": 35,
      "z": -1,
      "name": "Cloth_Block_Wool_White"
    },
    {
      "x": -7,
      "y": 24,
      "z": 0,
      "name": "Cloth_Block_Wool_White"
    },
    {
      "x": -7,
      "y": 25,
      "z": 0,
      "name": "Cloth_Block_Wool_White"
    },
    {
      "x": -7,
      "y": 33,
      "z": 0,
      "name": "Cloth_Block_Wool_White"
    },
    {
      "x": -7,
      "y": 34,
      "z": 0,
      "name": "Cloth_Block_Wool_White"
    },
    {
      "x": -7,
      "y": 26,
      "z": 1,
      "name": "Cloth_Block_Wool_White"
    },
    {
      "x": -7,
      "y": 27,
      "z": 1,
      "name": "Cloth_Block_Wool_White"
    },
    {
      "x": -7,
      "y": 28,
      "z": 1,
      "name": "Cloth_Block_Wool_White"
    },
    {
      "x": -7,
      "y": 29,
      "z": 1,
      "name": "Cloth_Block_Wool_White"
    },
    {
      "x": -7,
      "y": 30,
      "z": 1,
      "name": "Cloth_Block_Wool_White"
    },
    {
      "x": -7,
      "y": 31,
      "z": 1,
      "name": "Cloth_Block_Wool_White"
    },
    {
      "x": -7,
      "y": 32,
      "z": 1,
      "name": "Cloth_Block_Wool_White"
    },
    {
      "x": -6,
      "y": 26,
      "z": -14,
      "name": "Cloth_Block_Wool_White"
    },
    {
      "x": -6,
      "y": 27,
      "z": -14,
      "name": "Cloth_Block_Wool_White"
    },
    {
      "x": -6,
      "y": 28,
      "z": -14,
      "name": "Cloth_Block_Wool_White"
    },
    {
      "x": -6,
      "y": 29,
      "z": -14,
      "name": "Cloth_Block_Wool_White"
    },
    {
      "x": -6,
      "y": 30,
      "z": -14,
      "name": "Cloth_Block_Wool_White"
    },
    {
      "x": -6,
      "y": 31,
      "z": -14,
      "name": "Cloth_Block_Wool_White"
    },
    {
      "x": -6,
      "y": 32,
      "z": -14,
      "name": "Cloth_Block_Wool_White"
    },
    {
      "x": -6,
      "y": 24,
      "z": -13,
      "name": "Cloth_Block_Wool_White"
    },
    {
      "x": -6,
      "y": 25,
      "z": -13,
      "name": "Cloth_Block_Wool_White"
    },
    {
      "x": -6,
      "y": 33,
      "z": -13,
      "name": "Cloth_Block_Wool_White"
    },
    {
      "x": -6,
      "y": 34,
      "z": -13,
      "name": "Cloth_Block_Wool_White"
    },
    {
      "x": -6,
      "y": 23,
      "z": -12,
      "name": "Cloth_Block_Wool_White"
    },
    {
      "x": -6,
      "y": 35,
      "z": -12,
      "name": "Cloth_Block_Wool_White"
    },
    {
      "x": -6,
      "y": 22,
      "z": -11,
      "name": "Cloth_Block_Wool_White"
    },
    {
      "x": -6,
      "y": 35,
      "z": -11,
      "name": "Cloth_Block_Wool_White"
    },
    {
      "x": -6,
      "y": 36,
      "z": -11,
      "name": "Cloth_Block_Wool_White"
    },
    {
      "x": -6,
      "y": 22,
      "z": -10,
      "name": "Cloth_Block_Wool_Green"
    },
    {
      "x": -6,
      "y": 36,
      "z": -10,
      "name": "Cloth_Block_Wool_Green"
    },
    {
      "x": -6,
      "y": 21,
      "z": -9,
      "name": "Cloth_Block_Wool_Green"
    },
    {
      "x": -6,
      "y": 37,
      "z": -9,
      "name": "Cloth_Block_Wool_Green"
    },
    {
      "x": -6,
      "y": 21,
      "z": -8,
      "name": "Cloth_Block_Wool_Green"
    },
    {
      "x": -6,
      "y": 37,
      "z": -8,
      "name": "Cloth_Block_Wool_Green"
    },
    {
      "x": -6,
      "y": 21,
      "z": -7,
      "name": "Cloth_Block_Wool_White"
    },
    {
      "x": -6,
      "y": 37,
      "z": -7,
      "name": "Cloth_Block_Wool_White"
    },
    {
      "x": -6,
      "y": 21,
      "z": -6,
      "name": "Cloth_Block_Wool_White"
    },
    {
      "x": -6,
      "y": 37,
      "z": -6,
      "name": "Cloth_Block_Wool_White"
    },
    {
      "x": -6,
      "y": 21,
      "z": -5,
      "name": "Cloth_Block_Wool_White"
    },
    {
      "x": -6,
      "y": 37,
      "z": -5,
      "name": "Cloth_Block_Wool_White"
    },
    {
      "x": -6,
      "y": 21,
      "z": -4,
      "name": "Cloth_Block_Wool_Green"
    },
    {
      "x": -6,
      "y": 37,
      "z": -4,
      "name": "Cloth_Block_Wool_Green"
    },
    {
      "x": -6,
      "y": 21,
      "z": -3,
      "name": "Cloth_Block_Wool_Green"
    },
    {
      "x": -6,
      "y": 37,
      "z": -3,
      "name": "Cloth_Block_Wool_Green"
    },
    {
      "x": -6,
      "y": 22,
      "z": -2,
      "name": "Cloth_Block_Wool_Green"
    },
    {
      "x": -6,
      "y": 36,
      "z": -2,
      "name": "Cloth_Block_Wool_Green"
    },
    {
      "x": -6,
      "y": 22,
      "z": -1,
      "name": "Cloth_Block_Wool_White"
    },
    {
      "x": -6,
      "y": 23,
      "z": -1,
      "name": "Cloth_Block_Wool_White"
    },
    {
      "x": -6,
      "y": 36,
      "z": -1,
      "name": "Cloth_Block_Wool_White"
    },
    {
      "x": -6,
      "y": 23,
      "z": 0,
      "name": "Cloth_Block_Wool_White"
    },
    {
      "x": -6,
      "y": 35,
      "z": 0,
      "name": "Cloth_Block_Wool_White"
    },
    {
      "x": -6,
      "y": 24,
      "z": 1,
      "name": "Cloth_Block_Wool_White"
    },
    {
      "x": -6,
      "y": 25,
      "z": 1,
      "name": "Cloth_Block_Wool_White"
    },
    {
      "x": -6,
      "y": 33,
      "z": 1,
      "name": "Cloth_Block_Wool_White"
    },
    {
      "x": -6,
      "y": 34,
      "z": 1,
      "name": "Cloth_Block_Wool_White"
    },
    {
      "x": -6,
      "y": 26,
      "z": 2,
      "name": "Cloth_Block_Wool_White"
    },
    {
      "x": -6,
      "y": 27,
      "z": 2,
      "name": "Cloth_Block_Wool_White"
    },
    {
      "x": -6,
      "y": 28,
      "z": 2,
      "name": "Cloth_Block_Wool_White"
    },
    {
      "x": -6,
      "y": 29,
      "z": 2,
      "name": "Cloth_Block_Wool_White"
    },
    {
      "x": -6,
      "y": 30,
      "z": 2,
      "name": "Cloth_Block_Wool_White"
    },
    {
      "x": -6,
      "y": 31,
      "z": 2,
      "name": "Cloth_Block_Wool_White"
    },
    {
      "x": -6,
      "y": 32,
      "z": 2,
      "name": "Cloth_Block_Wool_White"
    },
    {
      "x": -5,
      "y": 27,
      "z": -15,
      "name": "Cloth_Block_Wool_Green"
    },
    {
      "x": -5,
      "y": 28,
      "z": -15,
      "name": "Cloth_Block_Wool_Green"
    },
    {
      "x": -5,
      "y": 29,
      "z": -15,
      "name": "Cloth_Block_Wool_Green"
    },
    {
      "x": -5,
      "y": 30,
      "z": -15,
      "name": "Cloth_Block_Wool_Green"
    },
    {
      "x": -5,
      "y": 31,
      "z": -15,
      "name": "Cloth_Block_Wool_Green"
    },
    {
      "x": -5,
      "y": 25,
      "z": -14,
      "name": "Cloth_Block_Wool_Green"
    },
    {
      "x": -5,
      "y": 26,
      "z": -14,
      "name": "Cloth_Block_Wool_Green"
    },
    {
      "x": -5,
      "y": 32,
      "z": -14,
      "name": "Cloth_Block_Wool_Green"
    },
    {
      "x": -5,
      "y": 33,
      "z": -14,
      "name": "Cloth_Block_Wool_Green"
    },
    {
      "x": -5,
      "y": 23,
      "z": -13,
      "name": "Cloth_Block_Wool_White"
    },
    {
      "x": -5,
      "y": 24,
      "z": -13,
      "name": "Cloth_Block_Wool_Green"
    },
    {
      "x": -5,
      "y": 25,
      "z": -13,
      "name": "Cloth_Block_Wool_White"
    },
    {
      "x": -5,
      "y": 34,
      "z": -13,
      "name": "Cloth_Block_Wool_Green"
    },
    {
      "x": -5,
      "y": 35,
      "z": -13,
      "name": "Cloth_Block_Wool_White"
    },
    {
      "x": -5,
      "y": 22,
      "z": -12,
      "name": "Cloth_Block_Wool_White"
    },
    {
      "x": -5,
      "y": 23,
      "z": -12,
      "name": "Cloth_Block_Wool_White"
    },
    {
      "x": -5,
      "y": 36,
      "z": -12,
      "name": "Cloth_Block_Wool_White"
    },
    {
      "x": -5,
      "y": 22,
      "z": -11,
      "name": "Cloth_Block_Wool_White"
    },
    {
      "x": -5,
      "y": 36,
      "z": -11,
      "name": "Cloth_Block_Wool_White"
    },
    {
      "x": -5,
      "y": 21,
      "z": -10,
      "name": "Cloth_Block_Wool_White"
    },
    {
      "x": -5,
      "y": 37,
      "z": -10,
      "name": "Cloth_Block_Wool_White"
    },
    {
      "x": -5,
      "y": 21,
      "z": -9,
      "name": "Cloth_Block_Wool_Green"
    },
    {
      "x": -5,
      "y": 37,
      "z": -9,
      "name": "Cloth_Block_Wool_Green"
    },
    {
      "x": -5,
      "y": 20,
      "z": -8,
      "name": "Cloth_Block_Wool_Green"
    },
    {
      "x": -5,
      "y": 38,
      "z": -8,
      "name": "Cloth_Block_Wool_Green"
    },
    {
      "x": -5,
      "y": 19,
      "z": -7,
      "name": "Cloth_Block_Wool_Green"
    },
    {
      "x": -5,
      "y": 20,
      "z": -7,
      "name": "Cloth_Block_Wool_Green"
    },
    {
      "x": -5,
      "y": 38,
      "z": -7,
      "name": "Cloth_Block_Wool_White"
    },
    {
      "x": -5,
      "y": 19,
      "z": -6,
      "name": "Cloth_Block_Wool_White"
    },
    {
      "x": -5,
      "y": 20,
      "z": -6,
      "name": "Cloth_Block_Wool_White"
    },
    {
      "x": -5,
      "y": 38,
      "z": -6,
      "name": "Cloth_Block_Wool_White"
    },
    {
      "x": -5,
      "y": 19,
      "z": -5,
      "name": "Cloth_Block_Wool_Green"
    },
    {
      "x": -5,
      "y": 20,
      "z": -5,
      "name": "Cloth_Block_Wool_Green"
    },
    {
      "x": -5,
      "y": 38,
      "z": -5,
      "name": "Cloth_Block_Wool_White"
    },
    {
      "x": -5,
      "y": 20,
      "z": -4,
      "name": "Cloth_Block_Wool_Green"
    },
    {
      "x": -5,
      "y": 38,
      "z": -4,
      "name": "Cloth_Block_Wool_Green"
    },
    {
      "x": -5,
      "y": 21,
      "z": -3,
      "name": "Cloth_Block_Wool_Green"
    },
    {
      "x": -5,
      "y": 37,
      "z": -3,
      "name": "Cloth_Block_Wool_Green"
    },
    {
      "x": -5,
      "y": 21,
      "z": -2,
      "name": "Cloth_Block_Wool_White"
    },
    {
      "x": -5,
      "y": 37,
      "z": -2,
      "name": "Cloth_Block_Wool_White"
    },
    {
      "x": -5,
      "y": 22,
      "z": -1,
      "name": "Cloth_Block_Wool_White"
    },
    {
      "x": -5,
      "y": 36,
      "z": -1,
      "name": "Cloth_Block_Wool_White"
    },
    {
      "x": -5,
      "y": 22,
      "z": 0,
      "name": "Cloth_Block_Wool_White"
    },
    {
      "x": -5,
      "y": 35,
      "z": 0,
      "name": "Cloth_Block_Wool_White"
    },
    {
      "x": -5,
      "y": 36,
      "z": 0,
      "name": "Cloth_Block_Wool_White"
    },
    {
      "x": -5,
      "y": 23,
      "z": 1,
      "name": "Cloth_Block_Wool_White"
    },
    {
      "x": -5,
      "y": 24,
      "z": 1,
      "name": "Cloth_Block_Wool_Green"
    },
    {
      "x": -5,
      "y": 25,
      "z": 1,
      "name": "Cloth_Block_Wool_White"
    },
    {
      "x": -5,
      "y": 34,
      "z": 1,
      "name": "Cloth_Block_Wool_Green"
    },
    {
      "x": -5,
      "y": 35,
      "z": 1,
      "name": "Cloth_Block_Wool_White"
    },
    {
      "x": -5,
      "y": 25,
      "z": 2,
      "name": "Cloth_Block_Wool_Green"
    },
    {
      "x": -5,
      "y": 26,
      "z": 2,
      "name": "Cloth_Block_Wool_Green"
    },
    {
      "x": -5,
      "y": 32,
      "z": 2,
      "name": "Cloth_Block_Wool_Green"
    },
    {
      "x": -5,
      "y": 33,
      "z": 2,
      "name": "Cloth_Block_Wool_Green"
    },
    {
      "x": -5,
      "y": 27,
      "z": 3,
      "name": "Cloth_Block_Wool_Green"
    },
    {
      "x": -5,
      "y": 28,
      "z": 3,
      "name": "Cloth_Block_Wool_Green"
    },
    {
      "x": -5,
      "y": 29,
      "z": 3,
      "name": "Cloth_Block_Wool_Green"
    },
    {
      "x": -5,
      "y": 30,
      "z": 3,
      "name": "Cloth_Block_Wool_Green"
    },
    {
      "x": -5,
      "y": 31,
      "z": 3,
      "name": "Cloth_Block_Wool_Green"
    },
    {
      "x": -4,
      "y": 26,
      "z": -15,
      "name": "Cloth_Block_Wool_Green"
    },
    {
      "x": -4,
      "y": 27,
      "z": -15,
      "name": "Cloth_Block_Wool_Green"
    },
    {
      "x": -4,
      "y": 28,
      "z": -15,
      "name": "Cloth_Block_Wool_Green"
    },
    {
      "x": -4,
      "y": 29,
      "z": -15,
      "name": "Cloth_Block_Wool_Green"
    },
    {
      "x": -4,
      "y": 30,
      "z": -15,
      "name": "Cloth_Block_Wool_Green"
    },
    {
      "x": -4,
      "y": 31,
      "z": -15,
      "name": "Cloth_Block_Wool_Green"
    },
    {
      "x": -4,
      "y": 32,
      "z": -15,
      "name": "Cloth_Block_Wool_Green"
    },
    {
      "x": -4,
      "y": 24,
      "z": -14,
      "name": "Cloth_Block_Wool_Green"
    },
    {
      "x": -4,
      "y": 25,
      "z": -14,
      "name": "Cloth_Block_Wool_Green"
    },
    {
      "x": -4,
      "y": 33,
      "z": -14,
      "name": "Cloth_Block_Wool_Green"
    },
    {
      "x": -4,
      "y": 34,
      "z": -14,
      "name": "Cloth_Block_Wool_Green"
    },
    {
      "x": -4,
      "y": 23,
      "z": -13,
      "name": "Cloth_Block_Wool_Green"
    },
    {
      "x": -4,
      "y": 35,
      "z": -13,
      "name": "Cloth_Block_Wool_Green"
    },
    {
      "x": -4,
      "y": 22,
      "z": -12,
      "name": "Cloth_Block_Wool_Green"
    },
    {
      "x": -4,
      "y": 36,
      "z": -12,
      "name": "Cloth_Block_Wool_Green"
    },
    {
      "x": -4,
      "y": 21,
      "z": -11,
      "name": "Cloth_Block_Wool_White"
    },
    {
      "x": -4,
      "y": 37,
      "z": -11,
      "name": "Cloth_Block_Wool_White"
    },
    {
      "x": -4,
      "y": 21,
      "z": -10,
      "name": "Cloth_Block_Wool_White"
    },
    {
      "x": -4,
      "y": 37,
      "z": -10,
      "name": "Cloth_Block_Wool_White"
    },
    {
      "x": -4,
      "y": 20,
      "z": -9,
      "name": "Cloth_Block_Wool_White"
    },
    {
      "x": -4,
      "y": 38,
      "z": -9,
      "name": "Cloth_Block_Wool_White"
    },
    {
      "x": -4,
      "y": 19,
      "z": -8,
      "name": "Cloth_Block_Wool_Green"
    },
    {
      "x": -4,
      "y": 20,
      "z": -8,
      "name": "Cloth_Block_Wool_Green"
    },
    {
      "x": -4,
      "y": 38,
      "z": -8,
      "name": "Cloth_Block_Wool_Green"
    },
    {
      "x": -4,
      "y": 18,
      "z": -7,
      "name": "Cloth_Block_Wool_Green"
    },
    {
      "x": -4,
      "y": 19,
      "z": -7,
      "name": "Cloth_Block_Wool_Green"
    },
    {
      "x": -4,
      "y": 20,
      "z": -7,
      "name": "Cloth_Block_Wool_White"
    },
    {
      "x": -4,
      "y": 38,
      "z": -7,
      "name": "Cloth_Block_Wool_White"
    },
    {
      "x": -4,
      "y": 17,
      "z": -6,
      "name": "Cloth_Block_Wool_White"
    },
    {
      "x": -4,
      "y": 18,
      "z": -6,
      "name": "Cloth_Block_Wool_White"
    },
    {
      "x": -4,
      "y": 19,
      "z": -6,
      "name": "Cloth_Block_Wool_Green"
    },
    {
      "x": -4,
      "y": 20,
      "z": -6,
      "name": "Cloth_Block_Wool_White"
    },
    {
      "x": -4,
      "y": 38,
      "z": -6,
      "name": "Cloth_Block_Wool_White"
    },
    {
      "x": -4,
      "y": 18,
      "z": -5,
      "name": "Cloth_Block_Wool_Green"
    },
    {
      "x": -4,
      "y": 19,
      "z": -5,
      "name": "Cloth_Block_Wool_Green"
    },
    {
      "x": -4,
      "y": 20,
      "z": -5,
      "name": "Cloth_Block_Wool_White"
    },
    {
      "x": -4,
      "y": 38,
      "z": -5,
      "name": "Cloth_Block_Wool_White"
    },
    {
      "x": -4,
      "y": 19,
      "z": -4,
      "name": "Cloth_Block_Wool_Green"
    },
    {
      "x": -4,
      "y": 20,
      "z": -4,
      "name": "Cloth_Block_Wool_Green"
    },
    {
      "x": -4,
      "y": 38,
      "z": -4,
      "name": "Cloth_Block_Wool_Green"
    },
    {
      "x": -4,
      "y": 20,
      "z": -3,
      "name": "Cloth_Block_Wool_White"
    },
    {
      "x": -4,
      "y": 38,
      "z": -3,
      "name": "Cloth_Block_Wool_White"
    },
    {
      "x": -4,
      "y": 21,
      "z": -2,
      "name": "Cloth_Block_Wool_White"
    },
    {
      "x": -4,
      "y": 37,
      "z": -2,
      "name": "Cloth_Block_Wool_White"
    },
    {
      "x": -4,
      "y": 21,
      "z": -1,
      "name": "Cloth_Block_Wool_White"
    },
    {
      "x": -4,
      "y": 37,
      "z": -1,
      "name": "Cloth_Block_Wool_White"
    },
    {
      "x": -4,
      "y": 22,
      "z": 0,
      "name": "Cloth_Block_Wool_Green"
    },
    {
      "x": -4,
      "y": 36,
      "z": 0,
      "name": "Cloth_Block_Wool_Green"
    },
    {
      "x": -4,
      "y": 23,
      "z": 1,
      "name": "Cloth_Block_Wool_Green"
    },
    {
      "x": -4,
      "y": 35,
      "z": 1,
      "name": "Cloth_Block_Wool_Green"
    },
    {
      "x": -4,
      "y": 24,
      "z": 2,
      "name": "Cloth_Block_Wool_Green"
    },
    {
      "x": -4,
      "y": 25,
      "z": 2,
      "name": "Cloth_Block_Wool_Green"
    },
    {
      "x": -4,
      "y": 33,
      "z": 2,
      "name": "Cloth_Block_Wool_Green"
    },
    {
      "x": -4,
      "y": 34,
      "z": 2,
      "name": "Cloth_Block_Wool_Green"
    },
    {
      "x": -4,
      "y": 26,
      "z": 3,
      "name": "Cloth_Block_Wool_Green"
    },
    {
      "x": -4,
      "y": 27,
      "z": 3,
      "name": "Cloth_Block_Wool_Green"
    },
    {
      "x": -4,
      "y": 28,
      "z": 3,
      "name": "Cloth_Block_Wool_Green"
    },
    {
      "x": -4,
      "y": 29,
      "z": 3,
      "name": "Cloth_Block_Wool_Green"
    },
    {
      "x": -4,
      "y": 30,
      "z": 3,
      "name": "Cloth_Block_Wool_Green"
    },
    {
      "x": -4,
      "y": 31,
      "z": 3,
      "name": "Cloth_Block_Wool_Green"
    },
    {
      "x": -4,
      "y": 32,
      "z": 3,
      "name": "Cloth_Block_Wool_Green"
    },
    {
      "x": -3,
      "y": 28,
      "z": -16,
      "name": "Cloth_Block_Wool_Green"
    },
    {
      "x": -3,
      "y": 29,
      "z": -16,
      "name": "Cloth_Block_Wool_Green"
    },
    {
      "x": -3,
      "y": 30,
      "z": -16,
      "name": "Cloth_Block_Wool_Green"
    },
    {
      "x": -3,
      "y": 25,
      "z": -15,
      "name": "Cloth_Block_Wool_Green"
    },
    {
      "x": -3,
      "y": 26,
      "z": -15,
      "name": "Cloth_Block_Wool_Green"
    },
    {
      "x": -3,
      "y": 27,
      "z": -15,
      "name": "Cloth_Block_Wool_Green"
    },
    {
      "x": -3,
      "y": 31,
      "z": -15,
      "name": "Cloth_Block_Wool_Green"
    },
    {
      "x": -3,
      "y": 32,
      "z": -15,
      "name": "Cloth_Block_Wool_Green"
    },
    {
      "x": -3,
      "y": 33,
      "z": -15,
      "name": "Cloth_Block_Wool_Green"
    },
    {
      "x": -3,
      "y": 23,
      "z": -14,
      "name": "Cloth_Block_Wool_Green"
    },
    {
      "x": -3,
      "y": 24,
      "z": -14,
      "name": "Cloth_Block_Wool_Green"
    },
    {
      "x": -3,
      "y": 34,
      "z": -14,
      "name": "Cloth_Block_Wool_Green"
    },
    {
      "x": -3,
      "y": 35,
      "z": -14,
      "name": "Cloth_Block_Wool_Green"
    },
    {
      "x": -3,
      "y": 22,
      "z": -13,
      "name": "Cloth_Block_Wool_Green"
    },
    {
      "x": -3,
      "y": 36,
      "z": -13,
      "name": "Cloth_Block_Wool_Green"
    },
    {
      "x": -3,
      "y": 21,
      "z": -12,
      "name": "Cloth_Block_Wool_Green"
    },
    {
      "x": -3,
      "y": 37,
      "z": -12,
      "name": "Cloth_Block_Wool_Green"
    },
    {
      "x": -3,
      "y": 21,
      "z": -11,
      "name": "Cloth_Block_Wool_Green"
    },
    {
      "x": -3,
      "y": 37,
      "z": -11,
      "name": "Cloth_Block_Wool_Green"
    },
    {
      "x": -3,
      "y": 20,
      "z": -10,
      "name": "Cloth_Block_Wool_White"
    },
    {
      "x": -3,
      "y": 38,
      "z": -10,
      "name": "Cloth_Block_Wool_White"
    },
    {
      "x": -3,
      "y": 19,
      "z": -9,
      "name": "Cloth_Block_Wool_White"
    },
    {
      "x": -3,
      "y": 20,
      "z": -9,
      "name": "Cloth_Block_Wool_White"
    },
    {
      "x": -3,
      "y": 38,
      "z": -9,
      "name": "Cloth_Block_Wool_White"
    },
    {
      "x": -3,
      "y": 18,
      "z": -8,
      "name": "Cloth_Block_Wool_Green"
    },
    {
      "x": -3,
      "y": 19,
      "z": -8,
      "name": "Cloth_Block_Wool_Green"
    },
    {
      "x": -3,
      "y": 20,
      "z": -8,
      "name": "Cloth_Block_Wool_White"
    },
    {
      "x": -3,
      "y": 38,
      "z": -8,
      "name": "Cloth_Block_Wool_Green"
    },
    {
      "x": -3,
      "y": 16,
      "z": -7,
      "name": "Cloth_Block_Wool_Green"
    },
    {
      "x": -3,
      "y": 17,
      "z": -7,
      "name": "Cloth_Block_Wool_Green"
    },
    {
      "x": -3,
      "y": 18,
      "z": -7,
      "name": "Cloth_Block_Wool_Green"
    },
    {
      "x": -3,
      "y": 19,
      "z": -7,
      "name": "Cloth_Block_Wool_White"
    },
    {
      "x": -3,
      "y": 39,
      "z": -7,
      "name": "Cloth_Block_Wool_Green"
    },
    {
      "x": -3,
      "y": 16,
      "z": -6,
      "name": "Cloth_Block_Wool_White"
    },
    {
      "x": -3,
      "y": 17,
      "z": -6,
      "name": "Cloth_Block_Wool_Green"
    },
    {
      "x": -3,
      "y": 18,
      "z": -6,
      "name": "Cloth_Block_Wool_Green"
    },
    {
      "x": -3,
      "y": 19,
      "z": -6,
      "name": "Cloth_Block_Wool_White"
    },
    {
      "x": -3,
      "y": 39,
      "z": -6,
      "name": "Cloth_Block_Wool_White"
    },
    {
      "x": -3,
      "y": 16,
      "z": -5,
      "name": "Cloth_Block_Wool_Green"
    },
    {
      "x": -3,
      "y": 17,
      "z": -5,
      "name": "Cloth_Block_Wool_Green"
    },
    {
      "x": -3,
      "y": 18,
      "z": -5,
      "name": "Cloth_Block_Wool_Green"
    },
    {
      "x": -3,
      "y": 19,
      "z": -5,
      "name": "Cloth_Block_Wool_White"
    },
    {
      "x": -3,
      "y": 39,
      "z": -5,
      "name": "Cloth_Block_Wool_Green"
    },
    {
      "x": -3,
      "y": 18,
      "z": -4,
      "name": "Cloth_Block_Wool_Green"
    },
    {
      "x": -3,
      "y": 19,
      "z": -4,
      "name": "Cloth_Block_Wool_Green"
    },
    {
      "x": -3,
      "y": 20,
      "z": -4,
      "name": "Cloth_Block_Wool_White"
    },
    {
      "x": -3,
      "y": 38,
      "z": -4,
      "name": "Cloth_Block_Wool_Green"
    },
    {
      "x": -3,
      "y": 19,
      "z": -3,
      "name": "Cloth_Block_Wool_White"
    },
    {
      "x": -3,
      "y": 20,
      "z": -3,
      "name": "Cloth_Block_Wool_White"
    },
    {
      "x": -3,
      "y": 38,
      "z": -3,
      "name": "Cloth_Block_Wool_White"
    },
    {
      "x": -3,
      "y": 20,
      "z": -2,
      "name": "Cloth_Block_Wool_White"
    },
    {
      "x": -3,
      "y": 38,
      "z": -2,
      "name": "Cloth_Block_Wool_White"
    },
    {
      "x": -3,
      "y": 21,
      "z": -1,
      "name": "Cloth_Block_Wool_Green"
    },
    {
      "x": -3,
      "y": 37,
      "z": -1,
      "name": "Cloth_Block_Wool_Green"
    },
    {
      "x": -3,
      "y": 21,
      "z": 0,
      "name": "Cloth_Block_Wool_Green"
    },
    {
      "x": -3,
      "y": 37,
      "z": 0,
      "name": "Cloth_Block_Wool_Green"
    },
    {
      "x": -3,
      "y": 22,
      "z": 1,
      "name": "Cloth_Block_Wool_Green"
    },
    {
      "x": -3,
      "y": 36,
      "z": 1,
      "name": "Cloth_Block_Wool_Green"
    },
    {
      "x": -3,
      "y": 23,
      "z": 2,
      "name": "Cloth_Block_Wool_Green"
    },
    {
      "x": -3,
      "y": 24,
      "z": 2,
      "name": "Cloth_Block_Wool_Green"
    },
    {
      "x": -3,
      "y": 34,
      "z": 2,
      "name": "Cloth_Block_Wool_Green"
    },
    {
      "x": -3,
      "y": 35,
      "z": 2,
      "name": "Cloth_Block_Wool_Green"
    },
    {
      "x": -3,
      "y": 25,
      "z": 3,
      "name": "Cloth_Block_Wool_Green"
    },
    {
      "x": -3,
      "y": 26,
      "z": 3,
      "name": "Cloth_Block_Wool_Green"
    },
    {
      "x": -3,
      "y": 27,
      "z": 3,
      "name": "Cloth_Block_Wool_Green"
    },
    {
      "x": -3,
      "y": 31,
      "z": 3,
      "name": "Cloth_Block_Wool_Green"
    },
    {
      "x": -3,
      "y": 32,
      "z": 3,
      "name": "Cloth_Block_Wool_Green"
    },
    {
      "x": -3,
      "y": 33,
      "z": 3,
      "name": "Cloth_Block_Wool_Green"
    },
    {
      "x": -3,
      "y": 28,
      "z": 4,
      "name": "Cloth_Block_Wool_Green"
    },
    {
      "x": -3,
      "y": 29,
      "z": 4,
      "name": "Cloth_Block_Wool_Green"
    },
    {
      "x": -3,
      "y": 30,
      "z": 4,
      "name": "Cloth_Block_Wool_Green"
    },
    {
      "x": -2,
      "y": 27,
      "z": -16,
      "name": "Cloth_Block_Wool_Green"
    },
    {
      "x": -2,
      "y": 28,
      "z": -16,
      "name": "Cloth_Block_Wool_Green"
    },
    {
      "x": -2,
      "y": 29,
      "z": -16,
      "name": "Cloth_Block_Wool_Green"
    },
    {
      "x": -2,
      "y": 30,
      "z": -16,
      "name": "Cloth_Block_Wool_Green"
    },
    {
      "x": -2,
      "y": 31,
      "z": -16,
      "name": "Cloth_Block_Wool_Green"
    },
    {
      "x": -2,
      "y": 24,
      "z": -15,
      "name": "Cloth_Block_Wool_Green"
    },
    {
      "x": -2,
      "y": 25,
      "z": -15,
      "name": "Cloth_Block_Wool_Green"
    },
    {
      "x": -2,
      "y": 26,
      "z": -15,
      "name": "Cloth_Block_Wool_Green"
    },
    {
      "x": -2,
      "y": 32,
      "z": -15,
      "name": "Cloth_Block_Wool_Green"
    },
    {
      "x": -2,
      "y": 33,
      "z": -15,
      "name": "Cloth_Block_Wool_Green"
    },
    {
      "x": -2,
      "y": 34,
      "z": -15,
      "name": "Cloth_Block_Wool_Green"
    },
    {
      "x": -2,
      "y": 23,
      "z": -14,
      "name": "Cloth_Block_Wool_Green"
    },
    {
      "x": -2,
      "y": 35,
      "z": -14,
      "name": "Cloth_Block_Wool_Green"
    },
    {
      "x": -2,
      "y": 22,
      "z": -13,
      "name": "Cloth_Block_Wool_Green"
    },
    {
      "x": -2,
      "y": 36,
      "z": -13,
      "name": "Cloth_Block_Wool_Green"
    },
    {
      "x": -2,
      "y": 21,
      "z": -12,
      "name": "Cloth_Block_Wool_Green"
    },
    {
      "x": -2,
      "y": 37,
      "z": -12,
      "name": "Cloth_Block_Wool_Green"
    },
    {
      "x": -2,
      "y": 20,
      "z": -11,
      "name": "Cloth_Block_Wool_Green"
    },
    {
      "x": -2,
      "y": 38,
      "z": -11,
      "name": "Cloth_Block_Wool_Green"
    },
    {
      "x": -2,
      "y": 19,
      "z": -10,
      "name": "Cloth_Block_Wool_Green"
    },
    {
      "x": -2,
      "y": 20,
      "z": -10,
      "name": "Cloth_Block_Wool_Green"
    },
    {
      "x": -2,
      "y": 38,
      "z": -10,
      "name": "Cloth_Block_Wool_Green"
    },
    {
      "x": -2,
      "y": 18,
      "z": -9,
      "name": "Cloth_Block_Wool_Green"
    },
    {
      "x": -2,
      "y": 19,
      "z": -9,
      "name": "Cloth_Block_Wool_Green"
    },
    {
      "x": -2,
      "y": 20,
      "z": -9,
      "name": "Cloth_Block_Wool_White"
    },
    {
      "x": -2,
      "y": 38,
      "z": -9,
      "name": "Cloth_Block_Wool_Green"
    },
    {
      "x": -2,
      "y": 0,
      "z": -8,
      "name": "Wood_Hardwood_Planks"
    },
    {
      "x": -2,
      "y": 1,
      "z": -8,
      "name": "Deco_Iron_Bars_Corner",
      "rotation": 1
    },
    {
      "x": -2,
      "y": 2,
      "z": -8,
      "name": "Deco_Iron_Bars_Corner",
      "rotation": 1
    },
    {
      "x": -2,
      "y": 3,
      "z": -8,
      "name": "Deco_Iron_Bars_Corner",
      "rotation": 1
    },
    {
      "x": -2,
      "y": 4,
      "z": -8,
      "name": "Wood_Hardwood_Planks_Half"
    },
    {
      "x": -2,
      "y": 16,
      "z": -8,
      "name": "Cloth_Block_Wool_Green"
    },
    {
      "x": -2,
      "y": 17,
      "z": -8,
      "name": "Cloth_Block_Wool_Green"
    },
    {
      "x": -2,
      "y": 18,
      "z": -8,
      "name": "Cloth_Block_Wool_Green"
    },
    {
      "x": -2,
      "y": 19,
      "z": -8,
      "name": "Cloth_Block_Wool_White"
    },
    {
      "x": -2,
      "y": 39,
      "z": -8,
      "name": "Cloth_Block_Wool_Green"
    },
    {
      "x": -2,
      "y": 0,
      "z": -7,
      "name": "Wood_Hardwood_Stairs",
      "rotation": 3
    },
    {
      "x": -2,
      "y": 1,
      "z": -7,
      "name": "Deco_Iron_Bars",
      "rotation": 1
    },
    {
      "x": -2,
      "y": 2,
      "z": -7,
      "name": "Deco_Iron_Bars",
      "rotation": 1
    },
    {
      "x": -2,
      "y": 3,
      "z": -7,
      "name": "Deco_Iron_Bars",
      "rotation": 1
    },
    {
      "x": -2,
      "y": 4,
      "z": -7,
      "name": "Wood_Hardwood_Planks_Half"
    },
    {
      "x": -2,
      "y": 9,
      "z": -7,
      "name": "Wood_Hardwood_Planks_Half",
      "rotation": 7
    },
    {
      "x": -2,
      "y": 12,
      "z": -7,
      "name": "Cloth_Block_Wool_Green_Half",
      "rotation": 7
    },
    {
      "x": -2,
      "y": 13,
      "z": -7,
      "name": "Cloth_Block_Wool_Green_Stairs",
      "rotation": 9
    },
    {
      "x": -2,
      "y": 14,
      "z": -7,
      "name": "Cloth_Block_Wool_Green"
    },
    {
      "x": -2,
      "y": 15,
      "z": -7,
      "name": "Cloth_Block_Wool_Green"
    },
    {
      "x": -2,
      "y": 16,
      "z": -7,
      "name": "Cloth_Block_Wool_Green"
    },
    {
      "x": -2,
      "y": 19,
      "z": -7,
      "name": "Cloth_Block_Wool_Green"
    },
    {
      "x": -2,
      "y": 39,
      "z": -7,
      "name": "Cloth_Block_Wool_Green"
    },
    {
      "x": -2,
      "y": 0,
      "z": -6,
      "name": "Wood_Hardwood_Stairs",
      "rotation": 3
    },
    {
      "x": -2,
      "y": 1,
      "z": -6,
      "name": "Deco_Iron_Bars",
      "rotation": 1
    },
    {
      "x": -2,
      "y": 2,
      "z": -6,
      "name": "Deco_Iron_Bars",
      "rotation": 1
    },
    {
      "x": -2,
      "y": 3,
      "z": -6,
      "name": "Deco_Iron_Bars",
      "rotation": 1
    },
    {
      "x": -2,
      "y": 4,
      "z": -6,
      "name": "Wood_Hardwood_Planks_Half"
    },
    {
      "x": -2,
      "y": 9,
      "z": -6,
      "name": "Wood_Hardwood_Planks_Half",
      "rotation": 7
    },
    {
      "x": -2,
      "y": 12,
      "z": -6,
      "name": "Cloth_Block_Wool_White_Half",
      "rotation": 7
    },
    {
      "x": -2,
      "y": 13,
      "z": -6,
      "name": "Cloth_Block_Wool_White_Stairs",
      "rotation": 9
    },
    {
      "x": -2,
      "y": 14,
      "z": -6,
      "name": "Cloth_Block_Wool_White"
    },
    {
      "x": -2,
      "y": 15,
      "z": -6,
      "name": "Cloth_Block_Wool_White"
    },
    {
      "x": -2,
      "y": 16,
      "z": -6,
      "name": "Cloth_Block_Wool_Green"
    },
    {
      "x": -2,
      "y": 19,
      "z": -6,
      "name": "Cloth_Block_Wool_White"
    },
    {
      "x": -2,
      "y": 40,
      "z": -6,
      "name": "Cloth_Block_Wool_White_Half"
    },
    {
      "x": -2,
      "y": 0,
      "z": -5,
      "name": "Wood_Hardwood_Stairs",
      "rotation": 3
    },
    {
      "x": -2,
      "y": 1,
      "z": -5,
      "name": "Deco_Iron_Bars",
      "rotation": 1
    },
    {
      "x": -2,
      "y": 2,
      "z": -5,
      "name": "Deco_Iron_Bars",
      "rotation": 1
    },
    {
      "x": -2,
      "y": 3,
      "z": -5,
      "name": "Deco_Iron_Bars",
      "rotation": 1
    },
    {
      "x": -2,
      "y": 4,
      "z": -5,
      "name": "Wood_Hardwood_Planks_Half"
    },
    {
      "x": -2,
      "y": 9,
      "z": -5,
      "name": "Wood_Hardwood_Planks_Half",
      "rotation": 7
    },
    {
      "x": -2,
      "y": 12,
      "z": -5,
      "name": "Cloth_Block_Wool_Green_Half",
      "rotation": 7
    },
    {
      "x": -2,
      "y": 13,
      "z": -5,
      "name": "Cloth_Block_Wool_Green_Stairs",
      "rotation": 9
    },
    {
      "x": -2,
      "y": 14,
      "z": -5,
      "name": "Cloth_Block_Wool_Green"
    },
    {
      "x": -2,
      "y": 15,
      "z": -5,
      "name": "Cloth_Block_Wool_Green"
    },
    {
      "x": -2,
      "y": 16,
      "z": -5,
      "name": "Cloth_Block_Wool_Green"
    },
    {
      "x": -2,
      "y": 19,
      "z": -5,
      "name": "Cloth_Block_Wool_Green"
    },
    {
      "x": -2,
      "y": 39,
      "z": -5,
      "name": "Cloth_Block_Wool_Green"
    },
    {
      "x": -2,
      "y": 0,
      "z": -4,
      "name": "Wood_Hardwood_Planks"
    },
    {
      "x": -2,
      "y": 1,
      "z": -4,
      "name": "Deco_Iron_Bars_Corner",
      "rotation": 2
    },
    {
      "x": -2,
      "y": 2,
      "z": -4,
      "name": "Deco_Iron_Bars_Corner",
      "rotation": 2
    },
    {
      "x": -2,
      "y": 3,
      "z": -4,
      "name": "Deco_Iron_Bars_Corner",
      "rotation": 2
    },
    {
      "x": -2,
      "y": 4,
      "z": -4,
      "name": "Wood_Hardwood_Planks_Half"
    },
    {
      "x": -2,
      "y": 16,
      "z": -4,
      "name": "Cloth_Block_Wool_Green"
    },
    {
      "x": -2,
      "y": 17,
      "z": -4,
      "name": "Cloth_Block_Wool_Green"
    },
    {
      "x": -2,
      "y": 18,
      "z": -4,
      "name": "Cloth_Block_Wool_Green"
    },
    {
      "x": -2,
      "y": 19,
      "z": -4,
      "name": "Cloth_Block_Wool_White"
    },
    {
      "x": -2,
      "y": 39,
      "z": -4,
      "name": "Cloth_Block_Wool_Green"
    },
    {
      "x": -2,
      "y": 18,
      "z": -3,
      "name": "Cloth_Block_Wool_Green"
    },
    {
      "x": -2,
      "y": 19,
      "z": -3,
      "name": "Cloth_Block_Wool_Green"
    },
    {
      "x": -2,
      "y": 20,
      "z": -3,
      "name": "Cloth_Block_Wool_White"
    },
    {
      "x": -2,
      "y": 38,
      "z": -3,
      "name": "Cloth_Block_Wool_Green"
    },
    {
      "x": -2,
      "y": 19,
      "z": -2,
      "name": "Cloth_Block_Wool_Green"
    },
    {
      "x": -2,
      "y": 20,
      "z": -2,
      "name": "Cloth_Block_Wool_Green"
    },
    {
      "x": -2,
      "y": 38,
      "z": -2,
      "name": "Cloth_Block_Wool_Green"
    },
    {
      "x": -2,
      "y": 20,
      "z": -1,
      "name": "Cloth_Block_Wool_Green"
    },
    {
      "x": -2,
      "y": 38,
      "z": -1,
      "name": "Cloth_Block_Wool_Green"
    },
    {
      "x": -2,
      "y": 21,
      "z": 0,
      "name": "Cloth_Block_Wool_Green"
    },
    {
      "x": -2,
      "y": 37,
      "z": 0,
      "name": "Cloth_Block_Wool_Green"
    },
    {
      "x": -2,
      "y": 22,
      "z": 1,
      "name": "Cloth_Block_Wool_Green"
    },
    {
      "x": -2,
      "y": 36,
      "z": 1,
      "name": "Cloth_Block_Wool_Green"
    },
    {
      "x": -2,
      "y": 23,
      "z": 2,
      "name": "Cloth_Block_Wool_Green"
    },
    {
      "x": -2,
      "y": 35,
      "z": 2,
      "name": "Cloth_Block_Wool_Green"
    },
    {
      "x": -2,
      "y": 24,
      "z": 3,
      "name": "Cloth_Block_Wool_Green"
    },
    {
      "x": -2,
      "y": 25,
      "z": 3,
      "name": "Cloth_Block_Wool_Green"
    },
    {
      "x": -2,
      "y": 26,
      "z": 3,
      "name": "Cloth_Block_Wool_Green"
    },
    {
      "x": -2,
      "y": 32,
      "z": 3,
      "name": "Cloth_Block_Wool_Green"
    },
    {
      "x": -2,
      "y": 33,
      "z": 3,
      "name": "Cloth_Block_Wool_Green"
    },
    {
      "x": -2,
      "y": 34,
      "z": 3,
      "name": "Cloth_Block_Wool_Green"
    },
    {
      "x": -2,
      "y": 27,
      "z": 4,
      "name": "Cloth_Block_Wool_Green"
    },
    {
      "x": -2,
      "y": 28,
      "z": 4,
      "name": "Cloth_Block_Wool_Green"
    },
    {
      "x": -2,
      "y": 29,
      "z": 4,
      "name": "Cloth_Block_Wool_Green"
    },
    {
      "x": -2,
      "y": 30,
      "z": 4,
      "name": "Cloth_Block_Wool_Green"
    },
    {
      "x": -2,
      "y": 31,
      "z": 4,
      "name": "Cloth_Block_Wool_Green"
    },
    {
      "x": -1,
      "y": 26,
      "z": -16,
      "name": "Cloth_Block_Wool_White"
    },
    {
      "x": -1,
      "y": 27,
      "z": -16,
      "name": "Cloth_Block_Wool_White"
    },
    {
      "x": -1,
      "y": 28,
      "z": -16,
      "name": "Cloth_Block_Wool_White"
    },
    {
      "x": -1,
      "y": 29,
      "z": -16,
      "name": "Cloth_Block_Wool_White"
    },
    {
      "x": -1,
      "y": 30,
      "z": -16,
      "name": "Cloth_Block_Wool_White"
    },
    {
      "x": -1,
      "y": 31,
      "z": -16,
      "name": "Cloth_Block_Wool_White"
    },
    {
      "x": -1,
      "y": 32,
      "z": -16,
      "name": "Cloth_Block_Wool_White"
    },
    {
      "x": -1,
      "y": 24,
      "z": -15,
      "name": "Cloth_Block_Wool_White"
    },
    {
      "x": -1,
      "y": 25,
      "z": -15,
      "name": "Cloth_Block_Wool_White"
    },
    {
      "x": -1,
      "y": 33,
      "z": -15,
      "name": "Cloth_Block_Wool_White"
    },
    {
      "x": -1,
      "y": 34,
      "z": -15,
      "name": "Cloth_Block_Wool_White"
    },
    {
      "x": -1,
      "y": 23,
      "z": -14,
      "name": "Cloth_Block_Wool_White"
    },
    {
      "x": -1,
      "y": 35,
      "z": -14,
      "name": "Cloth_Block_Wool_White"
    },
    {
      "x": -1,
      "y": 22,
      "z": -13,
      "name": "Cloth_Block_Wool_White"
    },
    {
      "x": -1,
      "y": 36,
      "z": -13,
      "name": "Cloth_Block_Wool_White"
    },
    {
      "x": -1,
      "y": 21,
      "z": -12,
      "name": "Cloth_Block_Wool_White"
    },
    {
      "x": -1,
      "y": 37,
      "z": -12,
      "name": "Cloth_Block_Wool_White"
    },
    {
      "x": -1,
      "y": 19,
      "z": -11,
      "name": "Cloth_Block_Wool_Green"
    },
    {
      "x": -1,
      "y": 20,
      "z": -11,
      "name": "Cloth_Block_Wool_Green"
    },
    {
      "x": -1,
      "y": 38,
      "z": -11,
      "name": "Cloth_Block_Wool_White"
    },
    {
      "x": -1,
      "y": 18,
      "z": -10,
      "name": "Cloth_Block_Wool_Green"
    },
    {
      "x": -1,
      "y": 19,
      "z": -10,
      "name": "Cloth_Block_Wool_Green"
    },
    {
      "x": -1,
      "y": 20,
      "z": -10,
      "name": "Cloth_Block_Wool_White"
    },
    {
      "x": -1,
      "y": 38,
      "z": -10,
      "name": "Cloth_Block_Wool_White"
    },
    {
      "x": -1,
      "y": 16,
      "z": -9,
      "name": "Cloth_Block_Wool_Green"
    },
    {
      "x": -1,
      "y": 17,
      "z": -9,
      "name": "Cloth_Block_Wool_Green"
    },
    {
      "x": -1,
      "y": 18,
      "z": -9,
      "name": "Cloth_Block_Wool_Green"
    },
    {
      "x": -1,
      "y": 19,
      "z": -9,
      "name": "Cloth_Block_Wool_White"
    },
    {
      "x": -1,
      "y": 39,
      "z": -9,
      "name": "Cloth_Block_Wool_Green"
    },
    {
      "x": -1,
      "y": 0,
      "z": -8,
      "name": "Wood_Hardwood_Stairs",
      "rotation": 2
    },
    {
      "x": -1,
      "y": 1,
      "z": -8,
      "name": "Deco_Iron_Bars"
    },
    {
      "x": -1,
      "y": 2,
      "z": -8,
      "name": "Deco_Iron_Bars"
    },
    {
      "x": -1,
      "y": 3,
      "z": -8,
      "name": "Deco_Iron_Bars"
    },
    {
      "x": -1,
      "y": 4,
      "z": -8,
      "name": "Wood_Hardwood_Planks_Half"
    },
    {
      "x": -1,
      "y": 9,
      "z": -8,
      "name": "Wood_Hardwood_Planks_Half",
      "rotation": 6
    },
    {
      "x": -1,
      "y": 12,
      "z": -8,
      "name": "Cloth_Block_Wool_Green_Half",
      "rotation": 6
    },
    {
      "x": -1,
      "y": 13,
      "z": -8,
      "name": "Cloth_Block_Wool_Green_Stairs",
      "rotation": 8
    },
    {
      "x": -1,
      "y": 14,
      "z": -8,
      "name": "Cloth_Block_Wool_Green"
    },
    {
      "x": -1,
      "y": 15,
      "z": -8,
      "name": "Cloth_Block_Wool_Green"
    },
    {
      "x": -1,
      "y": 16,
      "z": -8,
      "name": "Cloth_Block_Wool_Green"
    },
    {
      "x": -1,
      "y": 19,
      "z": -8,
      "name": "Cloth_Block_Wool_Green"
    },
    {
      "x": -1,
      "y": 39,
      "z": -8,
      "name": "Cloth_Block_Wool_Green"
    },
    {
      "x": -1,
      "y": 0,
      "z": -7,
      "name": "Wood_Hardwood_Planks"
    },
    {
      "x": -1,
      "y": 4,
      "z": -7,
      "name": "*Wood_Hardwood_Stairs_State_Definitions_Corner_Left",
      "rotation": 2
    },
    {
      "x": -1,
      "y": 8,
      "z": -7,
      "name": "*Wood_Hardwood_Stairs_State_Definitions_Corner_Left",
      "rotation": 9
    },
    {
      "x": -1,
      "y": 9,
      "z": -7,
      "name": "Wood_Hardwood_Planks"
    },
    {
      "x": -1,
      "y": 10,
      "z": -7,
      "name": "Deco_Iron_Chain_Small"
    },
    {
      "x": -1,
      "y": 11,
      "z": -7,
      "name": "Deco_Iron_Chain_Small"
    },
    {
      "x": -1,
      "y": 12,
      "z": -7,
      "name": "Deco_Iron_Chain_Small"
    },
    {
      "x": -1,
      "y": 13,
      "z": -7,
      "name": "Wood_Hardwood_Planks"
    },
    {
      "x": -1,
      "y": 19,
      "z": -7,
      "name": "Cloth_Block_Wool_Green"
    },
    {
      "x": -1,
      "y": 40,
      "z": -7,
      "name": "Cloth_Block_Wool_Green_Half",
      "rotation": 2
    },
    {
      "x": -1,
      "y": 0,
      "z": -6,
      "name": "Wood_Hardwood_Planks"
    },
    {
      "x": -1,
      "y": 4,
      "z": -6,
      "name": "Wood_Hardwood_Stairs",
      "rotation": 3
    },
    {
      "x": -1,
      "y": 8,
      "z": -6,
      "name": "Wood_Hardwood_Stairs",
      "rotation": 9
    },
    {
      "x": -1,
      "y": 9,
      "z": -6,
      "name": "Furniture_Crude_Stool"
    },
    {
      "x": -1,
      "y": 12,
      "z": -6,
      "name": "Deco_Iron_Bars_Platforms"
    },
    {
      "x": -1,
      "y": 19,
      "z": -6,
      "name": "Cloth_Block_Wool_Green"
    },
    {
      "x": -1,
      "y": 40,
      "z": -6,
      "name": "Cloth_Block_Wool_Green"
    },
    {
      "x": -1,
      "y": 0,
      "z": -5,
      "name": "Wood_Hardwood_Planks"
    },
    {
      "x": -1,
      "y": 4,
      "z": -5,
      "name": "*Wood_Hardwood_Stairs_State_Definitions_Corner_Left",
      "rotation": 3
    },
    {
      "x": -1,
      "y": 8,
      "z": -5,
      "name": "*Wood_Hardwood_Stairs_State_Definitions_Corner_Left",
      "rotation": 10
    },
    {
      "x": -1,
      "y": 9,
      "z": -5,
      "name": "Wood_Hardwood_Planks"
    },
    {
      "x": -1,
      "y": 10,
      "z": -5,
      "name": "Deco_Iron_Chain_Small"
    },
    {
      "x": -1,
      "y": 11,
      "z": -5,
      "name": "Deco_Iron_Chain_Small"
    },
    {
      "x": -1,
      "y": 12,
      "z": -5,
      "name": "Deco_Iron_Chain_Small"
    },
    {
      "x": -1,
      "y": 13,
      "z": -5,
      "name": "Wood_Hardwood_Planks"
    },
    {
      "x": -1,
      "y": 19,
      "z": -5,
      "name": "Cloth_Block_Wool_Green"
    },
    {
      "x": -1,
      "y": 40,
      "z": -5,
      "name": "Cloth_Block_Wool_Green_Half",
      "rotation": 2
    },
    {
      "x": -1,
      "y": 0,
      "z": -4,
      "name": "Wood_Hardwood_Stairs"
    },
    {
      "x": -1,
      "y": 1,
      "z": -4,
      "name": "Deco_Iron_Bars"
    },
    {
      "x": -1,
      "y": 2,
      "z": -4,
      "name": "Deco_Iron_Bars"
    },
    {
      "x": -1,
      "y": 3,
      "z": -4,
      "name": "Deco_Iron_Bars"
    },
    {
      "x": -1,
      "y": 4,
      "z": -4,
      "name": "Wood_Hardwood_Planks_Half"
    },
    {
      "x": -1,
      "y": 9,
      "z": -4,
      "name": "Wood_Hardwood_Planks_Half",
      "rotation": 4
    },
    {
      "x": -1,
      "y": 12,
      "z": -4,
      "name": "Cloth_Block_Wool_Green_Half",
      "rotation": 4
    },
    {
      "x": -1,
      "y": 13,
      "z": -4,
      "name": "Cloth_Block_Wool_Green_Stairs",
      "rotation": 10
    },
    {
      "x": -1,
      "y": 14,
      "z": -4,
      "name": "Cloth_Block_Wool_Green"
    },
    {
      "x": -1,
      "y": 15,
      "z": -4,
      "name": "Cloth_Block_Wool_Green"
    },
    {
      "x": -1,
      "y": 16,
      "z": -4,
      "name": "Cloth_Block_Wool_Green"
    },
    {
      "x": -1,
      "y": 19,
      "z": -4,
      "name": "Cloth_Block_Wool_Green"
    },
    {
      "x": -1,
      "y": 39,
      "z": -4,
      "name": "Cloth_Block_Wool_Green"
    },
    {
      "x": -1,
      "y": 16,
      "z": -3,
      "name": "Cloth_Block_Wool_Green"
    },
    {
      "x": -1,
      "y": 17,
      "z": -3,
      "name": "Cloth_Block_Wool_Green"
    },
    {
      "x": -1,
      "y": 18,
      "z": -3,
      "name": "Cloth_Block_Wool_Green"
    },
    {
      "x": -1,
      "y": 19,
      "z": -3,
      "name": "Cloth_Block_Wool_White"
    },
    {
      "x": -1,
      "y": 39,
      "z": -3,
      "name": "Cloth_Block_Wool_Green"
    },
    {
      "x": -1,
      "y": 18,
      "z": -2,
      "name": "Cloth_Block_Wool_Green"
    },
    {
      "x": -1,
      "y": 19,
      "z": -2,
      "name": "Cloth_Block_Wool_Green"
    },
    {
      "x": -1,
      "y": 20,
      "z": -2,
      "name": "Cloth_Block_Wool_White"
    },
    {
      "x": -1,
      "y": 38,
      "z": -2,
      "name": "Cloth_Block_Wool_White"
    },
    {
      "x": -1,
      "y": 19,
      "z": -1,
      "name": "Cloth_Block_Wool_Green"
    },
    {
      "x": -1,
      "y": 20,
      "z": -1,
      "name": "Cloth_Block_Wool_Green"
    },
    {
      "x": -1,
      "y": 38,
      "z": -1,
      "name": "Cloth_Block_Wool_White"
    },
    {
      "x": -1,
      "y": 21,
      "z": 0,
      "name": "Cloth_Block_Wool_White"
    },
    {
      "x": -1,
      "y": 37,
      "z": 0,
      "name": "Cloth_Block_Wool_White"
    },
    {
      "x": -1,
      "y": 22,
      "z": 1,
      "name": "Cloth_Block_Wool_White"
    },
    {
      "x": -1,
      "y": 36,
      "z": 1,
      "name": "Cloth_Block_Wool_White"
    },
    {
      "x": -1,
      "y": 23,
      "z": 2,
      "name": "Cloth_Block_Wool_White"
    },
    {
      "x": -1,
      "y": 35,
      "z": 2,
      "name": "Cloth_Block_Wool_White"
    },
    {
      "x": -1,
      "y": 24,
      "z": 3,
      "name": "Cloth_Block_Wool_White"
    },
    {
      "x": -1,
      "y": 25,
      "z": 3,
      "name": "Cloth_Block_Wool_White"
    },
    {
      "x": -1,
      "y": 33,
      "z": 3,
      "name": "Cloth_Block_Wool_White"
    },
    {
      "x": -1,
      "y": 34,
      "z": 3,
      "name": "Cloth_Block_Wool_White"
    },
    {
      "x": -1,
      "y": 26,
      "z": 4,
      "name": "Cloth_Block_Wool_White"
    },
    {
      "x": -1,
      "y": 27,
      "z": 4,
      "name": "Cloth_Block_Wool_White"
    },
    {
      "x": -1,
      "y": 28,
      "z": 4,
      "name": "Cloth_Block_Wool_White"
    },
    {
      "x": -1,
      "y": 29,
      "z": 4,
      "name": "Cloth_Block_Wool_White"
    },
    {
      "x": -1,
      "y": 30,
      "z": 4,
      "name": "Cloth_Block_Wool_White"
    },
    {
      "x": -1,
      "y": 31,
      "z": 4,
      "name": "Cloth_Block_Wool_White"
    },
    {
      "x": -1,
      "y": 32,
      "z": 4,
      "name": "Cloth_Block_Wool_White"
    },
    {
      "x": 0,
      "y": 28,
      "z": -17,
      "name": "Cloth_Block_Wool_White_Half",
      "rotation": 6
    },
    {
      "x": 0,
      "y": 29,
      "z": -17,
      "name": "Cloth_Block_Wool_White_Half",
      "rotation": 6
    },
    {
      "x": 0,
      "y": 30,
      "z": -17,
      "name": "Cloth_Block_Wool_White_Half",
      "rotation": 6
    },
    {
      "x": 0,
      "y": 26,
      "z": -16,
      "name": "Cloth_Block_Wool_White"
    },
    {
      "x": 0,
      "y": 27,
      "z": -16,
      "name": "Cloth_Block_Wool_White"
    },
    {
      "x": 0,
      "y": 31,
      "z": -16,
      "name": "Cloth_Block_Wool_White"
    },
    {
      "x": 0,
      "y": 32,
      "z": -16,
      "name": "Cloth_Block_Wool_White"
    },
    {
      "x": 0,
      "y": 24,
      "z": -15,
      "name": "Cloth_Block_Wool_White"
    },
    {
      "x": 0,
      "y": 25,
      "z": -15,
      "name": "Cloth_Block_Wool_White"
    },
    {
      "x": 0,
      "y": 33,
      "z": -15,
      "name": "Cloth_Block_Wool_White"
    },
    {
      "x": 0,
      "y": 34,
      "z": -15,
      "name": "Cloth_Block_Wool_White"
    },
    {
      "x": 0,
      "y": 23,
      "z": -14,
      "name": "Cloth_Block_Wool_White"
    },
    {
      "x": 0,
      "y": 35,
      "z": -14,
      "name": "Cloth_Block_Wool_White"
    },
    {
      "x": 0,
      "y": 22,
      "z": -13,
      "name": "Cloth_Block_Wool_White"
    },
    {
      "x": 0,
      "y": 36,
      "z": -13,
      "name": "Cloth_Block_Wool_White"
    },
    {
      "x": 0,
      "y": 21,
      "z": -12,
      "name": "Cloth_Block_Wool_White"
    },
    {
      "x": 0,
      "y": 37,
      "z": -12,
      "name": "Cloth_Block_Wool_White"
    },
    {
      "x": 0,
      "y": 19,
      "z": -11,
      "name": "Cloth_Block_Wool_White"
    },
    {
      "x": 0,
      "y": 20,
      "z": -11,
      "name": "Cloth_Block_Wool_White"
    },
    {
      "x": 0,
      "y": 38,
      "z": -11,
      "name": "Cloth_Block_Wool_White"
    },
    {
      "x": 0,
      "y": 17,
      "z": -10,
      "name": "Cloth_Block_Wool_White"
    },
    {
      "x": 0,
      "y": 18,
      "z": -10,
      "name": "Cloth_Block_Wool_White"
    },
    {
      "x": 0,
      "y": 19,
      "z": -10,
      "name": "Cloth_Block_Wool_Green"
    },
    {
      "x": 0,
      "y": 20,
      "z": -10,
      "name": "Cloth_Block_Wool_White"
    },
    {
      "x": 0,
      "y": 38,
      "z": -10,
      "name": "Cloth_Block_Wool_White"
    },
    {
      "x": 0,
      "y": 16,
      "z": -9,
      "name": "Cloth_Block_Wool_White"
    },
    {
      "x": 0,
      "y": 17,
      "z": -9,
      "name": "Cloth_Block_Wool_Green"
    },
    {
      "x": 0,
      "y": 18,
      "z": -9,
      "name": "Cloth_Block_Wool_Green"
    },
    {
      "x": 0,
      "y": 19,
      "z": -9,
      "name": "Cloth_Block_Wool_White"
    },
    {
      "x": 0,
      "y": 39,
      "z": -9,
      "name": "Cloth_Block_Wool_White"
    },
    {
      "x": 0,
      "y": 0,
      "z": -8,
      "name": "Wood_Hardwood_Stairs",
      "rotation": 2
    },
    {
      "x": 0,
      "y": 1,
      "z": -8,
      "name": "Deco_Iron_Bars"
    },
    {
      "x": 0,
      "y": 2,
      "z": -8,
      "name": "Deco_Iron_Bars"
    },
    {
      "x": 0,
      "y": 3,
      "z": -8,
      "name": "Deco_Iron_Bars"
    },
    {
      "x": 0,
      "y": 4,
      "z": -8,
      "name": "Wood_Hardwood_Planks_Half"
    },
    {
      "x": 0,
      "y": 9,
      "z": -8,
      "name": "Wood_Hardwood_Planks_Half",
      "rotation": 6
    },
    {
      "x": 0,
      "y": 12,
      "z": -8,
      "name": "Cloth_Block_Wool_White_Half",
      "rotation": 6
    },
    {
      "x": 0,
      "y": 13,
      "z": -8,
      "name": "Cloth_Block_Wool_White_Stairs",
      "rotation": 8
    },
    {
      "x": 0,
      "y": 14,
      "z": -8,
      "name": "Cloth_Block_Wool_White"
    },
    {
      "x": 0,
      "y": 15,
      "z": -8,
      "name": "Cloth_Block_Wool_White"
    },
    {
      "x": 0,
      "y": 16,
      "z": -8,
      "name": "Cloth_Block_Wool_Green"
    },
    {
      "x": 0,
      "y": 19,
      "z": -8,
      "name": "Cloth_Block_Wool_White"
    },
    {
      "x": 0,
      "y": 40,
      "z": -8,
      "name": "Cloth_Block_Wool_White_Half"
    },
    {
      "x": 0,
      "y": 0,
      "z": -7,
      "name": "Wood_Hardwood_Planks"
    },
    {
      "x": 0,
      "y": 4,
      "z": -7,
      "name": "Wood_Hardwood_Stairs",
      "rotation": 2
    },
    {
      "x": 0,
      "y": 8,
      "z": -7,
      "name": "Wood_Hardwood_Stairs",
      "rotation": 8
    },
    {
      "x": 0,
      "y": 9,
      "z": -7,
      "name": "Hotair_Balloon_Cage_Lever"
    },
    {
      "x": 0,
      "y": 12,
      "z": -7,
      "name": "Deco_Iron_Bars_Platforms",
      "rotation": 1
    },
    {
      "x": 0,
      "y": 19,
      "z": -7,
      "name": "Cloth_Block_Wool_Green"
    },
    {
      "x": 0,
      "y": 40,
      "z": -7,
      "name": "Cloth_Block_Wool_Green"
    },
    {
      "x": 0,
      "y": 0,
      "z": -6,
      "name": "Wood_Hardwood_Planks"
    },
    {
      "x": 0,
      "y": 4,
      "z": -6,
      "name": "Wood_Hardwood_Planks"
    },
    {
      "x": 0,
      "y": 5,
      "z": -6,
      "name": "Deco_Iron_Chain_Small"
    },
    {
      "x": 0,
      "y": 6,
      "z": -6,
      "name": "Deco_Iron_Chain_Small"
    },
    {
      "x": 0,
      "y": 7,
      "z": -6,
      "name": "Deco_Iron_Chain_Small"
    },
    {
      "x": 0,
      "y": 8,
      "z": -6,
      "name": "Wood_Hardwood_Planks"
    },
    {
      "x": 0,
      "y": 11,
      "z": -6,
      "name": "Hotair_Balloon_Chain"
    },
    {
      "x": 0,
      "y": 12,
      "z": -6,
      "name": "Hotair_Balloon_Burner",
      "support": 15,
      "rotation": 8
    },
    {
      "x": 0,
      "y": 19,
      "z": -6,
      "name": "Cloth_Block_Wool_Green"
    },
    {
      "x": 0,
      "y": 40,
      "z": -6,
      "name": "Cloth_Block_Wool_Green"
    },
    {
      "x": 0,
      "y": 0,
      "z": -5,
      "name": "Wood_Hardwood_Planks"
    },
    {
      "x": 0,
      "y": 4,
      "z": -5,
      "name": "Wood_Hardwood_Stairs"
    },
    {
      "x": 0,
      "y": 8,
      "z": -5,
      "name": "Wood_Hardwood_Stairs",
      "rotation": 10
    },
    {
      "x": 0,
      "y": 9,
      "z": -5,
      "name": "Hotair_Balloon_Cage_Gate_Lever"
    },
    {
      "x": 0,
      "y": 12,
      "z": -5,
      "name": "Deco_Iron_Bars_Platforms",
      "rotation": 1
    },
    {
      "x": 0,
      "y": 19,
      "z": -5,
      "name": "Cloth_Block_Wool_Green"
    },
    {
      "x": 0,
      "y": 40,
      "z": -5,
      "name": "Cloth_Block_Wool_Green"
    },
    {
      "x": 0,
      "y": 0,
      "z": -4,
      "name": "Wood_Hardwood_Stairs"
    },
    {
      "x": 0,
      "y": 1,
      "z": -4,
      "name": "Deco_Iron_Bars"
    },
    {
      "x": 0,
      "y": 3,
      "z": -4,
      "name": "Deco_Iron_Bars"
    },
    {
      "x": 0,
      "y": 4,
      "z": -4,
      "name": "Wood_Hardwood_Planks_Half"
    },
    {
      "x": 0,
      "y": 9,
      "z": -4,
      "name": "Wood_Hardwood_Planks"
    },
    {
      "x": 0,
      "y": 12,
      "z": -4,
      "name": "Cloth_Block_Wool_White_Half",
      "rotation": 4
    },
    {
      "x": 0,
      "y": 13,
      "z": -4,
      "name": "Cloth_Block_Wool_White_Stairs",
      "rotation": 10
    },
    {
      "x": 0,
      "y": 14,
      "z": -4,
      "name": "Cloth_Block_Wool_White"
    },
    {
      "x": 0,
      "y": 15,
      "z": -4,
      "name": "Cloth_Block_Wool_White"
    },
    {
      "x": 0,
      "y": 16,
      "z": -4,
      "name": "Cloth_Block_Wool_Green"
    },
    {
      "x": 0,
      "y": 19,
      "z": -4,
      "name": "Cloth_Block_Wool_White"
    },
    {
      "x": 0,
      "y": 40,
      "z": -4,
      "name": "Cloth_Block_Wool_White_Half"
    },
    {
      "x": 0,
      "y": 3,
      "z": -3,
      "name": "Furniture_Kweebec_Ladder"
    },
    {
      "x": 0,
      "y": 4,
      "z": -3,
      "name": "Furniture_Kweebec_Ladder"
    },
    {
      "x": 0,
      "y": 5,
      "z": -3,
      "name": "Furniture_Kweebec_Ladder"
    },
    {
      "x": 0,
      "y": 6,
      "z": -3,
      "name": "Furniture_Kweebec_Ladder"
    },
    {
      "x": 0,
      "y": 7,
      "z": -3,
      "name": "Furniture_Kweebec_Ladder"
    },
    {
      "x": 0,
      "y": 8,
      "z": -3,
      "name": "Furniture_Kweebec_Ladder"
    },
    {
      "x": 0,
      "y": 9,
      "z": -3,
      "name": "Furniture_Kweebec_Ladder"
    },
    {
      "x": 0,
      "y": 16,
      "z": -3,
      "name": "Cloth_Block_Wool_White"
    },
    {
      "x": 0,
      "y": 17,
      "z": -3,
      "name": "Cloth_Block_Wool_Green"
    },
    {
      "x": 0,
      "y": 18,
      "z": -3,
      "name": "Cloth_Block_Wool_Green"
    },
    {
      "x": 0,
      "y": 19,
      "z": -3,
      "name": "Cloth_Block_Wool_White"
    },
    {
      "x": 0,
      "y": 39,
      "z": -3,
      "name": "Cloth_Block_Wool_White"
    },
    {
      "x": 0,
      "y": 17,
      "z": -2,
      "name": "Cloth_Block_Wool_White"
    },
    {
      "x": 0,
      "y": 18,
      "z": -2,
      "name": "Cloth_Block_Wool_White"
    },
    {
      "x": 0,
      "y": 19,
      "z": -2,
      "name": "Cloth_Block_Wool_Green"
    },
    {
      "x": 0,
      "y": 20,
      "z": -2,
      "name": "Cloth_Block_Wool_White"
    },
    {
      "x": 0,
      "y": 38,
      "z": -2,
      "name": "Cloth_Block_Wool_White"
    },
    {
      "x": 0,
      "y": 19,
      "z": -1,
      "name": "Cloth_Block_Wool_White"
    },
    {
      "x": 0,
      "y": 20,
      "z": -1,
      "name": "Cloth_Block_Wool_White"
    },
    {
      "x": 0,
      "y": 38,
      "z": -1,
      "name": "Cloth_Block_Wool_White"
    },
    {
      "x": 0,
      "y": 21,
      "z": 0,
      "name": "Cloth_Block_Wool_White"
    },
    {
      "x": 0,
      "y": 37,
      "z": 0,
      "name": "Cloth_Block_Wool_White"
    },
    {
      "x": 0,
      "y": 22,
      "z": 1,
      "name": "Cloth_Block_Wool_White"
    },
    {
      "x": 0,
      "y": 36,
      "z": 1,
      "name": "Cloth_Block_Wool_White"
    },
    {
      "x": 0,
      "y": 23,
      "z": 2,
      "name": "Cloth_Block_Wool_White"
    },
    {
      "x": 0,
      "y": 35,
      "z": 2,
      "name": "Cloth_Block_Wool_White"
    },
    {
      "x": 0,
      "y": 24,
      "z": 3,
      "name": "Cloth_Block_Wool_White"
    },
    {
      "x": 0,
      "y": 25,
      "z": 3,
      "name": "Cloth_Block_Wool_White"
    },
    {
      "x": 0,
      "y": 33,
      "z": 3,
      "name": "Cloth_Block_Wool_White"
    },
    {
      "x": 0,
      "y": 34,
      "z": 3,
      "name": "Cloth_Block_Wool_White"
    },
    {
      "x": 0,
      "y": 26,
      "z": 4,
      "name": "Cloth_Block_Wool_White"
    },
    {
      "x": 0,
      "y": 27,
      "z": 4,
      "name": "Cloth_Block_Wool_White"
    },
    {
      "x": 0,
      "y": 31,
      "z": 4,
      "name": "Cloth_Block_Wool_White"
    },
    {
      "x": 0,
      "y": 32,
      "z": 4,
      "name": "Cloth_Block_Wool_White"
    },
    {
      "x": 0,
      "y": 28,
      "z": 5,
      "name": "Cloth_Block_Wool_White_Half",
      "rotation": 4
    },
    {
      "x": 0,
      "y": 29,
      "z": 5,
      "name": "Cloth_Block_Wool_White_Half",
      "rotation": 4
    },
    {
      "x": 0,
      "y": 30,
      "z": 5,
      "name": "Cloth_Block_Wool_White_Half",
      "rotation": 4
    },
    {
      "x": 1,
      "y": 26,
      "z": -16,
      "name": "Cloth_Block_Wool_White"
    },
    {
      "x": 1,
      "y": 27,
      "z": -16,
      "name": "Cloth_Block_Wool_White"
    },
    {
      "x": 1,
      "y": 28,
      "z": -16,
      "name": "Cloth_Block_Wool_White"
    },
    {
      "x": 1,
      "y": 29,
      "z": -16,
      "name": "Cloth_Block_Wool_White"
    },
    {
      "x": 1,
      "y": 30,
      "z": -16,
      "name": "Cloth_Block_Wool_White"
    },
    {
      "x": 1,
      "y": 31,
      "z": -16,
      "name": "Cloth_Block_Wool_White"
    },
    {
      "x": 1,
      "y": 32,
      "z": -16,
      "name": "Cloth_Block_Wool_White"
    },
    {
      "x": 1,
      "y": 24,
      "z": -15,
      "name": "Cloth_Block_Wool_White"
    },
    {
      "x": 1,
      "y": 25,
      "z": -15,
      "name": "Cloth_Block_Wool_White"
    },
    {
      "x": 1,
      "y": 33,
      "z": -15,
      "name": "Cloth_Block_Wool_White"
    },
    {
      "x": 1,
      "y": 34,
      "z": -15,
      "name": "Cloth_Block_Wool_White"
    },
    {
      "x": 1,
      "y": 23,
      "z": -14,
      "name": "Cloth_Block_Wool_White"
    },
    {
      "x": 1,
      "y": 35,
      "z": -14,
      "name": "Cloth_Block_Wool_White"
    },
    {
      "x": 1,
      "y": 22,
      "z": -13,
      "name": "Cloth_Block_Wool_White"
    },
    {
      "x": 1,
      "y": 36,
      "z": -13,
      "name": "Cloth_Block_Wool_White"
    },
    {
      "x": 1,
      "y": 21,
      "z": -12,
      "name": "Cloth_Block_Wool_White"
    },
    {
      "x": 1,
      "y": 37,
      "z": -12,
      "name": "Cloth_Block_Wool_White"
    },
    {
      "x": 1,
      "y": 19,
      "z": -11,
      "name": "Cloth_Block_Wool_Green"
    },
    {
      "x": 1,
      "y": 20,
      "z": -11,
      "name": "Cloth_Block_Wool_Green"
    },
    {
      "x": 1,
      "y": 38,
      "z": -11,
      "name": "Cloth_Block_Wool_White"
    },
    {
      "x": 1,
      "y": 18,
      "z": -10,
      "name": "Cloth_Block_Wool_Green"
    },
    {
      "x": 1,
      "y": 19,
      "z": -10,
      "name": "Cloth_Block_Wool_Green"
    },
    {
      "x": 1,
      "y": 20,
      "z": -10,
      "name": "Cloth_Block_Wool_White"
    },
    {
      "x": 1,
      "y": 38,
      "z": -10,
      "name": "Cloth_Block_Wool_White"
    },
    {
      "x": 1,
      "y": 16,
      "z": -9,
      "name": "Cloth_Block_Wool_Green"
    },
    {
      "x": 1,
      "y": 17,
      "z": -9,
      "name": "Cloth_Block_Wool_Green"
    },
    {
      "x": 1,
      "y": 18,
      "z": -9,
      "name": "Cloth_Block_Wool_Green"
    },
    {
      "x": 1,
      "y": 19,
      "z": -9,
      "name": "Cloth_Block_Wool_White"
    },
    {
      "x": 1,
      "y": 39,
      "z": -9,
      "name": "Cloth_Block_Wool_Green"
    },
    {
      "x": 1,
      "y": 0,
      "z": -8,
      "name": "Wood_Hardwood_Stairs",
      "rotation": 2
    },
    {
      "x": 1,
      "y": 1,
      "z": -8,
      "name": "Deco_Iron_Bars"
    },
    {
      "x": 1,
      "y": 2,
      "z": -8,
      "name": "Deco_Iron_Bars"
    },
    {
      "x": 1,
      "y": 3,
      "z": -8,
      "name": "Deco_Iron_Bars"
    },
    {
      "x": 1,
      "y": 4,
      "z": -8,
      "name": "Wood_Hardwood_Planks_Half"
    },
    {
      "x": 1,
      "y": 9,
      "z": -8,
      "name": "Wood_Hardwood_Planks_Half",
      "rotation": 6
    },
    {
      "x": 1,
      "y": 12,
      "z": -8,
      "name": "Cloth_Block_Wool_Green_Half",
      "rotation": 6
    },
    {
      "x": 1,
      "y": 13,
      "z": -8,
      "name": "Cloth_Block_Wool_Green_Stairs",
      "rotation": 8
    },
    {
      "x": 1,
      "y": 14,
      "z": -8,
      "name": "Cloth_Block_Wool_Green"
    },
    {
      "x": 1,
      "y": 15,
      "z": -8,
      "name": "Cloth_Block_Wool_Green"
    },
    {
      "x": 1,
      "y": 16,
      "z": -8,
      "name": "Cloth_Block_Wool_Green"
    },
    {
      "x": 1,
      "y": 19,
      "z": -8,
      "name": "Cloth_Block_Wool_Green"
    },
    {
      "x": 1,
      "y": 39,
      "z": -8,
      "name": "Cloth_Block_Wool_Green"
    },
    {
      "x": 1,
      "y": 0,
      "z": -7,
      "name": "Wood_Hardwood_Planks"
    },
    {
      "x": 1,
      "y": 4,
      "z": -7,
      "name": "*Wood_Hardwood_Stairs_State_Definitions_Corner_Right",
      "rotation": 2
    },
    {
      "x": 1,
      "y": 8,
      "z": -7,
      "name": "*Wood_Hardwood_Stairs_State_Definitions_Corner_Right",
      "rotation": 11
    },
    {
      "x": 1,
      "y": 9,
      "z": -7,
      "name": "Wood_Hardwood_Planks"
    },
    {
      "x": 1,
      "y": 10,
      "z": -7,
      "name": "Deco_Iron_Chain_Small"
    },
    {
      "x": 1,
      "y": 11,
      "z": -7,
      "name": "Deco_Iron_Chain_Small"
    },
    {
      "x": 1,
      "y": 12,
      "z": -7,
      "name": "Deco_Iron_Chain_Small"
    },
    {
      "x": 1,
      "y": 13,
      "z": -7,
      "name": "Wood_Hardwood_Planks"
    },
    {
      "x": 1,
      "y": 19,
      "z": -7,
      "name": "Cloth_Block_Wool_Green"
    },
    {
      "x": 1,
      "y": 40,
      "z": -7,
      "name": "Cloth_Block_Wool_Green_Half",
      "rotation": 2
    },
    {
      "x": 1,
      "y": 0,
      "z": -6,
      "name": "Wood_Hardwood_Planks"
    },
    {
      "x": 1,
      "y": 4,
      "z": -6,
      "name": "Wood_Hardwood_Stairs",
      "rotation": 1
    },
    {
      "x": 1,
      "y": 8,
      "z": -6,
      "name": "Wood_Hardwood_Stairs",
      "rotation": 11
    },
    {
      "x": 1,
      "y": 9,
      "z": -6,
      "name": "Wood_Hardwood_Planks_Half",
      "rotation": 8
    },
    {
      "x": 1,
      "y": 10,
      "z": -6,
      "name": "Furniture_Crude_Candle"
    },
    {
      "x": 1,
      "y": 12,
      "z": -6,
      "name": "Deco_Iron_Bars_Platforms"
    },
    {
      "x": 1,
      "y": 19,
      "z": -6,
      "name": "Cloth_Block_Wool_Green"
    },
    {
      "x": 1,
      "y": 40,
      "z": -6,
      "name": "Cloth_Block_Wool_Green"
    },
    {
      "x": 1,
      "y": 0,
      "z": -5,
      "name": "Wood_Hardwood_Planks"
    },
    {
      "x": 1,
      "y": 4,
      "z": -5,
      "name": "*Wood_Hardwood_Stairs_State_Definitions_Corner_Right",
      "rotation": 1
    },
    {
      "x": 1,
      "y": 8,
      "z": -5,
      "name": "*Wood_Hardwood_Stairs_State_Definitions_Corner_Left",
      "rotation": 11
    },
    {
      "x": 1,
      "y": 9,
      "z": -5,
      "name": "Wood_Hardwood_Planks"
    },
    {
      "x": 1,
      "y": 10,
      "z": -5,
      "name": "Deco_Iron_Chain_Small"
    },
    {
      "x": 1,
      "y": 11,
      "z": -5,
      "name": "Deco_Iron_Chain_Small"
    },
    {
      "x": 1,
      "y": 12,
      "z": -5,
      "name": "Deco_Iron_Chain_Small"
    },
    {
      "x": 1,
      "y": 13,
      "z": -5,
      "name": "Wood_Hardwood_Planks"
    },
    {
      "x": 1,
      "y": 19,
      "z": -5,
      "name": "Cloth_Block_Wool_Green"
    },
    {
      "x": 1,
      "y": 40,
      "z": -5,
      "name": "Cloth_Block_Wool_Green_Half",
      "rotation": 2
    },
    {
      "x": 1,
      "y": 0,
      "z": -4,
      "name": "Wood_Hardwood_Stairs"
    },
    {
      "x": 1,
      "y": 1,
      "z": -4,
      "name": "Deco_Iron_Bars"
    },
    {
      "x": 1,
      "y": 2,
      "z": -4,
      "name": "Deco_Iron_Bars"
    },
    {
      "x": 1,
      "y": 3,
      "z": -4,
      "name": "Deco_Iron_Bars"
    },
    {
      "x": 1,
      "y": 4,
      "z": -4,
      "name": "Wood_Hardwood_Planks_Half"
    },
    {
      "x": 1,
      "y": 9,
      "z": -4,
      "name": "Wood_Hardwood_Planks_Half",
      "rotation": 4
    },
    {
      "x": 1,
      "y": 12,
      "z": -4,
      "name": "Cloth_Block_Wool_Green_Half",
      "rotation": 4
    },
    {
      "x": 1,
      "y": 13,
      "z": -4,
      "name": "Cloth_Block_Wool_Green_Stairs",
      "rotation": 10
    },
    {
      "x": 1,
      "y": 14,
      "z": -4,
      "name": "Cloth_Block_Wool_Green"
    },
    {
      "x": 1,
      "y": 15,
      "z": -4,
      "name": "Cloth_Block_Wool_Green"
    },
    {
      "x": 1,
      "y": 16,
      "z": -4,
      "name": "Cloth_Block_Wool_Green"
    },
    {
      "x": 1,
      "y": 19,
      "z": -4,
      "name": "Cloth_Block_Wool_Green"
    },
    {
      "x": 1,
      "y": 39,
      "z": -4,
      "name": "Cloth_Block_Wool_Green"
    },
    {
      "x": 1,
      "y": 16,
      "z": -3,
      "name": "Cloth_Block_Wool_Green"
    },
    {
      "x": 1,
      "y": 17,
      "z": -3,
      "name": "Cloth_Block_Wool_Green"
    },
    {
      "x": 1,
      "y": 18,
      "z": -3,
      "name": "Cloth_Block_Wool_Green"
    },
    {
      "x": 1,
      "y": 19,
      "z": -3,
      "name": "Cloth_Block_Wool_White"
    },
    {
      "x": 1,
      "y": 39,
      "z": -3,
      "name": "Cloth_Block_Wool_Green"
    },
    {
      "x": 1,
      "y": 18,
      "z": -2,
      "name": "Cloth_Block_Wool_Green"
    },
    {
      "x": 1,
      "y": 19,
      "z": -2,
      "name": "Cloth_Block_Wool_Green"
    },
    {
      "x": 1,
      "y": 20,
      "z": -2,
      "name": "Cloth_Block_Wool_White"
    },
    {
      "x": 1,
      "y": 38,
      "z": -2,
      "name": "Cloth_Block_Wool_White"
    },
    {
      "x": 1,
      "y": 19,
      "z": -1,
      "name": "Cloth_Block_Wool_Green"
    },
    {
      "x": 1,
      "y": 20,
      "z": -1,
      "name": "Cloth_Block_Wool_Green"
    },
    {
      "x": 1,
      "y": 38,
      "z": -1,
      "name": "Cloth_Block_Wool_White"
    },
    {
      "x": 1,
      "y": 21,
      "z": 0,
      "name": "Cloth_Block_Wool_White"
    },
    {
      "x": 1,
      "y": 37,
      "z": 0,
      "name": "Cloth_Block_Wool_White"
    },
    {
      "x": 1,
      "y": 22,
      "z": 1,
      "name": "Cloth_Block_Wool_White"
    },
    {
      "x": 1,
      "y": 36,
      "z": 1,
      "name": "Cloth_Block_Wool_White"
    },
    {
      "x": 1,
      "y": 23,
      "z": 2,
      "name": "Cloth_Block_Wool_White"
    },
    {
      "x": 1,
      "y": 35,
      "z": 2,
      "name": "Cloth_Block_Wool_White"
    },
    {
      "x": 1,
      "y": 24,
      "z": 3,
      "name": "Cloth_Block_Wool_White"
    },
    {
      "x": 1,
      "y": 25,
      "z": 3,
      "name": "Cloth_Block_Wool_White"
    },
    {
      "x": 1,
      "y": 33,
      "z": 3,
      "name": "Cloth_Block_Wool_White"
    },
    {
      "x": 1,
      "y": 34,
      "z": 3,
      "name": "Cloth_Block_Wool_White"
    },
    {
      "x": 1,
      "y": 26,
      "z": 4,
      "name": "Cloth_Block_Wool_White"
    },
    {
      "x": 1,
      "y": 27,
      "z": 4,
      "name": "Cloth_Block_Wool_White"
    },
    {
      "x": 1,
      "y": 28,
      "z": 4,
      "name": "Cloth_Block_Wool_White"
    },
    {
      "x": 1,
      "y": 29,
      "z": 4,
      "name": "Cloth_Block_Wool_White"
    },
    {
      "x": 1,
      "y": 30,
      "z": 4,
      "name": "Cloth_Block_Wool_White"
    },
    {
      "x": 1,
      "y": 31,
      "z": 4,
      "name": "Cloth_Block_Wool_White"
    },
    {
      "x": 1,
      "y": 32,
      "z": 4,
      "name": "Cloth_Block_Wool_White"
    },
    {
      "x": 2,
      "y": 27,
      "z": -16,
      "name": "Cloth_Block_Wool_Green"
    },
    {
      "x": 2,
      "y": 28,
      "z": -16,
      "name": "Cloth_Block_Wool_Green"
    },
    {
      "x": 2,
      "y": 29,
      "z": -16,
      "name": "Cloth_Block_Wool_Green"
    },
    {
      "x": 2,
      "y": 30,
      "z": -16,
      "name": "Cloth_Block_Wool_Green"
    },
    {
      "x": 2,
      "y": 31,
      "z": -16,
      "name": "Cloth_Block_Wool_Green"
    },
    {
      "x": 2,
      "y": 24,
      "z": -15,
      "name": "Cloth_Block_Wool_Green"
    },
    {
      "x": 2,
      "y": 25,
      "z": -15,
      "name": "Cloth_Block_Wool_Green"
    },
    {
      "x": 2,
      "y": 26,
      "z": -15,
      "name": "Cloth_Block_Wool_Green"
    },
    {
      "x": 2,
      "y": 32,
      "z": -15,
      "name": "Cloth_Block_Wool_Green"
    },
    {
      "x": 2,
      "y": 33,
      "z": -15,
      "name": "Cloth_Block_Wool_Green"
    },
    {
      "x": 2,
      "y": 34,
      "z": -15,
      "name": "Cloth_Block_Wool_Green"
    },
    {
      "x": 2,
      "y": 23,
      "z": -14,
      "name": "Cloth_Block_Wool_Green"
    },
    {
      "x": 2,
      "y": 35,
      "z": -14,
      "name": "Cloth_Block_Wool_Green"
    },
    {
      "x": 2,
      "y": 22,
      "z": -13,
      "name": "Cloth_Block_Wool_Green"
    },
    {
      "x": 2,
      "y": 36,
      "z": -13,
      "name": "Cloth_Block_Wool_Green"
    },
    {
      "x": 2,
      "y": 21,
      "z": -12,
      "name": "Cloth_Block_Wool_Green"
    },
    {
      "x": 2,
      "y": 37,
      "z": -12,
      "name": "Cloth_Block_Wool_Green"
    },
    {
      "x": 2,
      "y": 20,
      "z": -11,
      "name": "Cloth_Block_Wool_Green"
    },
    {
      "x": 2,
      "y": 38,
      "z": -11,
      "name": "Cloth_Block_Wool_Green"
    },
    {
      "x": 2,
      "y": 19,
      "z": -10,
      "name": "Cloth_Block_Wool_Green"
    },
    {
      "x": 2,
      "y": 20,
      "z": -10,
      "name": "Cloth_Block_Wool_Green"
    },
    {
      "x": 2,
      "y": 38,
      "z": -10,
      "name": "Cloth_Block_Wool_Green"
    },
    {
      "x": 2,
      "y": 18,
      "z": -9,
      "name": "Cloth_Block_Wool_Green"
    },
    {
      "x": 2,
      "y": 19,
      "z": -9,
      "name": "Cloth_Block_Wool_Green"
    },
    {
      "x": 2,
      "y": 20,
      "z": -9,
      "name": "Cloth_Block_Wool_White"
    },
    {
      "x": 2,
      "y": 38,
      "z": -9,
      "name": "Cloth_Block_Wool_Green"
    },
    {
      "x": 2,
      "y": 0,
      "z": -8,
      "name": "Wood_Hardwood_Planks"
    },
    {
      "x": 2,
      "y": 1,
      "z": -8,
      "name": "Deco_Iron_Bars_Corner"
    },
    {
      "x": 2,
      "y": 2,
      "z": -8,
      "name": "Deco_Iron_Bars_Corner"
    },
    {
      "x": 2,
      "y": 3,
      "z": -8,
      "name": "Deco_Iron_Bars_Corner"
    },
    {
      "x": 2,
      "y": 4,
      "z": -8,
      "name": "Wood_Hardwood_Planks_Half"
    },
    {
      "x": 2,
      "y": 16,
      "z": -8,
      "name": "Cloth_Block_Wool_Green"
    },
    {
      "x": 2,
      "y": 17,
      "z": -8,
      "name": "Cloth_Block_Wool_Green"
    },
    {
      "x": 2,
      "y": 18,
      "z": -8,
      "name": "Cloth_Block_Wool_Green"
    },
    {
      "x": 2,
      "y": 19,
      "z": -8,
      "name": "Cloth_Block_Wool_White"
    },
    {
      "x": 2,
      "y": 39,
      "z": -8,
      "name": "Cloth_Block_Wool_Green"
    },
    {
      "x": 2,
      "y": 0,
      "z": -7,
      "name": "Wood_Hardwood_Stairs",
      "rotation": 1
    },
    {
      "x": 2,
      "y": 1,
      "z": -7,
      "name": "Deco_Iron_Bars",
      "rotation": 1
    },
    {
      "x": 2,
      "y": 2,
      "z": -7,
      "name": "Deco_Iron_Bars",
      "rotation": 1
    },
    {
      "x": 2,
      "y": 3,
      "z": -7,
      "name": "Deco_Iron_Bars",
      "rotation": 1
    },
    {
      "x": 2,
      "y": 4,
      "z": -7,
      "name": "Wood_Hardwood_Planks_Half"
    },
    {
      "x": 2,
      "y": 9,
      "z": -7,
      "name": "Wood_Hardwood_Planks_Half",
      "rotation": 5
    },
    {
      "x": 2,
      "y": 12,
      "z": -7,
      "name": "Cloth_Block_Wool_Green_Half",
      "rotation": 5
    },
    {
      "x": 2,
      "y": 13,
      "z": -7,
      "name": "Cloth_Block_Wool_Green_Stairs",
      "rotation": 11
    },
    {
      "x": 2,
      "y": 14,
      "z": -7,
      "name": "Cloth_Block_Wool_Green"
    },
    {
      "x": 2,
      "y": 15,
      "z": -7,
      "name": "Cloth_Block_Wool_Green"
    },
    {
      "x": 2,
      "y": 16,
      "z": -7,
      "name": "Cloth_Block_Wool_Green"
    },
    {
      "x": 2,
      "y": 19,
      "z": -7,
      "name": "Cloth_Block_Wool_Green"
    },
    {
      "x": 2,
      "y": 39,
      "z": -7,
      "name": "Cloth_Block_Wool_Green"
    },
    {
      "x": 2,
      "y": 0,
      "z": -6,
      "name": "Wood_Hardwood_Stairs",
      "rotation": 1
    },
    {
      "x": 2,
      "y": 1,
      "z": -6,
      "name": "Deco_Iron_Bars",
      "rotation": 1
    },
    {
      "x": 2,
      "y": 2,
      "z": -6,
      "name": "Deco_Iron_Bars",
      "rotation": 1
    },
    {
      "x": 2,
      "y": 3,
      "z": -6,
      "name": "Deco_Iron_Bars",
      "rotation": 1
    },
    {
      "x": 2,
      "y": 4,
      "z": -6,
      "name": "Wood_Hardwood_Planks_Half"
    },
    {
      "x": 2,
      "y": 9,
      "z": -6,
      "name": "Wood_Hardwood_Planks_Half",
      "rotation": 5
    },
    {
      "x": 2,
      "y": 12,
      "z": -6,
      "name": "Cloth_Block_Wool_White_Half",
      "rotation": 5
    },
    {
      "x": 2,
      "y": 13,
      "z": -6,
      "name": "Cloth_Block_Wool_White_Stairs",
      "rotation": 11
    },
    {
      "x": 2,
      "y": 14,
      "z": -6,
      "name": "Cloth_Block_Wool_White"
    },
    {
      "x": 2,
      "y": 15,
      "z": -6,
      "name": "Cloth_Block_Wool_White"
    },
    {
      "x": 2,
      "y": 16,
      "z": -6,
      "name": "Cloth_Block_Wool_Green"
    },
    {
      "x": 2,
      "y": 19,
      "z": -6,
      "name": "Cloth_Block_Wool_White"
    },
    {
      "x": 2,
      "y": 40,
      "z": -6,
      "name": "Cloth_Block_Wool_White_Half"
    },
    {
      "x": 2,
      "y": 0,
      "z": -5,
      "name": "Wood_Hardwood_Stairs",
      "rotation": 1
    },
    {
      "x": 2,
      "y": 1,
      "z": -5,
      "name": "Deco_Iron_Bars",
      "rotation": 1
    },
    {
      "x": 2,
      "y": 2,
      "z": -5,
      "name": "Deco_Iron_Bars",
      "rotation": 1
    },
    {
      "x": 2,
      "y": 3,
      "z": -5,
      "name": "Deco_Iron_Bars",
      "rotation": 1
    },
    {
      "x": 2,
      "y": 4,
      "z": -5,
      "name": "Wood_Hardwood_Planks_Half"
    },
    {
      "x": 2,
      "y": 9,
      "z": -5,
      "name": "Wood_Hardwood_Planks_Half",
      "rotation": 5
    },
    {
      "x": 2,
      "y": 12,
      "z": -5,
      "name": "Cloth_Block_Wool_Green_Half",
      "rotation": 5
    },
    {
      "x": 2,
      "y": 13,
      "z": -5,
      "name": "Cloth_Block_Wool_Green_Stairs",
      "rotation": 11
    },
    {
      "x": 2,
      "y": 14,
      "z": -5,
      "name": "Cloth_Block_Wool_Green"
    },
    {
      "x": 2,
      "y": 15,
      "z": -5,
      "name": "Cloth_Block_Wool_Green"
    },
    {
      "x": 2,
      "y": 16,
      "z": -5,
      "name": "Cloth_Block_Wool_Green"
    },
    {
      "x": 2,
      "y": 19,
      "z": -5,
      "name": "Cloth_Block_Wool_Green"
    },
    {
      "x": 2,
      "y": 39,
      "z": -5,
      "name": "Cloth_Block_Wool_Green"
    },
    {
      "x": 2,
      "y": 0,
      "z": -4,
      "name": "Wood_Hardwood_Planks"
    },
    {
      "x": 2,
      "y": 1,
      "z": -4,
      "name": "Deco_Iron_Bars_Corner",
      "rotation": 3
    },
    {
      "x": 2,
      "y": 2,
      "z": -4,
      "name": "Deco_Iron_Bars_Corner",
      "rotation": 3
    },
    {
      "x": 2,
      "y": 3,
      "z": -4,
      "name": "Deco_Iron_Bars_Corner",
      "rotation": 3
    },
    {
      "x": 2,
      "y": 4,
      "z": -4,
      "name": "Wood_Hardwood_Planks_Half"
    },
    {
      "x": 2,
      "y": 16,
      "z": -4,
      "name": "Cloth_Block_Wool_Green"
    },
    {
      "x": 2,
      "y": 17,
      "z": -4,
      "name": "Cloth_Block_Wool_Green"
    },
    {
      "x": 2,
      "y": 18,
      "z": -4,
      "name": "Cloth_Block_Wool_Green"
    },
    {
      "x": 2,
      "y": 19,
      "z": -4,
      "name": "Cloth_Block_Wool_White"
    },
    {
      "x": 2,
      "y": 39,
      "z": -4,
      "name": "Cloth_Block_Wool_Green"
    },
    {
      "x": 2,
      "y": 18,
      "z": -3,
      "name": "Cloth_Block_Wool_Green"
    },
    {
      "x": 2,
      "y": 19,
      "z": -3,
      "name": "Cloth_Block_Wool_Green"
    },
    {
      "x": 2,
      "y": 20,
      "z": -3,
      "name": "Cloth_Block_Wool_White"
    },
    {
      "x": 2,
      "y": 38,
      "z": -3,
      "name": "Cloth_Block_Wool_Green"
    },
    {
      "x": 2,
      "y": 19,
      "z": -2,
      "name": "Cloth_Block_Wool_Green"
    },
    {
      "x": 2,
      "y": 20,
      "z": -2,
      "name": "Cloth_Block_Wool_Green"
    },
    {
      "x": 2,
      "y": 38,
      "z": -2,
      "name": "Cloth_Block_Wool_Green"
    },
    {
      "x": 2,
      "y": 20,
      "z": -1,
      "name": "Cloth_Block_Wool_Green"
    },
    {
      "x": 2,
      "y": 38,
      "z": -1,
      "name": "Cloth_Block_Wool_Green"
    },
    {
      "x": 2,
      "y": 21,
      "z": 0,
      "name": "Cloth_Block_Wool_Green"
    },
    {
      "x": 2,
      "y": 37,
      "z": 0,
      "name": "Cloth_Block_Wool_Green"
    },
    {
      "x": 2,
      "y": 22,
      "z": 1,
      "name": "Cloth_Block_Wool_Green"
    },
    {
      "x": 2,
      "y": 36,
      "z": 1,
      "name": "Cloth_Block_Wool_Green"
    },
    {
      "x": 2,
      "y": 23,
      "z": 2,
      "name": "Cloth_Block_Wool_Green"
    },
    {
      "x": 2,
      "y": 35,
      "z": 2,
      "name": "Cloth_Block_Wool_Green"
    },
    {
      "x": 2,
      "y": 24,
      "z": 3,
      "name": "Cloth_Block_Wool_Green"
    },
    {
      "x": 2,
      "y": 25,
      "z": 3,
      "name": "Cloth_Block_Wool_Green"
    },
    {
      "x": 2,
      "y": 26,
      "z": 3,
      "name": "Cloth_Block_Wool_Green"
    },
    {
      "x": 2,
      "y": 32,
      "z": 3,
      "name": "Cloth_Block_Wool_Green"
    },
    {
      "x": 2,
      "y": 33,
      "z": 3,
      "name": "Cloth_Block_Wool_Green"
    },
    {
      "x": 2,
      "y": 34,
      "z": 3,
      "name": "Cloth_Block_Wool_Green"
    },
    {
      "x": 2,
      "y": 27,
      "z": 4,
      "name": "Cloth_Block_Wool_Green"
    },
    {
      "x": 2,
      "y": 28,
      "z": 4,
      "name": "Cloth_Block_Wool_Green"
    },
    {
      "x": 2,
      "y": 29,
      "z": 4,
      "name": "Cloth_Block_Wool_Green"
    },
    {
      "x": 2,
      "y": 30,
      "z": 4,
      "name": "Cloth_Block_Wool_Green"
    },
    {
      "x": 2,
      "y": 31,
      "z": 4,
      "name": "Cloth_Block_Wool_Green"
    },
    {
      "x": 3,
      "y": 28,
      "z": -16,
      "name": "Cloth_Block_Wool_Green"
    },
    {
      "x": 3,
      "y": 29,
      "z": -16,
      "name": "Cloth_Block_Wool_Green"
    },
    {
      "x": 3,
      "y": 30,
      "z": -16,
      "name": "Cloth_Block_Wool_Green"
    },
    {
      "x": 3,
      "y": 25,
      "z": -15,
      "name": "Cloth_Block_Wool_Green"
    },
    {
      "x": 3,
      "y": 26,
      "z": -15,
      "name": "Cloth_Block_Wool_Green"
    },
    {
      "x": 3,
      "y": 27,
      "z": -15,
      "name": "Cloth_Block_Wool_Green"
    },
    {
      "x": 3,
      "y": 31,
      "z": -15,
      "name": "Cloth_Block_Wool_Green"
    },
    {
      "x": 3,
      "y": 32,
      "z": -15,
      "name": "Cloth_Block_Wool_Green"
    },
    {
      "x": 3,
      "y": 33,
      "z": -15,
      "name": "Cloth_Block_Wool_Green"
    },
    {
      "x": 3,
      "y": 23,
      "z": -14,
      "name": "Cloth_Block_Wool_Green"
    },
    {
      "x": 3,
      "y": 24,
      "z": -14,
      "name": "Cloth_Block_Wool_Green"
    },
    {
      "x": 3,
      "y": 34,
      "z": -14,
      "name": "Cloth_Block_Wool_Green"
    },
    {
