{
    "version": 8,
    "blockIdVersion": 11,
    "anchorX": 0,
    "anchorY": 0,
    "anchorZ": 0,
    "blocks": [
        {
            "x": -12,
            "y": 29,
            "z": 7,
            "name": "*Furniture_Crude_Trapdoor_State_Definitions_OpenDoorOut",
            "rotation": 3
        },
        {
            "x": -12,
            "y": 28,
            "z": 8,
            "name": "*Furniture_Crude_Trapdoor_State_Definitions_OpenDoorOut",
            "rotation": 3
        },
        {
            "x": -12,
            "y": 29,
            "z": 8,
            "name": "Rock_Calcite_Brick_Smooth_Half",
            "rotation": 7
        },
        {
            "x": -12,
            "y": 30,
            "z": 8,
            "name": "*Furniture_Crude_Trapdoor_State_Definitions_OpenDoorOut",
            "rotation": 3
        },
        {
            "x": -12,
            "y": 29,
            "z": 9,
            "name": "*Furniture_Crude_Trapdoor_State_Definitions_OpenDoorOut",
            "rotation": 3
        },
        {
            "x": -11,
            "y": 28,
            "z": 5,
            "name": "Wood_Hardwood_Planks_Half",
            "rotation": 8
        },
        {
            "x": -11,
            "y": 29,
            "z": 5,
            "name": "Wood_Hardwood_Planks"
        },
        {
            "x": -11,
            "y": 30,
            "z": 5,
            "name": "Wood_Hardwood_Planks_Half"
        },
        {
            "x": -11,
            "y": 29,
            "z": 6,
            "name": "Wood_Hardwood_Planks"
        },
        {
            "x": -11,
            "y": 28,
            "z": 7,
            "name": "Wood_Hardwood_Stairs",
            "rotation": 8
        },
        {
            "x": -11,
            "y": 29,
            "z": 7,
            "name": "Wood_Hardwood_Planks"
        },
        {
            "x": -11,
            "y": 30,
            "z": 7,
            "name": "Wood_Hardwood_Stairs",
            "rotation": 2
        },
        {
            "x": -11,
            "y": 25,
            "z": 8,
            "name": "Wood_Hardwood_Beam"
        },
        {
            "x": -11,
            "y": 26,
            "z": 8,
            "name": "Wood_Hardwood_Planks"
        },
        {
            "x": -11,
            "y": 27,
            "z": 8,
            "name": "Wood_Hardwood_Planks"
        },
        {
            "x": -11,
            "y": 28,
            "z": 8,
            "name": "Wood_Hardwood_Planks"
        },
        {
            "x": -11,
            "y": 30,
            "z": 8,
            "name": "Wood_Hardwood_Planks"
        },
        {
            "x": -11,
            "y": 31,
            "z": 8,
            "name": "Wood_Hardwood_Planks"
        },
        {
            "x": -11,
            "y": 32,
            "z": 8,
            "name": "Wood_Hardwood_Planks"
        },
        {
            "x": -11,
            "y": 33,
            "z": 8,
            "name": "Wood_Hardwood_Beam"
        },
        {
            "x": -11,
            "y": 28,
            "z": 9,
            "name": "Wood_Hardwood_Stairs",
            "rotation": 10
        },
        {
            "x": -11,
            "y": 29,
            "z": 9,
            "name": "Wood_Hardwood_Planks"
        },
        {
            "x": -11,
            "y": 30,
            "z": 9,
            "name": "Wood_Hardwood_Stairs"
        },
        {
            "x": -11,
            "y": 29,
            "z": 10,
            "name": "Wood_Hardwood_Planks"
        },
        {
            "x": -11,
            "y": 28,
            "z": 11,
            "name": "Wood_Hardwood_Planks_Half",
            "rotation": 8
        },
        {
            "x": -11,
            "y": 29,
            "z": 11,
            "name": "Wood_Hardwood_Planks"
        },
        {
            "x": -11,
            "y": 30,
            "z": 11,
            "name": "Wood_Hardwood_Planks_Half"
        },
        {
            "x": -10,
            "y": 28,
            "z": 3,
            "name": "Wood_Hardwood_Beam"
        },
        {
            "x": -10,
            "y": 29,
            "z": 3,
            "name": "Wood_Hardwood_Planks"
        },
        {
            "x": -10,
            "y": 30,
            "z": 3,
            "name": "Wood_Hardwood_Beam"
        },
        {
            "x": -10,
            "y": 28,
            "z": 4,
            "name": "Wood_Hardwood_Planks_Half",
            "rotation": 8
        },
        {
            "x": -10,
            "y": 29,
            "z": 4,
            "name": "Wood_Hardwood_Planks"
        },
        {
            "x": -10,
            "y": 30,
            "z": 4,
            "name": "Wood_Hardwood_Planks_Half"
        },
        {
            "x": -10,
            "y": 28,
            "z": 5,
            "name": "Cloth_Block_Wool_Red"
        },
        {
            "x": -10,
            "y": 29,
            "z": 5,
            "name": "Cloth_Block_Wool_Red"
        },
        {
            "x": -10,
            "y": 30,
            "z": 5,
            "name": "Cloth_Block_Wool_Red"
        },
        {
            "x": -10,
            "y": 27,
            "z": 6,
            "name": "Cloth_Block_Wool_Red"
        },
        {
            "x": -10,
            "y": 28,
            "z": 6,
            "name": "Cloth_Block_Wool_Red"
        },
        {
            "x": -10,
            "y": 29,
            "z": 6,
            "name": "Cloth_Block_Wool_Red"
        },
        {
            "x": -10,
            "y": 30,
            "z": 6,
            "name": "Cloth_Block_Wool_Red"
        },
        {
            "x": -10,
            "y": 31,
            "z": 6,
            "name": "Cloth_Block_Wool_Red"
        },
        {
            "x": -10,
            "y": 26,
            "z": 7,
            "name": "Cloth_Block_Wool_White"
        },
        {
            "x": -10,
            "y": 27,
            "z": 7,
            "name": "Cloth_Block_Wool_White"
        },
        {
            "x": -10,
            "y": 28,
            "z": 7,
            "name": "Cloth_Block_Wool_White"
        },
        {
            "x": -10,
            "y": 29,
            "z": 7,
            "name": "Cloth_Block_Wool_White"
        },
        {
            "x": -10,
            "y": 30,
            "z": 7,
            "name": "Cloth_Block_Wool_White"
        },
        {
            "x": -10,
            "y": 31,
            "z": 7,
            "name": "Cloth_Block_Wool_White"
        },
        {
            "x": -10,
            "y": 32,
            "z": 7,
            "name": "Cloth_Block_Wool_White"
        },
        {
            "x": -10,
            "y": 23,
            "z": 8,
            "name": "Wood_Hardwood_Beam"
        },
        {
            "x": -10,
            "y": 24,
            "z": 8,
            "name": "Wood_Hardwood_Planks"
        },
        {
            "x": -10,
            "y": 25,
            "z": 8,
            "name": "Wood_Hardwood_Planks"
        },
        {
            "x": -10,
            "y": 26,
            "z": 8,
            "name": "Cloth_Block_Wool_White"
        },
        {
            "x": -10,
            "y": 27,
            "z": 8,
            "name": "Cloth_Block_Wool_White"
        },
        {
            "x": -10,
            "y": 28,
            "z": 8,
            "name": "Cloth_Block_Wool_White"
        },
        {
            "x": -10,
            "y": 30,
            "z": 8,
            "name": "Cloth_Block_Wool_White"
        },
        {
            "x": -10,
            "y": 31,
            "z": 8,
            "name": "Cloth_Block_Wool_White"
        },
        {
            "x": -10,
            "y": 32,
            "z": 8,
            "name": "Cloth_Block_Wool_White"
        },
        {
            "x": -10,
            "y": 33,
            "z": 8,
            "name": "Wood_Hardwood_Planks"
        },
        {
            "x": -10,
            "y": 34,
            "z": 8,
            "name": "Wood_Hardwood_Planks"
        },
        {
            "x": -10,
            "y": 35,
            "z": 8,
            "name": "Wood_Hardwood_Beam"
        },
        {
            "x": -10,
            "y": 26,
            "z": 9,
            "name": "Cloth_Block_Wool_White"
        },
        {
            "x": -10,
            "y": 27,
            "z": 9,
            "name": "Cloth_Block_Wool_White"
        },
        {
            "x": -10,
            "y": 28,
            "z": 9,
            "name": "Cloth_Block_Wool_White"
        },
        {
            "x": -10,
            "y": 29,
            "z": 9,
            "name": "Cloth_Block_Wool_White"
        },
        {
            "x": -10,
            "y": 30,
            "z": 9,
            "name": "Cloth_Block_Wool_White"
        },
        {
            "x": -10,
            "y": 31,
            "z": 9,
            "name": "Cloth_Block_Wool_White"
        },
        {
            "x": -10,
            "y": 32,
            "z": 9,
            "name": "Cloth_Block_Wool_White"
        },
        {
            "x": -10,
            "y": 27,
            "z": 10,
            "name": "Cloth_Block_Wool_Red"
        },
        {
            "x": -10,
            "y": 28,
            "z": 10,
            "name": "Cloth_Block_Wool_Red"
        },
        {
            "x": -10,
            "y": 29,
            "z": 10,
            "name": "Cloth_Block_Wool_Red"
        },
        {
            "x": -10,
            "y": 30,
            "z": 10,
            "name": "Cloth_Block_Wool_Red"
        },
        {
            "x": -10,
            "y": 31,
            "z": 10,
            "name": "Cloth_Block_Wool_Red"
        },
        {
            "x": -10,
            "y": 28,
            "z": 11,
            "name": "Cloth_Block_Wool_Red"
        },
        {
            "x": -10,
            "y": 29,
            "z": 11,
            "name": "Cloth_Block_Wool_Red"
        },
        {
            "x": -10,
            "y": 30,
            "z": 11,
            "name": "Cloth_Block_Wool_Red"
        },
        {
            "x": -10,
            "y": 28,
            "z": 12,
            "name": "Wood_Hardwood_Planks_Half",
            "rotation": 8
        },
        {
            "x": -10,
            "y": 29,
            "z": 12,
            "name": "Wood_Hardwood_Planks"
        },
        {
            "x": -10,
            "y": 30,
            "z": 12,
            "name": "Wood_Hardwood_Planks_Half"
        },
        {
            "x": -10,
            "y": 28,
            "z": 13,
            "name": "Wood_Hardwood_Beam"
        },
        {
            "x": -10,
            "y": 29,
            "z": 13,
            "name": "Wood_Hardwood_Planks"
        },
        {
            "x": -10,
            "y": 30,
            "z": 13,
            "name": "Wood_Hardwood_Beam"
        },
        {
            "x": -9,
            "y": 28,
            "z": 2,
            "name": "Wood_Hardwood_Beam"
        },
        {
            "x": -9,
            "y": 29,
            "z": 2,
            "name": "Wood_Hardwood_Planks"
        },
        {
            "x": -9,
            "y": 30,
            "z": 2,
            "name": "Wood_Hardwood_Beam"
        },
        {
            "x": -9,
            "y": 27,
            "z": 3,
            "name": "Cloth_Block_Wool_Red"
        },
        {
            "x": -9,
            "y": 28,
            "z": 3,
            "name": "Cloth_Block_Wool_Red"
        },
        {
            "x": -9,
            "y": 29,
            "z": 3,
            "name": "Cloth_Block_Wool_Red"
        },
        {
            "x": -9,
            "y": 30,
            "z": 3,
            "name": "Cloth_Block_Wool_Red"
        },
        {
            "x": -9,
            "y": 31,
            "z": 3,
            "name": "Cloth_Block_Wool_Red"
        },
        {
            "x": -9,
            "y": 26,
            "z": 4,
            "name": "Cloth_Block_Wool_Red"
        },
        {
            "x": -9,
            "y": 27,
            "z": 4,
            "name": "Cloth_Block_Wool_Red"
        },
        {
            "x": -9,
            "y": 28,
            "z": 4,
            "name": "Cloth_Block_Wool_Red"
        },
        {
            "x": -9,
            "y": 29,
            "z": 4,
            "name": "Cloth_Block_Wool_Red"
        },
        {
            "x": -9,
            "y": 30,
            "z": 4,
            "name": "Cloth_Block_Wool_Red"
        },
        {
            "x": -9,
            "y": 31,
            "z": 4,
            "name": "Cloth_Block_Wool_Red"
        },
        {
            "x": -9,
            "y": 32,
            "z": 4,
            "name": "Cloth_Block_Wool_Red"
        },
        {
            "x": -9,
            "y": 25,
            "z": 5,
            "name": "Cloth_Block_Wool_Red"
        },
        {
            "x": -9,
            "y": 26,
            "z": 5,
            "name": "Cloth_Block_Wool_Red"
        },
        {
            "x": -9,
            "y": 27,
            "z": 5,
            "name": "Cloth_Block_Wool_Red"
        },
        {
            "x": -9,
            "y": 31,
            "z": 5,
            "name": "Cloth_Block_Wool_Red"
        },
        {
            "x": -9,
            "y": 32,
            "z": 5,
            "name": "Cloth_Block_Wool_Red"
        },
        {
            "x": -9,
            "y": 33,
            "z": 5,
            "name": "Cloth_Block_Wool_Red"
        },
        {
            "x": -9,
            "y": 24,
            "z": 6,
            "name": "Cloth_Block_Wool_Red"
        },
        {
            "x": -9,
            "y": 25,
            "z": 6,
            "name": "Cloth_Block_Wool_Red"
        },
        {
            "x": -9,
            "y": 26,
            "z": 6,
            "name": "Cloth_Block_Wool_Red"
        },
        {
            "x": -9,
            "y": 32,
            "z": 6,
            "name": "Cloth_Block_Wool_Red"
        },
        {
            "x": -9,
            "y": 33,
            "z": 6,
            "name": "Cloth_Block_Wool_Red"
        },
        {
            "x": -9,
            "y": 34,
            "z": 6,
            "name": "Cloth_Block_Wool_Red"
        },
        {
            "x": -9,
            "y": 24,
            "z": 7,
            "name": "Cloth_Block_Wool_White"
        },
        {
            "x": -9,
            "y": 25,
            "z": 7,
            "name": "Cloth_Block_Wool_White"
        },
        {
            "x": -9,
            "y": 33,
            "z": 7,
            "name": "Cloth_Block_Wool_White"
        },
        {
            "x": -9,
            "y": 34,
            "z": 7,
            "name": "Cloth_Block_Wool_White"
        },
        {
            "x": -9,
            "y": 22,
            "z": 8,
            "name": "Wood_Hardwood_Beam"
        },
        {
            "x": -9,
            "y": 23,
            "z": 8,
            "name": "Wood_Hardwood_Planks"
        },
        {
            "x": -9,
            "y": 24,
            "z": 8,
            "name": "Cloth_Block_Wool_White"
        },
        {
            "x": -9,
            "y": 25,
            "z": 8,
            "name": "Cloth_Block_Wool_White"
        },
        {
            "x": -9,
            "y": 33,
            "z": 8,
            "name": "Cloth_Block_Wool_White"
        },
        {
            "x": -9,
            "y": 34,
            "z": 8,
            "name": "Cloth_Block_Wool_White"
        },
        {
            "x": -9,
            "y": 35,
            "z": 8,
            "name": "Wood_Hardwood_Planks"
        },
        {
            "x": -9,
            "y": 36,
            "z": 8,
            "name": "Wood_Hardwood_Beam"
        },
        {
            "x": -9,
            "y": 24,
            "z": 9,
            "name": "Cloth_Block_Wool_White"
        },
        {
            "x": -9,
            "y": 25,
            "z": 9,
            "name": "Cloth_Block_Wool_White"
        },
        {
            "x": -9,
            "y": 33,
            "z": 9,
            "name": "Cloth_Block_Wool_White"
        },
        {
            "x": -9,
            "y": 34,
            "z": 9,
            "name": "Cloth_Block_Wool_White"
        },
        {
            "x": -9,
            "y": 24,
            "z": 10,
            "name": "Cloth_Block_Wool_Red"
        },
        {
            "x": -9,
            "y": 25,
            "z": 10,
            "name": "Cloth_Block_Wool_Red"
        },
        {
            "x": -9,
            "y": 26,
            "z": 10,
            "name": "Cloth_Block_Wool_Red"
        },
        {
            "x": -9,
            "y": 32,
            "z": 10,
            "name": "Cloth_Block_Wool_Red"
        },
        {
            "x": -9,
            "y": 33,
            "z": 10,
            "name": "Cloth_Block_Wool_Red"
        },
        {
            "x": -9,
            "y": 34,
            "z": 10,
            "name": "Cloth_Block_Wool_Red"
        },
        {
            "x": -9,
            "y": 25,
            "z": 11,
            "name": "Cloth_Block_Wool_Red"
        },
        {
            "x": -9,
            "y": 26,
            "z": 11,
            "name": "Cloth_Block_Wool_Red"
        },
        {
            "x": -9,
            "y": 27,
            "z": 11,
            "name": "Cloth_Block_Wool_Red"
        },
        {
            "x": -9,
            "y": 31,
            "z": 11,
            "name": "Cloth_Block_Wool_Red"
        },
        {
            "x": -9,
            "y": 32,
            "z": 11,
            "name": "Cloth_Block_Wool_Red"
        },
        {
            "x": -9,
            "y": 33,
            "z": 11,
            "name": "Cloth_Block_Wool_Red"
        },
        {
            "x": -9,
            "y": 26,
            "z": 12,
            "name": "Cloth_Block_Wool_Red"
        },
        {
            "x": -9,
            "y": 27,
            "z": 12,
            "name": "Cloth_Block_Wool_Red"
        },
        {
            "x": -9,
            "y": 28,
            "z": 12,
            "name": "Cloth_Block_Wool_Red"
        },
        {
            "x": -9,
            "y": 29,
            "z": 12,
            "name": "Cloth_Block_Wool_Red"
        },
        {
            "x": -9,
            "y": 30,
            "z": 12,
            "name": "Cloth_Block_Wool_Red"
        },
        {
            "x": -9,
            "y": 31,
            "z": 12,
            "name": "Cloth_Block_Wool_Red"
        },
        {
            "x": -9,
            "y": 32,
            "z": 12,
            "name": "Cloth_Block_Wool_Red"
        },
        {
            "x": -9,
            "y": 27,
            "z": 13,
            "name": "Cloth_Block_Wool_Red"
        },
        {
            "x": -9,
            "y": 28,
            "z": 13,
            "name": "Cloth_Block_Wool_Red"
        },
        {
            "x": -9,
            "y": 29,
            "z": 13,
            "name": "Cloth_Block_Wool_Red"
        },
        {
            "x": -9,
            "y": 30,
            "z": 13,
            "name": "Cloth_Block_Wool_Red"
        },
        {
            "x": -9,
            "y": 31,
            "z": 13,
            "name": "Cloth_Block_Wool_Red"
        },
        {
            "x": -9,
            "y": 28,
            "z": 14,
            "name": "Wood_Hardwood_Beam"
        },
        {
            "x": -9,
            "y": 29,
            "z": 14,
            "name": "Wood_Hardwood_Planks"
        },
        {
            "x": -9,
            "y": 30,
            "z": 14,
            "name": "Wood_Hardwood_Beam"
        },
        {
            "x": -8,
            "y": 16,
            "z": 1,
            "name": "*Furniture_Crude_Trapdoor_State_Definitions_OpenDoorOut",
            "rotation": 3
        },
        {
            "x": -8,
            "y": 28,
            "z": 1,
            "name": "Wood_Hardwood_Stairs",
            "rotation": 9
        },
        {
            "x": -8,
            "y": 29,
            "z": 1,
            "name": "Wood_Hardwood_Planks"
        },
        {
            "x": -8,
            "y": 30,
            "z": 1,
            "name": "Wood_Hardwood_Stairs",
            "rotation": 3
        },
        {
            "x": -8,
            "y": 26,
            "z": 2,
            "name": "Cloth_Block_Wool_White"
        },
        {
            "x": -8,
            "y": 27,
            "z": 2,
            "name": "Cloth_Block_Wool_White"
        },
        {
            "x": -8,
            "y": 28,
            "z": 2,
            "name": "Cloth_Block_Wool_White"
        },
        {
            "x": -8,
            "y": 29,
            "z": 2,
            "name": "Cloth_Block_Wool_White"
        },
        {
            "x": -8,
            "y": 30,
            "z": 2,
            "name": "Cloth_Block_Wool_White"
        },
        {
            "x": -8,
            "y": 31,
            "z": 2,
            "name": "Cloth_Block_Wool_White"
        },
        {
            "x": -8,
            "y": 32,
            "z": 2,
            "name": "Cloth_Block_Wool_White"
        },
        {
            "x": -8,
            "y": 25,
            "z": 3,
            "name": "Cloth_Block_Wool_Red"
        },
        {
            "x": -8,
            "y": 26,
            "z": 3,
            "name": "Cloth_Block_Wool_Red"
        },
        {
            "x": -8,
            "y": 32,
            "z": 3,
            "name": "Cloth_Block_Wool_Red"
        },
        {
            "x": -8,
            "y": 33,
            "z": 3,
            "name": "Cloth_Block_Wool_Red"
        },
        {
            "x": -8,
            "y": 24,
            "z": 4,
            "name": "Cloth_Block_Wool_Red"
        },
        {
            "x": -8,
            "y": 25,
            "z": 4,
            "name": "Cloth_Block_Wool_Red"
        },
        {
            "x": -8,
            "y": 33,
            "z": 4,
            "name": "Cloth_Block_Wool_Red"
        },
        {
            "x": -8,
            "y": 34,
            "z": 4,
            "name": "Cloth_Block_Wool_Red"
        },
        {
            "x": -8,
            "y": 23,
            "z": 5,
            "name": "Cloth_Block_Wool_Red"
        },
        {
            "x": -8,
            "y": 24,
            "z": 5,
            "name": "Cloth_Block_Wool_Red"
        },
        {
            "x": -8,
            "y": 34,
            "z": 5,
            "name": "Cloth_Block_Wool_Red"
        },
        {
            "x": -8,
            "y": 35,
            "z": 5,
            "name": "Cloth_Block_Wool_Red"
        },
        {
            "x": -8,
            "y": 23,
            "z": 6,
            "name": "Cloth_Block_Wool_Red"
        },
        {
            "x": -8,
            "y": 35,
            "z": 6,
            "name": "Cloth_Block_Wool_Red"
        },
        {
            "x": -8,
            "y": 23,
            "z": 7,
            "name": "Cloth_Block_Wool_White"
        },
        {
            "x": -8,
            "y": 35,
            "z": 7,
            "name": "Cloth_Block_Wool_White"
        },
        {
            "x": -8,
            "y": 21,
            "z": 8,
            "name": "Wood_Hardwood_Beam"
        },
        {
            "x": -8,
            "y": 22,
            "z": 8,
            "name": "Wood_Hardwood_Planks"
        },
        {
            "x": -8,
            "y": 23,
            "z": 8,
            "name": "Cloth_Block_Wool_White"
        },
        {
            "x": -8,
            "y": 35,
            "z": 8,
            "name": "Cloth_Block_Wool_White"
        },
        {
            "x": -8,
            "y": 36,
            "z": 8,
            "name": "Wood_Hardwood_Planks"
        },
        {
            "x": -8,
            "y": 37,
            "z": 8,
            "name": "Wood_Hardwood_Beam"
        },
        {
            "x": -8,
            "y": 23,
            "z": 9,
            "name": "Cloth_Block_Wool_White"
        },
        {
            "x": -8,
            "y": 35,
            "z": 9,
            "name": "Cloth_Block_Wool_White"
        },
        {
            "x": -8,
            "y": 23,
            "z": 10,
            "name": "Cloth_Block_Wool_Red"
        },
        {
            "x": -8,
            "y": 35,
            "z": 10,
            "name": "Cloth_Block_Wool_Red"
        },
        {
            "x": -8,
            "y": 23,
            "z": 11,
            "name": "Cloth_Block_Wool_Red"
        },
        {
            "x": -8,
            "y": 24,
            "z": 11,
            "name": "Cloth_Block_Wool_Red"
        },
        {
            "x": -8,
            "y": 34,
            "z": 11,
            "name": "Cloth_Block_Wool_Red"
        },
        {
            "x": -8,
            "y": 35,
            "z": 11,
            "name": "Cloth_Block_Wool_Red"
        },
        {
            "x": -8,
            "y": 24,
            "z": 12,
            "name": "Cloth_Block_Wool_Red"
        },
        {
            "x": -8,
            "y": 25,
            "z": 12,
            "name": "Cloth_Block_Wool_Red"
        },
        {
            "x": -8,
            "y": 33,
            "z": 12,
            "name": "Cloth_Block_Wool_Red"
        },
        {
            "x": -8,
            "y": 34,
            "z": 12,
            "name": "Cloth_Block_Wool_Red"
        },
        {
            "x": -8,
            "y": 25,
            "z": 13,
            "name": "Cloth_Block_Wool_Red"
        },
        {
            "x": -8,
            "y": 26,
            "z": 13,
            "name": "Cloth_Block_Wool_Red"
        },
        {
            "x": -8,
            "y": 32,
            "z": 13,
            "name": "Cloth_Block_Wool_Red"
        },
        {
            "x": -8,
            "y": 33,
            "z": 13,
            "name": "Cloth_Block_Wool_Red"
        },
        {
            "x": -8,
            "y": 26,
            "z": 14,
            "name": "Cloth_Block_Wool_White"
        },
        {
            "x": -8,
            "y": 27,
            "z": 14,
            "name": "Cloth_Block_Wool_White"
        },
        {
            "x": -8,
            "y": 28,
            "z": 14,
            "name": "Cloth_Block_Wool_White"
        },
        {
            "x": -8,
            "y": 29,
            "z": 14,
            "name": "Cloth_Block_Wool_White"
        },
        {
            "x": -8,
            "y": 30,
            "z": 14,
            "name": "Cloth_Block_Wool_White"
        },
        {
            "x": -8,
            "y": 31,
            "z": 14,
            "name": "Cloth_Block_Wool_White"
        },
        {
            "x": -8,
            "y": 32,
            "z": 14,
            "name": "Cloth_Block_Wool_White"
        },
        {
            "x": -8,
            "y": 14,
            "z": 15,
            "name": "*Furniture_Crude_Trapdoor_State_Definitions_OpenDoorOut",
            "rotation": 3
        },
        {
            "x": -8,
            "y": 28,
            "z": 15,
            "name": "Wood_Hardwood_Stairs",
            "rotation": 9
        },
        {
            "x": -8,
            "y": 29,
            "z": 15,
            "name": "Wood_Hardwood_Planks"
        },
        {
            "x": -8,
            "y": 30,
            "z": 15,
            "name": "Wood_Hardwood_Stairs",
            "rotation": 3
        },
        {
            "x": -7,
            "y": 16,
            "z": 0,
            "name": "*Furniture_Crude_Trapdoor_State_Definitions_OpenDoorOut",
            "rotation": 2
        },
        {
            "x": -7,
            "y": 28,
            "z": 0,
            "name": "Wood_Hardwood_Stairs",
            "rotation": 8
        },
        {
            "x": -7,
            "y": 29,
            "z": 0,
            "name": "Wood_Hardwood_Planks"
        },
        {
            "x": -7,
            "y": 30,
            "z": 0,
            "name": "Wood_Hardwood_Stairs",
            "rotation": 2
        },
        {
            "x": -7,
            "y": 15,
            "z": 1,
            "name": "Furniture_Crude_Trapdoor",
            "rotation": 2
        },
        {
            "x": -7,
            "y": 16,
            "z": 1,
            "name": "Rock_Crystal_Yellow_Block"
        },
        {
            "x": -7,
            "y": 17,
            "z": 1,
            "name": "Wood_Hardwood_Planks"
        },
        {
            "x": -7,
            "y": 18,
            "z": 1,
            "name": "Wood_Hardwood_Beam"
        },
        {
            "x": -7,
            "y": 19,
            "z": 1,
            "name": "Wood_Hardwood_Beam"
        },
        {
            "x": -7,
            "y": 20,
            "z": 1,
            "name": "Wood_Hardwood_Beam"
        },
        {
            "x": -7,
            "y": 21,
            "z": 1,
            "name": "Wood_Hardwood_Beam"
        },
        {
            "x": -7,
            "y": 22,
            "z": 1,
            "name": "Wood_Hardwood_Beam"
        },
        {
            "x": -7,
            "y": 23,
            "z": 1,
            "name": "Rock_Stone_Brick_Beam"
        },
        {
            "x": -7,
            "y": 24,
            "z": 1,
            "name": "Wood_Hardwood_Planks"
        },
        {
            "x": -7,
            "y": 25,
            "z": 1,
            "name": "Wood_Hardwood_Planks"
        },
        {
            "x": -7,
            "y": 26,
            "z": 1,
            "name": "Wood_Hardwood_Planks"
        },
        {
            "x": -7,
            "y": 27,
            "z": 1,
            "name": "Wood_Hardwood_Planks"
        },
        {
            "x": -7,
            "y": 28,
            "z": 1,
            "name": "Wood_Hardwood_Planks"
        },
        {
            "x": -7,
            "y": 29,
            "z": 1,
            "name": "Cloth_Block_Wool_White"
        },
        {
            "x": -7,
            "y": 30,
            "z": 1,
            "name": "Wood_Hardwood_Planks"
        },
        {
            "x": -7,
            "y": 31,
            "z": 1,
            "name": "Wood_Hardwood_Planks"
        },
        {
            "x": -7,
            "y": 32,
            "z": 1,
            "name": "Wood_Hardwood_Planks"
        },
        {
            "x": -7,
            "y": 33,
            "z": 1,
            "name": "Wood_Hardwood_Planks"
        },
        {
            "x": -7,
            "y": 34,
            "z": 1,
            "name": "Wood_Hardwood_Planks"
        },
        {
            "x": -7,
            "y": 35,
            "z": 1,
            "name": "Wood_Hardwood_Beam"
        },
        {
            "x": -7,
            "y": 16,
            "z": 2,
            "name": "*Furniture_Crude_Trapdoor_State_Definitions_OpenDoorOut"
        },
        {
            "x": -7,
            "y": 24,
            "z": 2,
            "name": "Cloth_Block_Wool_White"
        },
        {
            "x": -7,
            "y": 25,
            "z": 2,
            "name": "Cloth_Block_Wool_White"
        },
        {
            "x": -7,
            "y": 33,
            "z": 2,
            "name": "Cloth_Block_Wool_White"
        },
        {
            "x": -7,
            "y": 34,
            "z": 2,
            "name": "Cloth_Block_Wool_White"
        },
        {
            "x": -7,
            "y": 23,
            "z": 3,
            "name": "Cloth_Block_Wool_White"
        },
        {
            "x": -7,
            "y": 24,
            "z": 3,
            "name": "Cloth_Block_Wool_Red"
        },
        {
            "x": -7,
            "y": 25,
            "z": 3,
            "name": "Cloth_Block_Wool_White"
        },
        {
            "x": -7,
            "y": 34,
            "z": 3,
            "name": "Cloth_Block_Wool_Red"
        },
        {
            "x": -7,
            "y": 35,
            "z": 3,
            "name": "Cloth_Block_Wool_White"
        },
        {
            "x": -7,
            "y": 23,
            "z": 4,
            "name": "Cloth_Block_Wool_Red"
        },
        {
            "x": -7,
            "y": 35,
            "z": 4,
            "name": "Cloth_Block_Wool_Red"
        },
        {
            "x": -7,
            "y": 22,
            "z": 5,
            "name": "Cloth_Block_Wool_Red"
        },
        {
            "x": -7,
            "y": 36,
            "z": 5,
            "name": "Cloth_Block_Wool_Red"
        },
        {
            "x": -7,
            "y": 22,
            "z": 6,
            "name": "Cloth_Block_Wool_Red"
        },
        {
            "x": -7,
            "y": 36,
            "z": 6,
            "name": "Cloth_Block_Wool_Red"
        },
        {
            "x": -7,
            "y": 22,
            "z": 7,
            "name": "Cloth_Block_Wool_White"
        },
        {
            "x": -7,
            "y": 36,
            "z": 7,
            "name": "Cloth_Block_Wool_White"
        },
        {
            "x": -7,
            "y": 20,
            "z": 8,
            "name": "Wood_Hardwood_Beam"
        },
        {
            "x": -7,
            "y": 21,
            "z": 8,
            "name": "Wood_Hardwood_Planks"
        },
        {
            "x": -7,
            "y": 22,
            "z": 8,
            "name": "Cloth_Block_Wool_White"
        },
        {
            "x": -7,
            "y": 36,
            "z": 8,
            "name": "Cloth_Block_Wool_White"
        },
        {
            "x": -7,
            "y": 37,
            "z": 8,
            "name": "Wood_Hardwood_Planks"
        },
        {
            "x": -7,
            "y": 38,
            "z": 8,
            "name": "Wood_Hardwood_Beam"
        },
        {
            "x": -7,
            "y": 22,
            "z": 9,
            "name": "Cloth_Block_Wool_White"
        },
        {
            "x": -7,
            "y": 36,
            "z": 9,
            "name": "Cloth_Block_Wool_White"
        },
        {
            "x": -7,
            "y": 22,
            "z": 10,
            "name": "Cloth_Block_Wool_Red"
        },
        {
            "x": -7,
            "y": 36,
            "z": 10,
            "name": "Cloth_Block_Wool_Red"
        },
        {
            "x": -7,
            "y": 22,
            "z": 11,
            "name": "Cloth_Block_Wool_Red"
        },
        {
            "x": -7,
            "y": 36,
            "z": 11,
            "name": "Cloth_Block_Wool_Red"
        },
        {
            "x": -7,
            "y": 23,
            "z": 12,
            "name": "Cloth_Block_Wool_Red"
        },
        {
            "x": -7,
            "y": 35,
            "z": 12,
            "name": "Cloth_Block_Wool_Red"
        },
        {
            "x": -7,
            "y": 23,
            "z": 13,
            "name": "Cloth_Block_Wool_White"
        },
        {
            "x": -7,
            "y": 24,
            "z": 13,
            "name": "Cloth_Block_Wool_Red"
        },
        {
            "x": -7,
            "y": 25,
            "z": 13,
            "name": "Cloth_Block_Wool_White"
        },
        {
            "x": -7,
            "y": 34,
            "z": 13,
            "name": "Cloth_Block_Wool_Red"
        },
        {
            "x": -7,
            "y": 35,
            "z": 13,
            "name": "Cloth_Block_Wool_White"
        },
        {
            "x": -7,
            "y": 14,
            "z": 14,
            "name": "*Furniture_Crude_Trapdoor_State_Definitions_OpenDoorOut",
            "rotation": 2
        },
        {
            "x": -7,
            "y": 24,
            "z": 14,
            "name": "Cloth_Block_Wool_White"
        },
        {
            "x": -7,
            "y": 25,
            "z": 14,
            "name": "Cloth_Block_Wool_White"
        },
        {
            "x": -7,
            "y": 33,
            "z": 14,
            "name": "Cloth_Block_Wool_White"
        },
        {
            "x": -7,
            "y": 34,
            "z": 14,
            "name": "Cloth_Block_Wool_White"
        },
        {
            "x": -7,
            "y": 13,
            "z": 15,
            "name": "Furniture_Crude_Trapdoor"
        },
        {
            "x": -7,
            "y": 14,
            "z": 15,
            "name": "Rock_Crystal_Yellow_Block"
        },
        {
            "x": -7,
            "y": 15,
            "z": 15,
            "name": "Wood_Hardwood_Planks"
        },
        {
            "x": -7,
            "y": 16,
            "z": 15,
            "name": "Wood_Hardwood_Beam"
        },
        {
            "x": -7,
            "y": 17,
            "z": 15,
            "name": "Wood_Hardwood_Beam"
        },
        {
            "x": -7,
            "y": 18,
            "z": 15,
            "name": "Wood_Hardwood_Beam"
        },
        {
            "x": -7,
            "y": 19,
            "z": 15,
            "name": "Wood_Hardwood_Beam"
        },
        {
            "x": -7,
            "y": 20,
            "z": 15,
            "name": "Wood_Hardwood_Beam"
        },
        {
            "x": -7,
            "y": 21,
            "z": 15,
            "name": "Wood_Hardwood_Beam"
        },
        {
            "x": -7,
            "y": 22,
            "z": 15,
            "name": "Wood_Hardwood_Beam"
        },
        {
            "x": -7,
            "y": 23,
            "z": 15,
            "name": "Rock_Stone_Brick_Beam"
        },
        {
            "x": -7,
            "y": 24,
            "z": 15,
            "name": "Wood_Hardwood_Planks"
        },
        {
            "x": -7,
            "y": 25,
            "z": 15,
            "name": "Wood_Hardwood_Planks"
        },
        {
            "x": -7,
            "y": 26,
            "z": 15,
            "name": "Wood_Hardwood_Planks"
        },
        {
            "x": -7,
            "y": 27,
            "z": 15,
            "name": "Wood_Hardwood_Planks"
        },
        {
            "x": -7,
            "y": 28,
            "z": 15,
            "name": "Wood_Hardwood_Planks"
        },
        {
            "x": -7,
            "y": 29,
            "z": 15,
            "name": "Cloth_Block_Wool_White"
        },
        {
            "x": -7,
            "y": 30,
            "z": 15,
            "name": "Wood_Hardwood_Planks"
        },
        {
            "x": -7,
            "y": 31,
            "z": 15,
            "name": "Wood_Hardwood_Planks"
        },
        {
            "x": -7,
            "y": 32,
            "z": 15,
            "name": "Wood_Hardwood_Planks"
        },
        {
            "x": -7,
            "y": 33,
            "z": 15,
            "name": "Wood_Hardwood_Planks"
        },
        {
            "x": -7,
            "y": 34,
            "z": 15,
            "name": "Wood_Hardwood_Planks"
        },
        {
            "x": -7,
            "y": 35,
            "z": 15,
            "name": "Wood_Hardwood_Beam"
        },
        {
            "x": -7,
            "y": 14,
            "z": 16,
            "name": "*Furniture_Crude_Trapdoor_State_Definitions_OpenDoorOut"
        },
        {
            "x": -7,
            "y": 28,
            "z": 16,
            "name": "Wood_Hardwood_Stairs",
            "rotation": 10
        },
        {
            "x": -7,
            "y": 29,
            "z": 16,
            "name": "Wood_Hardwood_Planks"
        },
        {
            "x": -7,
            "y": 30,
            "z": 16,
            "name": "Wood_Hardwood_Stairs"
        },
        {
            "x": -6,
            "y": 28,
            "z": -1,
            "name": "Wood_Hardwood_Beam"
        },
        {
            "x": -6,
            "y": 29,
            "z": -1,
            "name": "Wood_Hardwood_Planks"
        },
        {
            "x": -6,
            "y": 30,
            "z": -1,
            "name": "Wood_Hardwood_Beam"
        },
        {
            "x": -6,
            "y": 26,
            "z": 0,
            "name": "Cloth_Block_Wool_White"
        },
        {
            "x": -6,
            "y": 27,
            "z": 0,
            "name": "Cloth_Block_Wool_White"
        },
        {
            "x": -6,
            "y": 28,
            "z": 0,
            "name": "Cloth_Block_Wool_White"
        },
        {
            "x": -6,
            "y": 29,
            "z": 0,
            "name": "Cloth_Block_Wool_White"
        },
        {
            "x": -6,
            "y": 30,
            "z": 0,
            "name": "Cloth_Block_Wool_White"
        },
        {
            "x": -6,
            "y": 31,
            "z": 0,
            "name": "Cloth_Block_Wool_White"
        },
        {
            "x": -6,
            "y": 32,
            "z": 0,
            "name": "Cloth_Block_Wool_White"
        },
        {
            "x": -6,
            "y": 16,
            "z": 1,
            "name": "*Furniture_Crude_Trapdoor_State_Definitions_OpenDoorOut",
            "rotation": 1
        },
        {
            "x": -6,
            "y": 24,
            "z": 1,
            "name": "Cloth_Block_Wool_White"
        },
        {
            "x": -6,
            "y": 25,
            "z": 1,
            "name": "Cloth_Block_Wool_White"
        },
        {
            "x": -6,
            "y": 33,
            "z": 1,
            "name": "Cloth_Block_Wool_White"
        },
        {
            "x": -6,
            "y": 34,
            "z": 1,
            "name": "Cloth_Block_Wool_White"
        },
        {
            "x": -6,
            "y": 21,
            "z": 2,
            "name": "Wood_Hardwood_Beam"
        },
        {
            "x": -6,
            "y": 22,
            "z": 2,
            "name": "Wood_Hardwood_Planks"
        },
        {
            "x": -6,
            "y": 23,
            "z": 2,
            "name": "Wood_Hardwood_Planks"
        },
        {
            "x": -6,
            "y": 35,
            "z": 2,
            "name": "Wood_Hardwood_Planks"
        },
        {
            "x": -6,
            "y": 36,
            "z": 2,
            "name": "Wood_Hardwood_Planks"
        },
        {
            "x": -6,
            "y": 37,
            "z": 2,
            "name": "Wood_Hardwood_Beam"
        },
        {
            "x": -6,
            "y": 22,
            "z": 3,
            "name": "Cloth_Block_Wool_White"
        },
        {
            "x": -6,
            "y": 35,
            "z": 3,
            "name": "Cloth_Block_Wool_White"
        },
        {
            "x": -6,
            "y": 36,
            "z": 3,
            "name": "Cloth_Block_Wool_White"
        },
        {
            "x": -6,
            "y": 22,
            "z": 4,
            "name": "Cloth_Block_Wool_Red"
        },
        {
            "x": -6,
            "y": 36,
            "z": 4,
            "name": "Cloth_Block_Wool_Red"
        },
        {
            "x": -6,
            "y": 21,
            "z": 5,
            "name": "Cloth_Block_Wool_Red"
        },
        {
            "x": -6,
            "y": 37,
            "z": 5,
            "name": "Cloth_Block_Wool_Red"
        },
        {
            "x": -6,
            "y": 20,
            "z": 6,
            "name": "Wood_Hardwood_Planks"
        },
        {
            "x": -6,
            "y": 21,
            "z": 6,
            "name": "Cloth_Block_Wool_Red"
        },
        {
            "x": -6,
            "y": 37,
            "z": 6,
            "name": "Cloth_Block_Wool_Red"
        },
        {
            "x": -6,
            "y": 20,
            "z": 7,
            "name": "Wood_Hardwood_Planks"
        },
        {
            "x": -6,
            "y": 21,
            "z": 7,
            "name": "Cloth_Block_Wool_White"
        },
        {
            "x": -6,
            "y": 37,
            "z": 7,
            "name": "Cloth_Block_Wool_White"
        },
        {
            "x": -6,
            "y": 18,
            "z": 8,
            "name": "Wood_Hardwood_Beam"
        },
        {
            "x": -6,
            "y": 19,
            "z": 8,
            "name": "Wood_Hardwood_Planks"
        },
        {
            "x": -6,
            "y": 20,
            "z": 8,
            "name": "Wood_Hardwood_Planks"
        },
        {
            "x": -6,
            "y": 21,
            "z": 8,
            "name": "Cloth_Block_Wool_White"
        },
        {
            "x": -6,
            "y": 37,
            "z": 8,
            "name": "Cloth_Block_Wool_White"
        },
        {
            "x": -6,
            "y": 38,
            "z": 8,
            "name": "Wood_Hardwood_Planks"
        },
        {
            "x": -6,
            "y": 39,
            "z": 8,
            "name": "Wood_Hardwood_Beam"
        },
        {
            "x": -6,
            "y": 20,
            "z": 9,
            "name": "Wood_Hardwood_Planks"
        },
        {
            "x": -6,
            "y": 21,
            "z": 9,
            "name": "Cloth_Block_Wool_White"
        },
        {
            "x": -6,
            "y": 37,
            "z": 9,
            "name": "Cloth_Block_Wool_White"
        },
        {
            "x": -6,
            "y": 20,
            "z": 10,
            "name": "Wood_Hardwood_Planks"
        },
        {
            "x": -6,
            "y": 21,
            "z": 10,
            "name": "Cloth_Block_Wool_Red"
        },
        {
            "x": -6,
            "y": 37,
            "z": 10,
            "name": "Cloth_Block_Wool_Red"
        },
        {
            "x": -6,
            "y": 21,
            "z": 11,
            "name": "Cloth_Block_Wool_Red"
        },
        {
            "x": -6,
            "y": 37,
            "z": 11,
            "name": "Cloth_Block_Wool_Red"
        },
        {
            "x": -6,
            "y": 22,
            "z": 12,
            "name": "Cloth_Block_Wool_Red"
        },
        {
            "x": -6,
            "y": 36,
            "z": 12,
            "name": "Cloth_Block_Wool_Red"
        },
        {
            "x": -6,
            "y": 22,
            "z": 13,
            "name": "Cloth_Block_Wool_White"
        },
        {
            "x": -6,
            "y": 23,
            "z": 13,
            "name": "Cloth_Block_Wool_White"
        },
        {
            "x": -6,
            "y": 36,
            "z": 13,
            "name": "Cloth_Block_Wool_White"
        },
        {
            "x": -6,
            "y": 21,
            "z": 14,
            "name": "Wood_Hardwood_Beam"
        },
        {
            "x": -6,
            "y": 22,
            "z": 14,
            "name": "Wood_Hardwood_Planks"
        },
        {
            "x": -6,
            "y": 23,
            "z": 14,
            "name": "Wood_Hardwood_Planks"
        },
        {
            "x": -6,
            "y": 35,
            "z": 14,
            "name": "Wood_Hardwood_Planks"
        },
        {
            "x": -6,
            "y": 36,
            "z": 14,
            "name": "Wood_Hardwood_Planks"
        },
        {
            "x": -6,
            "y": 37,
            "z": 14,
            "name": "Wood_Hardwood_Beam"
        },
        {
            "x": -6,
            "y": 14,
            "z": 15,
            "name": "*Furniture_Crude_Trapdoor_State_Definitions_OpenDoorOut",
            "rotation": 1
        },
        {
            "x": -6,
            "y": 24,
            "z": 15,
            "name": "Cloth_Block_Wool_White"
        },
        {
            "x": -6,
            "y": 25,
            "z": 15,
            "name": "Cloth_Block_Wool_White"
        },
        {
            "x": -6,
            "y": 33,
            "z": 15,
            "name": "Cloth_Block_Wool_White"
        },
        {
            "x": -6,
            "y": 34,
            "z": 15,
            "name": "Cloth_Block_Wool_White"
        },
        {
            "x": -6,
            "y": 26,
            "z": 16,
            "name": "Cloth_Block_Wool_White"
        },
        {
            "x": -6,
            "y": 27,
            "z": 16,
            "name": "Cloth_Block_Wool_White"
        },
        {
            "x": -6,
            "y": 28,
            "z": 16,
            "name": "Cloth_Block_Wool_White"
        },
        {
            "x": -6,
            "y": 29,
            "z": 16,
            "name": "Cloth_Block_Wool_White"
        },
        {
            "x": -6,
            "y": 30,
            "z": 16,
            "name": "Cloth_Block_Wool_White"
        },
        {
            "x": -6,
            "y": 31,
            "z": 16,
            "name": "Cloth_Block_Wool_White"
        },
        {
            "x": -6,
            "y": 32,
            "z": 16,
            "name": "Cloth_Block_Wool_White"
        },
        {
            "x": -6,
            "y": 28,
            "z": 17,
            "name": "Wood_Hardwood_Beam"
        },
        {
            "x": -6,
            "y": 29,
            "z": 17,
            "name": "Wood_Hardwood_Planks"
        },
        {
            "x": -6,
            "y": 30,
            "z": 17,
            "name": "Wood_Hardwood_Beam"
        },
        {
            "x": -5,
            "y": 28,
            "z": -2,
            "name": "Wood_Hardwood_Beam",
            "rotation": 1
        },
        {
            "x": -5,
            "y": 29,
            "z": -2,
            "name": "Wood_Hardwood_Planks"
        },
        {
            "x": -5,
            "y": 30,
            "z": -2,
            "name": "Wood_Hardwood_Beam",
            "rotation": 1
        },
        {
            "x": -5,
            "y": 27,
            "z": -1,
            "name": "Cloth_Block_Wool_Red"
        },
        {
            "x": -5,
            "y": 28,
            "z": -1,
            "name": "Cloth_Block_Wool_Red"
        },
        {
            "x": -5,
            "y": 29,
            "z": -1,
            "name": "Cloth_Block_Wool_Red"
        },
        {
            "x": -5,
            "y": 30,
            "z": -1,
            "name": "Cloth_Block_Wool_Red"
        },
        {
            "x": -5,
            "y": 31,
            "z": -1,
            "name": "Cloth_Block_Wool_Red"
        },
        {
            "x": -5,
            "y": 25,
            "z": 0,
            "name": "Cloth_Block_Wool_Red"
        },
        {
            "x": -5,
            "y": 26,
            "z": 0,
            "name": "Cloth_Block_Wool_Red"
        },
        {
            "x": -5,
            "y": 32,
            "z": 0,
            "name": "Cloth_Block_Wool_Red"
        },
        {
            "x": -5,
            "y": 33,
            "z": 0,
            "name": "Cloth_Block_Wool_Red"
        },
        {
            "x": -5,
            "y": 23,
            "z": 1,
            "name": "Cloth_Block_Wool_White"
        },
        {
            "x": -5,
            "y": 24,
            "z": 1,
            "name": "Cloth_Block_Wool_Red"
        },
        {
            "x": -5,
            "y": 25,
            "z": 1,
            "name": "Cloth_Block_Wool_White"
        },
        {
            "x": -5,
            "y": 34,
            "z": 1,
            "name": "Cloth_Block_Wool_Red"
        },
        {
            "x": -5,
            "y": 35,
            "z": 1,
            "name": "Cloth_Block_Wool_White"
        },
        {
            "x": -5,
            "y": 22,
            "z": 2,
            "name": "Cloth_Block_Wool_White"
        },
        {
            "x": -5,
            "y": 23,
            "z": 2,
            "name": "Cloth_Block_Wool_White"
        },
        {
            "x": -5,
            "y": 36,
            "z": 2,
            "name": "Cloth_Block_Wool_White"
        },
        {
            "x": -5,
            "y": 20,
            "z": 3,
            "name": "Wood_Hardwood_Beam"
        },
        {
            "x": -5,
            "y": 21,
            "z": 3,
            "name": "Wood_Hardwood_Planks"
        },
        {
            "x": -5,
            "y": 22,
            "z": 3,
            "name": "Cloth_Block_Wool_White"
        },
        {
            "x": -5,
            "y": 36,
            "z": 3,
            "name": "Cloth_Block_Wool_White"
        },
        {
            "x": -5,
            "y": 37,
            "z": 3,
            "name": "Wood_Hardwood_Planks"
        },
        {
            "x": -5,
            "y": 38,
            "z": 3,
            "name": "Wood_Hardwood_Beam"
        },
        {
            "x": -5,
            "y": 21,
            "z": 4,
            "name": "Cloth_Block_Wool_White"
        },
        {
            "x": -5,
            "y": 37,
            "z": 4,
            "name": "Cloth_Block_Wool_White"
        },
        {
            "x": -5,
            "y": 20,
            "z": 5,
            "name": "Wood_Hardwood_Planks"
        },
        {
            "x": -5,
            "y": 21,
            "z": 5,
            "name": "Cloth_Block_Wool_Red"
        },
        {
            "x": -5,
            "y": 37,
            "z": 5,
            "name": "Cloth_Block_Wool_Red"
        },
        {
            "x": -5,
            "y": 20,
            "z": 6,
            "name": "Cloth_Block_Wool_Red"
        },
        {
            "x": -5,
            "y": 38,
            "z": 6,
            "name": "Cloth_Block_Wool_Red"
        },
        {
            "x": -5,
            "y": 18,
            "z": 7,
            "name": "Wood_Hardwood_Planks"
        },
        {
            "x": -5,
            "y": 19,
            "z": 7,
            "name": "Cloth_Block_Wool_Red"
        },
        {
            "x": -5,
            "y": 20,
            "z": 7,
            "name": "Cloth_Block_Wool_White"
        },
        {
            "x": -5,
            "y": 38,
            "z": 7,
            "name": "Cloth_Block_Wool_White"
        },
        {
            "x": -5,
            "y": 16,
            "z": 8,
            "name": "Wood_Hardwood_Beam"
        },
        {
            "x": -5,
            "y": 17,
            "z": 8,
            "name": "Wood_Hardwood_Beam"
        },
        {
            "x": -5,
            "y": 18,
            "z": 8,
            "name": "Wood_Hardwood_Planks"
        },
        {
            "x": -5,
            "y": 19,
            "z": 8,
            "name": "Cloth_Block_Wool_Red"
        },
        {
            "x": -5,
            "y": 20,
            "z": 8,
            "name": "Cloth_Block_Wool_White"
        },
        {
            "x": -5,
            "y": 38,
            "z": 8,
            "name": "Cloth_Block_Wool_White"
        },
        {
            "x": -5,
            "y": 39,
            "z": 8,
            "name": "Wood_Hardwood_Planks"
        },
        {
            "x": -5,
            "y": 18,
            "z": 9,
            "name": "Wood_Hardwood_Planks"
        },
        {
            "x": -5,
            "y": 19,
            "z": 9,
            "name": "Cloth_Block_Wool_Red"
        },
        {
            "x": -5,
            "y": 20,
            "z": 9,
            "name": "Cloth_Block_Wool_White"
        },
        {
            "x": -5,
            "y": 38,
            "z": 9,
            "name": "Cloth_Block_Wool_White"
        },
        {
            "x": -5,
            "y": 20,
            "z": 10,
            "name": "Cloth_Block_Wool_Red"
        },
        {
            "x": -5,
            "y": 38,
            "z": 10,
            "name": "Cloth_Block_Wool_Red"
        },
        {
            "x": -5,
            "y": 20,
            "z": 11,
            "name": "Wood_Hardwood_Planks"
        },
        {
            "x": -5,
            "y": 21,
            "z": 11,
            "name": "Cloth_Block_Wool_Red"
        },
        {
            "x": -5,
            "y": 37,
            "z": 11,
            "name": "Cloth_Block_Wool_Red"
        },
        {
            "x": -5,
            "y": 21,
            "z": 12,
            "name": "Cloth_Block_Wool_White"
        },
        {
            "x": -5,
            "y": 37,
            "z": 12,
            "name": "Cloth_Block_Wool_White"
        },
        {
            "x": -5,
            "y": 20,
            "z": 13,
            "name": "Wood_Hardwood_Beam"
        },
        {
            "x": -5,
            "y": 21,
            "z": 13,
            "name": "Wood_Hardwood_Planks"
        },
        {
            "x": -5,
            "y": 22,
            "z": 13,
            "name": "Cloth_Block_Wool_White"
        },
        {
            "x": -5,
            "y": 36,
            "z": 13,
            "name": "Cloth_Block_Wool_White"
        },
        {
            "x": -5,
            "y": 37,
            "z": 13,
            "name": "Wood_Hardwood_Planks"
        },
        {
            "x": -5,
            "y": 38,
            "z": 13,
            "name": "Wood_Hardwood_Beam"
        },
        {
            "x": -5,
            "y": 22,
            "z": 14,
            "name": "Cloth_Block_Wool_White"
        },
        {
            "x": -5,
            "y": 35,
            "z": 14,
            "name": "Cloth_Block_Wool_White"
        },
        {
            "x": -5,
            "y": 36,
            "z": 14,
            "name": "Cloth_Block_Wool_White"
        },
        {
            "x": -5,
            "y": 23,
            "z": 15,
            "name": "Cloth_Block_Wool_White"
        },
        {
            "x": -5,
            "y": 24,
            "z": 15,
            "name": "Cloth_Block_Wool_Red"
        },
        {
            "x": -5,
            "y": 25,
            "z": 15,
            "name": "Cloth_Block_Wool_White"
        },
        {
            "x": -5,
            "y": 34,
            "z": 15,
            "name": "Cloth_Block_Wool_Red"
        },
        {
            "x": -5,
            "y": 35,
            "z": 15,
            "name": "Cloth_Block_Wool_White"
        },
        {
            "x": -5,
            "y": 25,
            "z": 16,
            "name": "Cloth_Block_Wool_Red"
        },
        {
            "x": -5,
            "y": 26,
            "z": 16,
            "name": "Cloth_Block_Wool_Red"
        },
        {
            "x": -5,
            "y": 32,
            "z": 16,
            "name": "Cloth_Block_Wool_Red"
        },
        {
            "x": -5,
            "y": 33,
            "z": 16,
            "name": "Cloth_Block_Wool_Red"
        },
        {
            "x": -5,
            "y": 27,
            "z": 17,
            "name": "Cloth_Block_Wool_Red"
        },
        {
            "x": -5,
            "y": 28,
            "z": 17,
            "name": "Cloth_Block_Wool_Red"
        },
        {
            "x": -5,
            "y": 29,
            "z": 17,
            "name": "Cloth_Block_Wool_Red"
        },
        {
            "x": -5,
            "y": 30,
            "z": 17,
            "name": "Cloth_Block_Wool_Red"
        },
        {
            "x": -5,
            "y": 31,
            "z": 17,
            "name": "Cloth_Block_Wool_Red"
        },
        {
            "x": -5,
            "y": 28,
            "z": 18,
            "name": "Wood_Hardwood_Beam",
            "rotation": 1
        },
        {
            "x": -5,
            "y": 29,
            "z": 18,
            "name": "Wood_Hardwood_Planks"
        },
        {
            "x": -5,
            "y": 30,
            "z": 18,
            "name": "Wood_Hardwood_Beam",
            "rotation": 1
        },
        {
            "x": -4,
            "y": 28,
            "z": -2,
            "name": "Wood_Hardwood_Planks_Half",
            "rotation": 8
        },
        {
            "x": -4,
            "y": 29,
            "z": -2,
            "name": "Wood_Hardwood_Planks"
        },
        {
            "x": -4,
            "y": 30,
            "z": -2,
            "name": "Wood_Hardwood_Planks_Half"
        },
        {
            "x": -4,
            "y": 26,
            "z": -1,
            "name": "Cloth_Block_Wool_Red"
        },
        {
            "x": -4,
            "y": 27,
            "z": -1,
            "name": "Cloth_Block_Wool_Red"
        },
        {
            "x": -4,
            "y": 28,
            "z": -1,
            "name": "Cloth_Block_Wool_Red"
        },
        {
            "x": -4,
            "y": 29,
            "z": -1,
            "name": "Cloth_Block_Wool_Red"
        },
        {
            "x": -4,
            "y": 30,
            "z": -1,
            "name": "Cloth_Block_Wool_Red"
        },
        {
            "x": -4,
            "y": 31,
            "z": -1,
            "name": "Cloth_Block_Wool_Red"
        },
        {
            "x": -4,
            "y": 32,
            "z": -1,
            "name": "Cloth_Block_Wool_Red"
        },
        {
            "x": -4,
            "y": 24,
            "z": 0,
            "name": "Cloth_Block_Wool_Red"
        },
        {
            "x": -4,
            "y": 25,
            "z": 0,
            "name": "Cloth_Block_Wool_Red"
        },
        {
            "x": -4,
            "y": 33,
            "z": 0,
            "name": "Cloth_Block_Wool_Red"
        },
        {
            "x": -4,
            "y": 34,
            "z": 0,
            "name": "Cloth_Block_Wool_Red"
        },
        {
            "x": -4,
            "y": 23,
            "z": 1,
            "name": "Cloth_Block_Wool_Red"
        },
        {
            "x": -4,
            "y": 35,
            "z": 1,
            "name": "Cloth_Block_Wool_Red"
        },
        {
            "x": -4,
            "y": 22,
            "z": 2,
            "name": "Cloth_Block_Wool_Red"
        },
        {
            "x": -4,
            "y": 36,
            "z": 2,
            "name": "Cloth_Block_Wool_Red"
        },
        {
            "x": -4,
            "y": 21,
            "z": 3,
            "name": "Cloth_Block_Wool_White"
        },
        {
            "x": -4,
            "y": 37,
            "z": 3,
            "name": "Cloth_Block_Wool_White"
        },
        {
            "x": -4,
            "y": 19,
            "z": 4,
            "name": "Wood_Hardwood_Beam"
        },
        {
            "x": -4,
            "y": 20,
            "z": 4,
            "name": "Wood_Hardwood_Planks"
        },
        {
            "x": -4,
            "y": 21,
            "z": 4,
            "name": "Cloth_Block_Wool_White"
        },
        {
            "x": -4,
            "y": 37,
            "z": 4,
            "name": "Cloth_Block_Wool_White"
        },
        {
            "x": -4,
            "y": 38,
            "z": 4,
            "name": "Wood_Hardwood_Planks"
        },
        {
            "x": -4,
            "y": 39,
            "z": 4,
            "name": "Wood_Hardwood_Beam"
        },
        {
            "x": -4,
            "y": 20,
            "z": 5,
            "name": "Cloth_Block_Wool_White"
        },
        {
            "x": -4,
            "y": 38,
            "z": 5,
            "name": "Cloth_Block_Wool_White"
        },
        {
            "x": -4,
            "y": 18,
            "z": 6,
            "name": "Wood_Hardwood_Planks"
        },
        {
            "x": -4,
            "y": 19,
            "z": 6,
            "name": "Cloth_Block_Wool_Red"
        },
        {
            "x": -4,
            "y": 20,
            "z": 6,
            "name": "Cloth_Block_Wool_Red"
        },
        {
            "x": -4,
            "y": 38,
            "z": 6,
            "name": "Cloth_Block_Wool_Red"
        },
        {
            "x": -4,
            "y": 18,
            "z": 7,
            "name": "Cloth_Block_Wool_Red"
        },
        {
            "x": -4,
            "y": 19,
            "z": 7,
            "name": "Cloth_Block_Wool_Red"
        },
        {
            "x": -4,
            "y": 20,
            "z": 7,
            "name": "Cloth_Block_Wool_White"
        },
        {
            "x": -4,
            "y": 38,
            "z": 7,
            "name": "Cloth_Block_Wool_White"
        },
        {
            "x": -4,
            "y": 15,
            "z": 8,
            "name": "Wood_Hardwood_Beam"
        },
        {
            "x": -4,
            "y": 16,
            "z": 8,
            "name": "Wood_Hardwood_Beam"
        },
        {
            "x": -4,
            "y": 17,
            "z": 8,
            "name": "Cloth_Block_Wool_Red"
        },
        {
            "x": -4,
            "y": 18,
            "z": 8,
            "name": "Cloth_Block_Wool_Red"
        },
        {
            "x": -4,
            "y": 19,
            "z": 8,
            "name": "Cloth_Block_Wool_Red"
        },
        {
            "x": -4,
            "y": 20,
            "z": 8,
            "name": "Cloth_Block_Wool_White"
        },
        {
            "x": -4,
            "y": 38,
            "z": 8,
            "name": "Cloth_Block_Wool_White"
        },
        {
            "x": -4,
            "y": 39,
            "z": 8,
            "name": "Wood_Hardwood_Planks"
        },
        {
            "x": -4,
            "y": 40,
            "z": 8,
            "name": "Wood_Hardwood_Beam"
        },
        {
            "x": -4,
            "y": 18,
            "z": 9,
            "name": "Cloth_Block_Wool_Red"
        },
        {
            "x": -4,
            "y": 19,
            "z": 9,
            "name": "Cloth_Block_Wool_Red"
        },
        {
            "x": -4,
            "y": 20,
            "z": 9,
            "name": "Cloth_Block_Wool_White"
        },
        {
            "x": -4,
            "y": 38,
            "z": 9,
            "name": "Cloth_Block_Wool_White"
        },
        {
            "x": -4,
            "y": 18,
            "z": 10,
            "name": "Wood_Hardwood_Planks"
        },
        {
            "x": -4,
            "y": 19,
            "z": 10,
            "name": "Cloth_Block_Wool_Red"
        },
        {
            "x": -4,
            "y": 20,
            "z": 10,
            "name": "Cloth_Block_Wool_Red"
        },
        {
            "x": -4,
            "y": 38,
            "z": 10,
            "name": "Cloth_Block_Wool_Red"
        },
        {
            "x": -4,
            "y": 20,
            "z": 11,
            "name": "Cloth_Block_Wool_White"
        },
        {
            "x": -4,
            "y": 38,
            "z": 11,
            "name": "Cloth_Block_Wool_White"
        },
        {
            "x": -4,
            "y": 19,
            "z": 12,
            "name": "Wood_Hardwood_Beam"
        },
        {
            "x": -4,
            "y": 20,
            "z": 12,
            "name": "Wood_Hardwood_Planks"
        },
        {
            "x": -4,
            "y": 21,
            "z": 12,
            "name": "Cloth_Block_Wool_White"
        },
        {
            "x": -4,
            "y": 37,
            "z": 12,
            "name": "Cloth_Block_Wool_White"
        },
        {
            "x": -4,
            "y": 38,
            "z": 12,
            "name": "Wood_Hardwood_Planks"
        },
        {
            "x": -4,
            "y": 39,
            "z": 12,
            "name": "Wood_Hardwood_Beam"
        },
        {
            "x": -4,
            "y": 21,
            "z": 13,
            "name": "Cloth_Block_Wool_White"
        },
        {
            "x": -4,
            "y": 37,
            "z": 13,
            "name": "Cloth_Block_Wool_White"
        },
        {
            "x": -4,
            "y": 22,
            "z": 14,
            "name": "Cloth_Block_Wool_Red"
        },
        {
            "x": -4,
            "y": 36,
            "z": 14,
            "name": "Cloth_Block_Wool_Red"
        },
        {
            "x": -4,
            "y": 23,
            "z": 15,
            "name": "Cloth_Block_Wool_Red"
        },
        {
            "x": -4,
            "y": 35,
            "z": 15,
            "name": "Cloth_Block_Wool_Red"
        },
        {
            "x": -4,
            "y": 24,
            "z": 16,
            "name": "Cloth_Block_Wool_Red"
        },
        {
            "x": -4,
            "y": 25,
            "z": 16,
            "name": "Cloth_Block_Wool_Red"
        },
        {
            "x": -4,
            "y": 33,
            "z": 16,
            "name": "Cloth_Block_Wool_Red"
        },
        {
            "x": -4,
            "y": 34,
            "z": 16,
            "name": "Cloth_Block_Wool_Red"
        },
        {
            "x": -4,
            "y": 26,
            "z": 17,
            "name": "Cloth_Block_Wool_Red"
        },
        {
            "x": -4,
            "y": 27,
            "z": 17,
            "name": "Cloth_Block_Wool_Red"
        },
        {
            "x": -4,
            "y": 28,
            "z": 17,
            "name": "Cloth_Block_Wool_Red"
        },
        {
            "x": -4,
            "y": 29,
            "z": 17,
            "name": "Cloth_Block_Wool_Red"
        },
        {
            "x": -4,
            "y": 30,
            "z": 17,
            "name": "Cloth_Block_Wool_Red"
        },
        {
            "x": -4,
            "y": 31,
            "z": 17,
            "name": "Cloth_Block_Wool_Red"
        },
        {
            "x": -4,
            "y": 32,
            "z": 17,
            "name": "Cloth_Block_Wool_Red"
        },
        {
            "x": -4,
            "y": 28,
            "z": 18,
            "name": "Wood_Hardwood_Planks_Half",
            "rotation": 8
        },
        {
            "x": -4,
            "y": 29,
            "z": 18,
            "name": "Wood_Hardwood_Planks"
        },
        {
            "x": -4,
            "y": 30,
            "z": 18,
            "name": "Wood_Hardwood_Planks_Half"
        },
        {
            "x": -3,
            "y": 28,
            "z": -3,
            "name": "Wood_Hardwood_Planks_Half",
            "rotation": 8
        },
        {
            "x": -3,
            "y": 29,
            "z": -3,
            "name": "Wood_Hardwood_Planks"
        },
        {
            "x": -3,
            "y": 30,
            "z": -3,
            "name": "Wood_Hardwood_Planks_Half"
        },
        {
            "x": -3,
            "y": 28,
            "z": -2,
            "name": "Cloth_Block_Wool_Red"
        },
        {
            "x": -3,
            "y": 29,
            "z": -2,
            "name": "Cloth_Block_Wool_Red"
        },
        {
            "x": -3,
            "y": 30,
            "z": -2,
            "name": "Cloth_Block_Wool_Red"
        },
        {
            "x": -3,
            "y": 25,
            "z": -1,
            "name": "Cloth_Block_Wool_Red"
        },
        {
            "x": -3,
            "y": 26,
            "z": -1,
            "name": "Cloth_Block_Wool_Red"
        },
        {
            "x": -3,
            "y": 27,
            "z": -1,
            "name": "Cloth_Block_Wool_Red"
        },
        {
            "x": -3,
            "y": 31,
            "z": -1,
            "name": "Cloth_Block_Wool_Red"
        },
        {
            "x": -3,
            "y": 32,
            "z": -1,
            "name": "Cloth_Block_Wool_Red"
        },
        {
            "x": -3,
            "y": 33,
            "z": -1,
            "name": "Cloth_Block_Wool_Red"
        },
        {
            "x": -3,
            "y": 23,
            "z": 0,
            "name": "Cloth_Block_Wool_Red"
        },
        {
            "x": -3,
            "y": 24,
            "z": 0,
            "name": "Cloth_Block_Wool_Red"
        },
        {
            "x": -3,
            "y": 34,
            "z": 0,
            "name": "Cloth_Block_Wool_Red"
        },
        {
            "x": -3,
            "y": 35,
            "z": 0,
            "name": "Cloth_Block_Wool_Red"
        },
        {
            "x": -3,
            "y": 22,
            "z": 1,
            "name": "Cloth_Block_Wool_Red"
        },
        {
            "x": -3,
            "y": 36,
            "z": 1,
            "name": "Cloth_Block_Wool_Red"
        },
        {
            "x": -3,
            "y": 21,
            "z": 2,
            "name": "Cloth_Block_Wool_Red"
        },
        {
            "x": -3,
            "y": 37,
            "z": 2,
            "name": "Cloth_Block_Wool_Red"
        },
        {
            "x": -3,
            "y": 20,
            "z": 3,
            "name": "Wood_Hardwood_Planks"
        },
        {
            "x": -3,
            "y": 21,
            "z": 3,
            "name": "Cloth_Block_Wool_Red"
        },
        {
            "x": -3,
            "y": 37,
            "z": 3,
            "name": "Cloth_Block_Wool_Red"
        },
        {
            "x": -3,
            "y": 20,
            "z": 4,
            "name": "Cloth_Block_Wool_White"
        },
        {
            "x": -3,
            "y": 38,
            "z": 4,
            "name": "Cloth_Block_Wool_White"
        },
        {
            "x": -3,
            "y": 18,
            "z": 5,
            "name": "Wood_Hardwood_Planks"
        },
        {
            "x": -3,
            "y": 19,
            "z": 5,
            "name": "Cloth_Block_Wool_Red"
        },
        {
            "x": -3,
            "y": 20,
            "z": 5,
            "name": "Cloth_Block_Wool_White"
        },
        {
            "x": -3,
            "y": 38,
            "z": 5,
            "name": "Cloth_Block_Wool_White"
        },
        {
            "x": -3,
            "y": 39,
            "z": 5,
            "name": "Wood_Hardwood_Planks"
        },
        {
            "x": -3,
            "y": 40,
            "z": 5,
            "name": "Wood_Hardwood_Beam"
        },
        {
            "x": -3,
            "y": 9,
            "z": 6,
            "name": "Wood_Hardwood_Planks_Half",
            "rotation": 7
        },
        {
            "x": -3,
            "y": 18,
            "z": 6,
            "name": "Cloth_Block_Wool_Red"
        },
        {
            "x": -3,
            "y": 19,
            "z": 6,
            "name": "Cloth_Block_Wool_Red"
        },
        {
            "x": -3,
            "y": 20,
            "z": 6,
            "name": "Cloth_Block_Wool_White"
        },
        {
            "x": -3,
            "y": 38,
            "z": 6,
            "name": "Cloth_Block_Wool_White"
        },
        {
            "x": -3,
            "y": 13,
            "z": 7,
            "name": "Wood_Hardwood_Planks_Half",
            "rotation": 7
        },
        {
            "x": -3,
            "y": 16,
            "z": 7,
            "name": "Cloth_Block_Wool_Red"
        },
        {
            "x": -3,
            "y": 17,
            "z": 7,
            "name": "Cloth_Block_Wool_Red"
        },
        {
            "x": -3,
            "y": 18,
            "z": 7,
            "name": "Cloth_Block_Wool_Red"
        },
        {
            "x": -3,
            "y": 19,
            "z": 7,
            "name": "Cloth_Block_Wool_White"
        },
        {
            "x": -3,
            "y": 39,
            "z": 7,
            "name": "Cloth_Block_Wool_White"
        },
        {
            "x": -3,
            "y": 9,
            "z": 8,
            "name": "*Furniture_Crude_Trapdoor_State_Definitions_OpenDoorOut",
            "rotation": 3
        },
        {
            "x": -3,
            "y": 13,
            "z": 8,
            "name": "Wood_Hardwood_Planks_Half",
            "rotation": 7
        },
        {
            "x": -3,
            "y": 14,
            "z": 8,
            "name": "Wood_Hardwood_Planks_Half",
            "rotation": 7
        },
        {
            "x": -3,
            "y": 15,
            "z": 8,
            "name": "Wood_Hardwood_Planks_Half",
            "rotation": 7
        },
        {
            "x": -3,
            "y": 16,
            "z": 8,
            "name": "Cloth_Block_Wool_Red"
        },
        {
            "x": -3,
            "y": 17,
            "z": 8,
            "name": "Cloth_Block_Wool_Red"
        },
        {
            "x": -3,
            "y": 18,
            "z": 8,
            "name": "Cloth_Block_Wool_Red"
        },
        {
            "x": -3,
            "y": 19,
            "z": 8,
            "name": "Cloth_Block_Wool_White"
        },
        {
            "x": -3,
            "y": 39,
            "z": 8,
            "name": "Cloth_Block_Wool_White"
        },
        {
            "x": -3,
            "y": 40,
            "z": 8,
            "name": "Wood_Hardwood_Planks"
        },
        {
            "x": -3,
            "y": 13,
            "z": 9,
            "name": "Wood_Hardwood_Planks_Half",
            "rotation": 7
        },
        {
            "x": -3,
            "y": 16,
            "z": 9,
            "name": "Cloth_Block_Wool_Red"
        },
        {
            "x": -3,
            "y": 17,
            "z": 9,
            "name": "Cloth_Block_Wool_Red"
        },
        {
            "x": -3,
            "y": 18,
            "z": 9,
            "name": "Cloth_Block_Wool_Red"
        },
        {
            "x": -3,
            "y": 19,
            "z": 9,
            "name": "Cloth_Block_Wool_White"
        },
        {
            "x": -3,
            "y": 39,
            "z": 9,
            "name": "Cloth_Block_Wool_White"
        },
        {
            "x": -3,
            "y": 9,
            "z": 10,
            "name": "Wood_Hardwood_Planks_Half",
            "rotation": 7
        },
        {
            "x": -3,
            "y": 18,
            "z": 10,
            "name": "Cloth_Block_Wool_Red"
        },
        {
            "x": -3,
            "y": 19,
            "z": 10,
            "name": "Cloth_Block_Wool_Red"
        },
        {
            "x": -3,
            "y": 20,
            "z": 10,
            "name": "Cloth_Block_Wool_White"
        },
        {
            "x": -3,
            "y": 38,
            "z": 10,
            "name": "Cloth_Block_Wool_White"
        },
        {
            "x": -3,
            "y": 17,
            "z": 11,
            "name": "Wood_Hardwood_Beam"
        },
        {
            "x": -3,
            "y": 18,
            "z": 11,
            "name": "Wood_Hardwood_Planks"
        },
        {
            "x": -3,
            "y": 19,
            "z": 11,
            "name": "Cloth_Block_Wool_Red"
        },
        {
            "x": -3,
            "y": 20,
            "z": 11,
            "name": "Cloth_Block_Wool_White"
        },
        {
            "x": -3,
            "y": 38,
            "z": 11,
            "name": "Cloth_Block_Wool_White"
        },
        {
            "x": -3,
            "y": 39,
            "z": 11,
            "name": "Wood_Hardwood_Planks"
        },
        {
            "x": -3,
            "y": 40,
            "z": 11,
            "name": "Wood_Hardwood_Beam"
        },
        {
            "x": -3,
            "y": 20,
            "z": 12,
            "name": "Cloth_Block_Wool_White"
        },
        {
            "x": -3,
            "y": 38,
            "z": 12,
            "name": "Cloth_Block_Wool_White"
        },
        {
            "x": -3,
            "y": 20,
            "z": 13,
            "name": "Wood_Hardwood_Planks"
        },
        {
            "x": -3,
            "y": 21,
            "z": 13,
            "name": "Cloth_Block_Wool_Red"
        },
        {
            "x": -3,
            "y": 37,
            "z": 13,
            "name": "Cloth_Block_Wool_Red"
        },
        {
            "x": -3,
            "y": 21,
            "z": 14,
            "name": "Cloth_Block_Wool_Red"
        },
        {
            "x": -3,
            "y": 37,
            "z": 14,
            "name": "Cloth_Block_Wool_Red"
        },
        {
            "x": -3,
            "y": 22,
            "z": 15,
            "name": "Cloth_Block_Wool_Red"
        },
        {
            "x": -3,
            "y": 36,
            "z": 15,
            "name": "Cloth_Block_Wool_Red"
        },
        {
            "x": -3,
            "y": 23,
            "z": 16,
            "name": "Cloth_Block_Wool_Red"
        },
        {
            "x": -3,
            "y": 24,
            "z": 16,
            "name": "Cloth_Block_Wool_Red"
        },
        {
            "x": -3,
            "y": 34,
            "z": 16,
            "name": "Cloth_Block_Wool_Red"
        },
        {
            "x": -3,
            "y": 35,
            "z": 16,
            "name": "Cloth_Block_Wool_Red"
        },
        {
            "x": -3,
            "y": 25,
            "z": 17,
            "name": "Cloth_Block_Wool_Red"
        },
        {
            "x": -3,
            "y": 26,
            "z": 17,
            "name": "Cloth_Block_Wool_Red"
        },
        {
            "x": -3,
            "y": 27,
            "z": 17,
            "name": "Cloth_Block_Wool_Red"
        },
        {
            "x": -3,
            "y": 31,
            "z": 17,
            "name": "Cloth_Block_Wool_Red"
        },
        {
            "x": -3,
            "y": 32,
            "z": 17,
            "name": "Cloth_Block_Wool_Red"
        },
        {
            "x": -3,
            "y": 33,
            "z": 17,
            "name": "Cloth_Block_Wool_Red"
        },
        {
            "x": -3,
            "y": 28,
            "z": 18,
            "name": "Cloth_Block_Wool_Red"
        },
        {
            "x": -3,
            "y": 29,
            "z": 18,
            "name": "Cloth_Block_Wool_Red"
        },
        {
            "x": -3,
            "y": 30,
            "z": 18,
            "name": "Cloth_Block_Wool_Red"
        },
        {
            "x": -3,
            "y": 28,
            "z": 19,
            "name": "Wood_Hardwood_Planks_Half",
            "rotation": 8
        },
        {
            "x": -3,
            "y": 29,
            "z": 19,
            "name": "Wood_Hardwood_Planks"
        },
        {
            "x": -3,
            "y": 30,
            "z": 19,
            "name": "Wood_Hardwood_Planks_Half"
        },
        {
            "x": -2,
            "y": 29,
            "z": -3,
            "name": "Wood_Hardwood_Planks"
        },
        {
            "x": -2,
            "y": 27,
            "z": -2,
            "name": "Cloth_Block_Wool_Red"
        },
        {
            "x": -2,
            "y": 28,
            "z": -2,
            "name": "Cloth_Block_Wool_Red"
        },
        {
            "x": -2,
            "y": 29,
            "z": -2,
            "name": "Cloth_Block_Wool_Red"
        },
        {
            "x": -2,
            "y": 30,
            "z": -2,
            "name": "Cloth_Block_Wool_Red"
        },
        {
            "x": -2,
            "y": 31,
            "z": -2,
            "name": "Cloth_Block_Wool_Red"
        },
        {
            "x": -2,
            "y": 24,
            "z": -1,
            "name": "Cloth_Block_Wool_Red"
        },
        {
            "x": -2,
            "y": 25,
            "z": -1,
            "name": "Cloth_Block_Wool_Red"
        },
        {
            "x": -2,
            "y": 26,
            "z": -1,
            "name": "Cloth_Block_Wool_Red"
        },
        {
            "x": -2,
            "y": 32,
            "z": -1,
            "name": "Cloth_Block_Wool_Red"
        },
        {
            "x": -2,
            "y": 33,
            "z": -1,
            "name": "Cloth_Block_Wool_Red"
        },
        {
            "x": -2,
            "y": 34,
            "z": -1,
            "name": "Cloth_Block_Wool_Red"
        },
        {
            "x": -2,
            "y": 23,
            "z": 0,
            "name": "Cloth_Block_Wool_Red"
        },
        {
            "x": -2,
            "y": 35,
            "z": 0,
            "name": "Cloth_Block_Wool_Red"
        },
        {
            "x": -2,
            "y": 22,
            "z": 1,
            "name": "Cloth_Block_Wool_Red"
        },
        {
            "x": -2,
            "y": 36,
            "z": 1,
            "name": "Cloth_Block_Wool_Red"
        },
        {
            "x": -2,
            "y": 20,
            "z": 2,
            "name": "Wood_Hardwood_Planks"
        },
        {
            "x": -2,
            "y": 21,
            "z": 2,
            "name": "Cloth_Block_Wool_Red"
        },
        {
            "x": -2,
            "y": 37,
            "z": 2,
            "name": "Cloth_Block_Wool_Red"
        },
        {
            "x": -2,
            "y": 20,
            "z": 3,
            "name": "Cloth_Block_Wool_Red"
        },
        {
            "x": -2,
            "y": 38,
            "z": 3,
            "name": "Cloth_Block_Wool_Red"
        },
        {
            "x": -2,
            "y": 18,
            "z": 4,
            "name": "Wood_Hardwood_Planks"
        },
        {
            "x": -2,
            "y": 19,
            "z": 4,
            "name": "Cloth_Block_Wool_Red"
        },
        {
            "x": -2,
            "y": 20,
            "z": 4,
            "name": "Cloth_Block_Wool_Red"
        },
        {
            "x": -2,
            "y": 38,
            "z": 4,
            "name": "Cloth_Block_Wool_Red"
        },
        {
            "x": -2,
            "y": 9,
            "z": 5,
            "name": "Wood_Hardwood_Planks_Half",
            "rotation": 6
        },
        {
            "x": -2,
            "y": 18,
            "z": 5,
            "name": "Cloth_Block_Wool_Red"
        },
        {
            "x": -2,
            "y": 19,
            "z": 5,
            "name": "Cloth_Block_Wool_Red"
        },
        {
            "x": -2,
            "y": 20,
            "z": 5,
            "name": "Cloth_Block_Wool_White"
        },
        {
            "x": -2,
            "y": 38,
            "z": 5,
            "name": "Cloth_Block_Wool_White"
        },
        {
            "x": -2,
            "y": 7,
            "z": 6,
            "name": "Furniture_Village_Crate"
        },
        {
            "x": -2,
            "y": 8,
            "z": 6,
            "name": "Deco_Rope"
        },
        {
            "x": -2,
            "y": 9,
            "z": 6,
            "name": "*Wood_Hardwood_Planks_Half_State_Definitions_Block",
            "rotation": 8
        },
        {
            "x": -2,
            "y": 10,
            "z": 6,
            "name": "Rock_Calcite_Brick_Beam"
        },
        {
            "x": -2,
            "y": 11,
            "z": 6,
            "name": "Wood_Hardwood_Beam"
        },
        {
            "x": -2,
            "y": 12,
            "z": 6,
            "name": "Wood_Hardwood_Beam"
        },
        {
            "x": -2,
            "y": 13,
            "z": 6,
            "name": "Wood_Hardwood_Beam"
        },
        {
            "x": -2,
            "y": 14,
            "z": 6,
            "name": "Wood_Hardwood_Beam"
        },
        {
            "x": -2,
            "y": 15,
            "z": 6,
            "name": "Wood_Hardwood_Beam"
        },
        {
            "x": -2,
            "y": 16,
            "z": 6,
            "name": "Cloth_Block_Wool_Red"
        },
        {
            "x": -2,
            "y": 17,
            "z": 6,
            "name": "Cloth_Block_Wool_Red"
        },
        {
            "x": -2,
            "y": 18,
            "z": 6,
            "name": "Cloth_Block_Wool_Red"
        },
        {
            "x": -2,
            "y": 19,
            "z": 6,
            "name": "Cloth_Block_Wool_White"
        },
        {
            "x": -2,
            "y": 39,
            "z": 6,
            "name": "Cloth_Block_Wool_White"
        },
        {
            "x": -2,
            "y": 40,
            "z": 6,
            "name": "Wood_Hardwood_Planks"
        },
        {
            "x": -2,
            "y": 8,
            "z": 7,
            "name": "Wood_Hardwood_Beam"
        },
        {
            "x": -2,
            "y": 9,
            "z": 7,
            "name": "Wood_Hardwood_Stairs"
        },
        {
            "x": -2,
            "y": 13,
            "z": 7,
            "name": "Wood_Hardwood_Planks"
        },
        {
            "x": -2,
            "y": 14,
            "z": 7,
            "name": "Cloth_Block_Wool_Red"
        },
        {
            "x": -2,
            "y": 15,
            "z": 7,
            "name": "Cloth_Block_Wool_Red"
        },
        {
            "x": -2,
            "y": 16,
            "z": 7,
            "name": "Cloth_Block_Wool_Red"
        },
        {
            "x": -2,
            "y": 19,
            "z": 7,
            "name": "Cloth_Block_Wool_Red"
        },
        {
            "x": -2,
            "y": 39,
            "z": 7,
            "name": "Cloth_Block_Wool_Red"
        },
        {
            "x": -2,
            "y": 8,
            "z": 8,
            "name": "Wood_Hardwood_Stairs",
            "rotation": 9
        },
        {
            "x": -2,
            "y": 9,
            "z": 8,
            "name": "Wood_Hardwood_Planks"
        },
        {
            "x": -2,
            "y": 13,
            "z": 8,
            "name": "Wood_Hardwood_Planks"
        },
        {
            "x": -2,
            "y": 14,
            "z": 8,
            "name": "Cloth_Block_Wool_Red"
        },
        {
            "x": -2,
            "y": 15,
            "z": 8,
            "name": "Cloth_Block_Wool_Red"
        },
        {
            "x": -2,
            "y": 16,
            "z": 8,
            "name": "Cloth_Block_Wool_Red"
        },
        {
            "x": -2,
            "y": 19,
            "z": 8,
            "name": "Cloth_Block_Wool_White"
        },
        {
            "x": -2,
            "y": 39,
            "z": 8,
            "name": "Cloth_Block_Wool_White"
        },
        {
            "x": -2,
            "y": 40,
            "z": 8,
            "name": "Wood_Hardwood_Planks"
        },
        {
            "x": -2,
            "y": 8,
            "z": 9,
            "name": "Wood_Hardwood_Beam"
        },
        {
            "x": -2,
            "y": 9,
            "z": 9,
            "name": "Wood_Hardwood_Stairs",
            "rotation": 2
        },
        {
            "x": -2,
            "y": 13,
            "z": 9,
            "name": "Wood_Hardwood_Planks"
        },
        {
            "x": -2,
            "y": 14,
            "z": 9,
            "name": "Cloth_Block_Wool_Red"
        },
        {
            "x": -2,
            "y": 15,
            "z": 9,
            "name": "Cloth_Block_Wool_Red"
        },
        {
            "x": -2,
            "y": 16,
            "z": 9,
            "name": "Cloth_Block_Wool_Red"
        },
        {
            "x": -2,
            "y": 19,
            "z": 9,
            "name": "Cloth_Block_Wool_Red"
        },
        {
            "x": -2,
            "y": 39,
            "z": 9,
            "name": "Cloth_Block_Wool_Red"
        },
        {
            "x": -2,
            "y": 7,
            "z": 10,
            "name": "Furniture_Village_Crate"
        },
        {
            "x": -2,
            "y": 8,
            "z": 10,
            "name": "Deco_Rope"
        },
        {
            "x": -2,
            "y": 9,
            "z": 10,
            "name": "*Wood_Hardwood_Planks_Half_State_Definitions_Block",
            "rotation": 8
        },
        {
            "x": -2,
            "y": 10,
            "z": 10,
            "name": "Rock_Calcite_Brick_Beam"
        },
        {
            "x": -2,
            "y": 11,
            "z": 10,
            "name": "Wood_Hardwood_Beam"
        },
        {
            "x": -2,
            "y": 12,
            "z": 10,
            "name": "Wood_Hardwood_Beam"
        },
        {
            "x": -2,
            "y": 13,
            "z": 10,
            "name": "Wood_Hardwood_Beam"
        },
        {
            "x": -2,
            "y": 14,
            "z": 10,
            "name": "Wood_Hardwood_Beam"
        },
        {
            "x": -2,
            "y": 15,
            "z": 10,
            "name": "Wood_Hardwood_Beam"
        },
        {
            "x": -2,
            "y": 16,
            "z": 10,
            "name": "Cloth_Block_Wool_Red"
        },
        {
            "x": -2,
            "y": 17,
            "z": 10,
            "name": "Cloth_Block_Wool_Red"
        },
        {
            "x": -2,
            "y": 18,
            "z": 10,
            "name": "Cloth_Block_Wool_Red"
        },
        {
            "x": -2,
            "y": 19,
            "z": 10,
            "name": "Cloth_Block_Wool_White"
        },
        {
            "x": -2,
            "y": 39,
            "z": 10,
            "name": "Cloth_Block_Wool_White"
        },
        {
            "x": -2,
            "y": 40,
            "z": 10,
            "name": "Wood_Hardwood_Planks"
        },
        {
            "x": -2,
            "y": 9,
            "z": 11,
            "name": "Wood_Hardwood_Planks_Half",
            "rotation": 4
        },
        {
            "x": -2,
            "y": 18,
            "z": 11,
            "name": "Cloth_Block_Wool_Red"
        },
        {
            "x": -2,
            "y": 19,
            "z": 11,
            "name": "Cloth_Block_Wool_Red"
        },
        {
            "x": -2,
            "y": 20,
            "z": 11,
            "name": "Cloth_Block_Wool_White"
        },
        {
            "x": -2,
            "y": 38,
            "z": 11,
            "name": "Cloth_Block_Wool_White"
        },
        {
            "x": -2,
            "y": 18,
            "z": 12,
            "name": "Wood_Hardwood_Planks"
        },
        {
            "x": -2,
            "y": 19,
            "z": 12,
            "name": "Cloth_Block_Wool_Red"
        },
        {
            "x": -2,
            "y": 20,
            "z": 12,
            "name": "Cloth_Block_Wool_Red"
        },
        {
            "x": -2,
            "y": 38,
            "z": 12,
            "name": "Cloth_Block_Wool_Red"
        },
        {
            "x": -2,
            "y": 20,
            "z": 13,
            "name": "Cloth_Block_Wool_Red"
        },
        {
            "x": -2,
            "y": 38,
            "z": 13,
            "name": "Cloth_Block_Wool_Red"
        },
        {
            "x": -2,
            "y": 20,
            "z": 14,
            "name": "Wood_Hardwood_Planks"
        },
        {
            "x": -2,
            "y": 21,
            "z": 14,
            "name": "Cloth_Block_Wool_Red"
        },
        {
            "x": -2,
            "y": 37,
            "z": 14,
            "name": "Cloth_Block_Wool_Red"
        },
        {
            "x": -2,
            "y": 22,
            "z": 15,
            "name": "Cloth_Block_Wool_Red"
        },
        {
            "x": -2,
            "y": 36,
            "z": 15,
            "name": "Cloth_Block_Wool_Red"
        },
        {
            "x": -2,
            "y": 23,
            "z": 16,
            "name": "Cloth_Block_Wool_Red"
        },
        {
            "x": -2,
            "y": 35,
            "z": 16,
            "name": "Cloth_Block_Wool_Red"
        },
        {
            "x": -2,
            "y": 24,
            "z": 17,
            "name": "Cloth_Block_Wool_Red"
        },
        {
            "x": -2,
            "y": 25,
            "z": 17,
            "name": "Cloth_Block_Wool_Red"
        },
        {
            "x": -2,
            "y": 26,
            "z": 17,
            "name": "Cloth_Block_Wool_Red"
        },
        {
            "x": -2,
            "y": 32,
            "z": 17,
            "name": "Cloth_Block_Wool_Red"
        },
        {
            "x": -2,
            "y": 33,
            "z": 17,
            "name": "Cloth_Block_Wool_Red"
        },
        {
            "x": -2,
            "y": 34,
            "z": 17,
            "name": "Cloth_Block_Wool_Red"
        },
        {
            "x": -2,
            "y": 27,
            "z": 18,
            "name": "Cloth_Block_Wool_Red"
        },
        {
            "x": -2,
            "y": 28,
            "z": 18,
            "name": "Cloth_Block_Wool_Red"
        },
        {
            "x": -2,
            "y": 29,
            "z": 18,
            "name": "Cloth_Block_Wool_Red"
        },
        {
            "x": -2,
            "y": 30,
            "z": 18,
            "name": "Cloth_Block_Wool_Red"
        },
        {
            "x": -2,
            "y": 31,
            "z": 18,
            "name": "Cloth_Block_Wool_Red"
        },
        {
            "x": -2,
            "y": 29,
            "z": 19,
            "name": "Wood_Hardwood_Planks"
        },
        {
            "x": -1,
            "y": 29,
            "z": -4,
            "name": "*Furniture_Crude_Trapdoor_State_Definitions_OpenDoorOut",
            "rotation": 2
        },
        {
            "x": -1,
            "y": 28,
            "z": -3,
            "name": "Wood_Hardwood_Stairs",
            "rotation": 9
        },
        {
            "x": -1,
            "y": 29,
            "z": -3,
            "name": "Wood_Hardwood_Planks"
        },
        {
            "x": -1,
            "y": 30,
            "z": -3,
            "name": "Wood_Hardwood_Stairs",
            "rotation": 3
        },
        {
            "x": -1,
            "y": 26,
            "z": -2,
            "name": "Cloth_Block_Wool_White"
        },
        {
            "x": -1,
            "y": 27,
            "z": -2,
            "name": "Cloth_Block_Wool_White"
        },
        {
            "x": -1,
            "y": 28,
            "z": -2,
            "name": "Cloth_Block_Wool_White"
        },
        {
            "x": -1,
            "y": 29,
            "z": -2,
            "name": "Cloth_Block_Wool_White"
        },
        {
            "x": -1,
            "y": 30,
            "z": -2,
            "name": "Cloth_Block_Wool_White"
        },
        {
            "x": -1,
            "y": 31,
            "z": -2,
            "name": "Cloth_Block_Wool_White"
        },
        {
            "x": -1,
            "y": 32,
            "z": -2,
            "name": "Cloth_Block_Wool_White"
        },
        {
            "x": -1,
            "y": 24,
            "z": -1,
            "name": "Cloth_Block_Wool_White"
        },
        {
            "x": -1,
            "y": 25,
            "z": -1,
            "name": "Cloth_Block_Wool_White"
        },
        {
            "x": -1,
            "y": 33,
            "z": -1,
            "name": "Cloth_Block_Wool_White"
        },
        {
            "x": -1,
            "y": 34,
            "z": -1,
            "name": "Cloth_Block_Wool_White"
        },
        {
            "x": -1,
            "y": 23,
            "z": 0,
            "name": "Cloth_Block_Wool_White"
        },
        {
            "x": -1,
            "y": 35,
            "z": 0,
            "name": "Cloth_Block_Wool_White"
        },
        {
            "x": -1,
            "y": 22,
            "z": 1,
            "name": "Cloth_Block_Wool_White"
        },
        {
            "x": -1,
            "y": 36,
            "z": 1,
            "name": "Cloth_Block_Wool_White"
        },
