{
  "version": 8,
  "blockIdVersion": 11,
  "anchorX": 0,
  "anchorY": 0,
  "anchorZ": 0,
  "blocks": [
    {
      "x": -5,
      "y": 14,
      "z": -8,
      "name": "Cloth_Roof_White_Vertical",
      "rotation": 3
    },
    {
      "x": -5,
      "y": 14,
      "z": -7,
      "name": "Cloth_Roof_White_Vertical",
      "rotation": 3
    },
    {
      "x": -5,
      "y": 14,
      "z": -6,
      "name": "Cloth_Roof_White_Vertical",
      "rotation": 3
    },
    {
      "x": -5,
      "y": 14,
      "z": -5,
      "name": "Cloth_Roof_White_Vertical",
      "rotation": 3
    },
    {
      "x": -5,
      "y": 14,
      "z": -4,
      "name": "Cloth_Roof_White_Vertical",
      "rotation": 3
    },
    {
      "x": -5,
      "y": 6,
      "z": -3,
      "name": "Wood_Softwood_Planks_Half",
      "rotation": 7
    },
    {
      "x": -5,
      "y": 7,
      "z": -3,
      "name": "*Wood_Softwood_Fence_State_Definitions_Corner",
      "rotation": 1
    },
    {
      "x": -5,
      "y": 13,
      "z": -3,
      "name": "*Furniture_Crude_Trapdoor_State_Definitions_OpenDoorOut",
      "rotation": 3
    },
    {
      "x": -5,
      "y": 15,
      "z": -3,
      "name": "*Furniture_Crude_Trapdoor_State_Definitions_OpenDoorOut",
      "rotation": 3
    },
    {
      "x": -5,
      "y": 6,
      "z": -2,
      "name": "Wood_Softwood_Planks_Half",
      "rotation": 7
    },
    {
      "x": -5,
      "y": 7,
      "z": -2,
      "name": "Wood_Softwood_Fence",
      "rotation": 3
    },
    {
      "x": -5,
      "y": 14,
      "z": -2,
      "name": "Cloth_Roof_White_Vertical",
      "rotation": 3
    },
    {
      "x": -5,
      "y": 5,
      "z": -1,
      "name": "Wood_Softwood_Planks_Half",
      "rotation": 7
    },
    {
      "x": -5,
      "y": 6,
      "z": -1,
      "name": "Wood_Softwood_Planks_Half",
      "rotation": 7
    },
    {
      "x": -5,
      "y": 7,
      "z": -1,
      "name": "Wood_Softwood_Fence",
      "rotation": 3
    },
    {
      "x": -5,
      "y": 14,
      "z": -1,
      "name": "Cloth_Roof_White_Vertical",
      "rotation": 3
    },
    {
      "x": -5,
      "y": 4,
      "z": 0,
      "name": "Furniture_Crude_Ladder",
      "rotation": 3
    },
    {
      "x": -5,
      "y": 5,
      "z": 0,
      "name": "Furniture_Crude_Ladder",
      "rotation": 3
    },
    {
      "x": -5,
      "y": 6,
      "z": 0,
      "name": "Furniture_Crude_Ladder",
      "rotation": 3
    },
    {
      "x": -5,
      "y": 7,
      "z": 0,
      "name": "Wood_Softwood_Fence_Gate",
      "rotation": 1
    },
    {
      "x": -5,
      "y": 14,
      "z": 0,
      "name": "Cloth_Roof_White_Vertical",
      "rotation": 3
    },
    {
      "x": -5,
      "y": 5,
      "z": 1,
      "name": "Wood_Softwood_Planks_Half",
      "rotation": 7
    },
    {
      "x": -5,
      "y": 6,
      "z": 1,
      "name": "Wood_Softwood_Planks_Half",
      "rotation": 7
    },
    {
      "x": -5,
      "y": 7,
      "z": 1,
      "name": "Wood_Softwood_Fence",
      "rotation": 3
    },
    {
      "x": -5,
      "y": 13,
      "z": 1,
      "name": "*Furniture_Crude_Trapdoor_State_Definitions_OpenDoorOut",
      "rotation": 3
    },
    {
      "x": -5,
      "y": 15,
      "z": 1,
      "name": "*Furniture_Crude_Trapdoor_State_Definitions_OpenDoorOut",
      "rotation": 3
    },
    {
      "x": -5,
      "y": 6,
      "z": 2,
      "name": "Wood_Softwood_Planks_Half",
      "rotation": 7
    },
    {
      "x": -5,
      "y": 7,
      "z": 2,
      "name": "Wood_Softwood_Fence",
      "rotation": 3
    },
    {
      "x": -5,
      "y": 14,
      "z": 2,
      "name": "Cloth_Roof_White_Vertical",
      "rotation": 3
    },
    {
      "x": -5,
      "y": 6,
      "z": 3,
      "name": "Wood_Softwood_Planks_Half",
      "rotation": 7
    },
    {
      "x": -5,
      "y": 7,
      "z": 3,
      "name": "Wood_Softwood_Planks_Half",
      "rotation": 7
    },
    {
      "x": -5,
      "y": 8,
      "z": 3,
      "name": "Wood_Softwood_Planks_Half",
      "rotation": 7
    },
    {
      "x": -5,
      "y": 14,
      "z": 3,
      "name": "Cloth_Roof_White_Vertical",
      "rotation": 3
    },
    {
      "x": -5,
      "y": 7,
      "z": 4,
      "name": "Wood_Softwood_Planks_Half",
      "rotation": 7
    },
    {
      "x": -5,
      "y": 8,
      "z": 4,
      "name": "Wood_Softwood_Planks_Half",
      "rotation": 7
    },
    {
      "x": -5,
      "y": 9,
      "z": 4,
      "name": "Wood_Softwood_Fence",
      "rotation": 3
    },
    {
      "x": -5,
      "y": 14,
      "z": 4,
      "name": "Cloth_Roof_White_Vertical",
      "rotation": 3
    },
    {
      "x": -5,
      "y": 7,
      "z": 5,
      "name": "Wood_Softwood_Fence",
      "rotation": 3
    },
    {
      "x": -5,
      "y": 8,
      "z": 5,
      "name": "Wood_Softwood_Planks_Half",
      "rotation": 7
    },
    {
      "x": -5,
      "y": 9,
      "z": 5,
      "name": "Wood_Softwood_Fence",
      "rotation": 3
    },
    {
      "x": -5,
      "y": 13,
      "z": 5,
      "name": "*Furniture_Crude_Trapdoor_State_Definitions_OpenDoorOut",
      "rotation": 3
    },
    {
      "x": -5,
      "y": 15,
      "z": 5,
      "name": "*Furniture_Crude_Trapdoor_State_Definitions_OpenDoorOut",
      "rotation": 3
    },
    {
      "x": -5,
      "y": 7,
      "z": 6,
      "name": "Wood_Softwood_Planks_Half",
      "rotation": 7
    },
    {
      "x": -5,
      "y": 8,
      "z": 6,
      "name": "Wood_Softwood_Planks_Half",
      "rotation": 7
    },
    {
      "x": -5,
      "y": 9,
      "z": 6,
      "name": "Wood_Softwood_Planks_Half",
      "rotation": 7
    },
    {
      "x": -5,
      "y": 14,
      "z": 6,
      "name": "Cloth_Roof_White_Vertical",
      "rotation": 3
    },
    {
      "x": -5,
      "y": 8,
      "z": 7,
      "name": "Wood_Softwood_Planks_Half",
      "rotation": 7
    },
    {
      "x": -5,
      "y": 9,
      "z": 7,
      "name": "Wood_Softwood_Fence",
      "rotation": 3
    },
    {
      "x": -5,
      "y": 14,
      "z": 7,
      "name": "Cloth_Roof_White_Vertical",
      "rotation": 3
    },
    {
      "x": -5,
      "y": 14,
      "z": 8,
      "name": "Cloth_Roof_White_Vertical",
      "rotation": 3
    },
    {
      "x": -5,
      "y": 13,
      "z": 9,
      "name": "*Furniture_Crude_Trapdoor_State_Definitions_OpenDoorOut",
      "rotation": 3
    },
    {
      "x": -5,
      "y": 15,
      "z": 9,
      "name": "*Furniture_Crude_Trapdoor_State_Definitions_OpenDoorOut",
      "rotation": 3
    },
    {
      "x": -5,
      "y": 14,
      "z": 10,
      "name": "Cloth_Roof_White_Vertical",
      "rotation": 3
    },
    {
      "x": -5,
      "y": 14,
      "z": 11,
      "name": "Cloth_Roof_White_Vertical",
      "rotation": 3
    },
    {
      "x": -5,
      "y": 14,
      "z": 12,
      "name": "Cloth_Roof_White_Vertical",
      "rotation": 3
    },
    {
      "x": -5,
      "y": 14,
      "z": 13,
      "name": "Cloth_Roof_White_Vertical",
      "rotation": 3
    },
    {
      "x": -5,
      "y": 14,
      "z": 14,
      "name": "Cloth_Roof_White_Vertical",
      "rotation": 3
    },
    {
      "x": -4,
      "y": 14,
      "z": -9,
      "name": "Cloth_Roof_White_Vertical",
      "rotation": 2
    },
    {
      "x": -4,
      "y": 12,
      "z": -8,
      "name": "*Cloth_Roof_White_Steep_State_Definitions_Corner_Left",
      "filler": 31744,
      "rotation": 9
    },
    {
      "x": -4,
      "y": 13,
      "z": -8,
      "name": "*Cloth_Roof_White_Steep_State_Definitions_Corner_Left",
      "rotation": 9
    },
    {
      "x": -4,
      "y": 14,
      "z": -8,
      "name": "Cloth_Block_Wool_White"
    },
    {
      "x": -4,
      "y": 15,
      "z": -8,
      "name": "*Cloth_Roof_White_Steep_State_Definitions_Corner_Left",
      "rotation": 2
    },
    {
      "x": -4,
      "y": 16,
      "z": -8,
      "name": "*Cloth_Roof_White_Steep_State_Definitions_Corner_Left",
      "filler": 1024,
      "rotation": 2
    },
    {
      "x": -4,
      "y": 12,
      "z": -7,
      "name": "Cloth_Roof_White_Steep",
      "rotation": 1
    },
    {
      "x": -4,
      "y": 13,
      "z": -7,
      "name": "Cloth_Roof_White_Steep",
      "filler": 1024,
      "rotation": 1
    },
    {
      "x": -4,
      "y": 14,
      "z": -7,
      "name": "Cloth_Block_Wool_White"
    },
    {
      "x": -4,
      "y": 15,
      "z": -7,
      "name": "Cloth_Roof_White_Steep",
      "rotation": 3
    },
    {
      "x": -4,
      "y": 16,
      "z": -7,
      "name": "Cloth_Roof_White_Steep",
      "filler": 1024,
      "rotation": 3
    },
    {
      "x": -4,
      "y": 12,
      "z": -6,
      "name": "Cloth_Roof_White_Steep",
      "rotation": 1
    },
    {
      "x": -4,
      "y": 13,
      "z": -6,
      "name": "Cloth_Roof_White_Steep",
      "filler": 1024,
      "rotation": 1
    },
    {
      "x": -4,
      "y": 14,
      "z": -6,
      "name": "Cloth_Block_Wool_White"
    },
    {
      "x": -4,
      "y": 15,
      "z": -6,
      "name": "Cloth_Roof_White_Steep",
      "rotation": 3
    },
    {
      "x": -4,
      "y": 16,
      "z": -6,
      "name": "Cloth_Roof_White_Steep",
      "filler": 1024,
      "rotation": 3
    },
    {
      "x": -4,
      "y": 12,
      "z": -5,
      "name": "Cloth_Roof_White_Steep",
      "rotation": 1
    },
    {
      "x": -4,
      "y": 13,
      "z": -5,
      "name": "Cloth_Roof_White_Steep",
      "filler": 1024,
      "rotation": 1
    },
    {
      "x": -4,
      "y": 14,
      "z": -5,
      "name": "Cloth_Block_Wool_White"
    },
    {
      "x": -4,
      "y": 15,
      "z": -5,
      "name": "Cloth_Roof_White_Steep",
      "rotation": 3
    },
    {
      "x": -4,
      "y": 16,
      "z": -5,
      "name": "Cloth_Roof_White_Steep",
      "filler": 1024,
      "rotation": 3
    },
    {
      "x": -4,
      "y": 7,
      "z": -4,
      "name": "*Wood_Softwood_Fence_State_Definitions_Corner",
      "rotation": 1
    },
    {
      "x": -4,
      "y": 12,
      "z": -4,
      "name": "Cloth_Roof_White_Vertical",
      "rotation": 3
    },
    {
      "x": -4,
      "y": 13,
      "z": -4,
      "name": "Cloth_Roof_White",
      "rotation": 1
    },
    {
      "x": -4,
      "y": 14,
      "z": -4,
      "name": "Cloth_Roof_White",
      "rotation": 3
    },
    {
      "x": -4,
      "y": 15,
      "z": -4,
      "name": "Cloth_Roof_White",
      "rotation": 3
    },
    {
      "x": -4,
      "y": 16,
      "z": -4,
      "name": "Cloth_Roof_White_Vertical",
      "rotation": 3
    },
    {
      "x": -4,
      "y": 6,
      "z": -3,
      "name": "Wood_Softwood_Planks"
    },
    {
      "x": -4,
      "y": 7,
      "z": -3,
      "name": "*Wood_Softwood_Fence_State_Definitions_Corner",
      "rotation": 3
    },
    {
      "x": -4,
      "y": 12,
      "z": -3,
      "name": "Wood_Softwood_Stairs",
      "rotation": 9
    },
    {
      "x": -4,
      "y": 13,
      "z": -3,
      "name": "Wood_Softwood_Planks",
      "support": 15,
      "rotation": 2
    },
    {
      "x": -4,
      "y": 14,
      "z": -3,
      "name": "Wood_Softwood_Planks_Half",
      "rotation": 5
    },
    {
      "x": -4,
      "y": 15,
      "z": -3,
      "name": "Wood_Softwood_Planks",
      "support": 15,
      "rotation": 2
    },
    {
      "x": -4,
      "y": 16,
      "z": -3,
      "name": "Wood_Softwood_Stairs",
      "rotation": 3
    },
    {
      "x": -4,
      "y": 5,
      "z": -2,
      "name": "Wood_Softwood_Stairs",
      "rotation": 8
    },
    {
      "x": -4,
      "y": 6,
      "z": -2,
      "name": "Wood_Softwood_Planks"
    },
    {
      "x": -4,
      "y": 12,
      "z": -2,
      "name": "Cloth_Roof_White_Vertical",
      "rotation": 3
    },
    {
      "x": -4,
      "y": 13,
      "z": -2,
      "name": "Cloth_Roof_White",
      "rotation": 1
    },
    {
      "x": -4,
      "y": 14,
      "z": -2,
      "name": "Wood_Softwood_Planks",
      "support": 15
    },
    {
      "x": -4,
      "y": 15,
      "z": -2,
      "name": "Cloth_Roof_White",
      "rotation": 3
    },
    {
      "x": -4,
      "y": 16,
      "z": -2,
      "name": "Cloth_Roof_White_Vertical",
      "rotation": 3
    },
    {
      "x": -4,
      "y": 4,
      "z": -1,
      "name": "Wood_Softwood_Planks_Half",
      "rotation": 7
    },
    {
      "x": -4,
      "y": 5,
      "z": -1,
      "name": "Wood_Softwood_Planks"
    },
    {
      "x": -4,
      "y": 6,
      "z": -1,
      "name": "Wood_Softwood_Planks"
    },
    {
      "x": -4,
      "y": 12,
      "z": -1,
      "name": "Cloth_Roof_White_Steep",
      "rotation": 1
    },
    {
      "x": -4,
      "y": 13,
      "z": -1,
      "name": "Cloth_Roof_White_Steep",
      "filler": 1024,
      "rotation": 1
    },
    {
      "x": -4,
      "y": 14,
      "z": -1,
      "name": "Cloth_Block_Wool_White"
    },
    {
      "x": -4,
      "y": 15,
      "z": -1,
      "name": "Cloth_Roof_White_Steep",
      "rotation": 3
    },
    {
      "x": -4,
      "y": 16,
      "z": -1,
      "name": "Cloth_Roof_White_Steep",
      "filler": 1024,
      "rotation": 3
    },
    {
      "x": -4,
      "y": 5,
      "z": 0,
      "name": "Wood_Softwood_Planks"
    },
    {
      "x": -4,
      "y": 6,
      "z": 0,
      "name": "Wood_Softwood_Planks"
    },
    {
      "x": -4,
      "y": 12,
      "z": 0,
      "name": "Cloth_Roof_White_Vertical",
      "rotation": 3
    },
    {
      "x": -4,
      "y": 13,
      "z": 0,
      "name": "Cloth_Roof_White",
      "rotation": 1
    },
    {
      "x": -4,
      "y": 14,
      "z": 0,
      "name": "Cloth_Block_Wool_White"
    },
    {
      "x": -4,
      "y": 15,
      "z": 0,
      "name": "Cloth_Roof_White",
      "rotation": 3
    },
    {
      "x": -4,
      "y": 16,
      "z": 0,
      "name": "Cloth_Roof_White_Vertical",
      "rotation": 3
    },
    {
      "x": -4,
      "y": 4,
      "z": 1,
      "name": "Wood_Softwood_Planks_Half",
      "rotation": 7
    },
    {
      "x": -4,
      "y": 5,
      "z": 1,
      "name": "Wood_Softwood_Planks"
    },
    {
      "x": -4,
      "y": 6,
      "z": 1,
      "name": "Wood_Softwood_Planks"
    },
    {
      "x": -4,
      "y": 12,
      "z": 1,
      "name": "Wood_Softwood_Stairs",
      "rotation": 9
    },
    {
      "x": -4,
      "y": 13,
      "z": 1,
      "name": "Wood_Softwood_Planks",
      "support": 15,
      "rotation": 2
    },
    {
      "x": -4,
      "y": 14,
      "z": 1,
      "name": "Wood_Softwood_Planks_Half",
      "rotation": 5
    },
    {
      "x": -4,
      "y": 15,
      "z": 1,
      "name": "Wood_Softwood_Planks",
      "support": 15,
      "rotation": 2
    },
    {
      "x": -4,
      "y": 16,
      "z": 1,
      "name": "Wood_Softwood_Stairs",
      "rotation": 3
    },
    {
      "x": -4,
      "y": 4,
      "z": 2,
      "name": "Wood_Softwood_Planks_Half",
      "rotation": 7
    },
    {
      "x": -4,
      "y": 5,
      "z": 2,
      "name": "Wood_Softwood_Planks"
    },
    {
      "x": -4,
      "y": 6,
      "z": 2,
      "name": "Wood_Softwood_Planks"
    },
    {
      "x": -4,
      "y": 7,
      "z": 2,
      "name": "Furniture_Tavern_Barrel"
    },
    {
      "x": -4,
      "y": 12,
      "z": 2,
      "name": "Cloth_Roof_White_Vertical",
      "rotation": 3
    },
    {
      "x": -4,
      "y": 13,
      "z": 2,
      "name": "Cloth_Roof_White",
      "rotation": 1
    },
    {
      "x": -4,
      "y": 14,
      "z": 2,
      "name": "Cloth_Block_Wool_White"
    },
    {
      "x": -4,
      "y": 15,
      "z": 2,
      "name": "Cloth_Roof_White",
      "rotation": 3
    },
    {
      "x": -4,
      "y": 16,
      "z": 2,
      "name": "Cloth_Roof_White_Vertical",
      "rotation": 3
    },
    {
      "x": -4,
      "y": 5,
      "z": 3,
      "name": "Wood_Softwood_Stairs",
      "rotation": 10
    },
    {
      "x": -4,
      "y": 6,
      "z": 3,
      "name": "Wood_Softwood_Planks"
    },
    {
      "x": -4,
      "y": 7,
      "z": 3,
      "name": "Wood_Softwood_Planks"
    },
    {
      "x": -4,
      "y": 8,
      "z": 3,
      "name": "Wood_Softwood_Planks"
    },
    {
      "x": -4,
      "y": 9,
      "z": 3,
      "name": "Wood_Softwood_Planks_Half"
    },
    {
      "x": -4,
      "y": 12,
      "z": 3,
      "name": "Cloth_Roof_White_Steep",
      "filler": 31744,
      "rotation": 9
    },
    {
      "x": -4,
      "y": 13,
      "z": 3,
      "name": "Cloth_Roof_White_Steep",
      "rotation": 9
    },
    {
      "x": -4,
      "y": 14,
      "z": 3,
      "name": "Cloth_Roof_White_Vertical",
      "rotation": 3
    },
    {
      "x": -4,
      "y": 15,
      "z": 3,
      "name": "Cloth_Roof_White_Steep",
      "rotation": 3
    },
    {
      "x": -4,
      "y": 16,
      "z": 3,
      "name": "Cloth_Roof_White_Steep",
      "filler": 1024,
      "rotation": 3
    },
    {
      "x": -4,
      "y": 6,
      "z": 4,
      "name": "Wood_Softwood_Planks"
    },
    {
      "x": -4,
      "y": 7,
      "z": 4,
      "name": "Wood_Softwood_Planks"
    },
    {
      "x": -4,
      "y": 8,
      "z": 4,
      "name": "Wood_Softwood_Planks"
    },
    {
      "x": -4,
      "y": 9,
      "z": 4,
      "name": "Wood_Softwood_Stairs",
      "rotation": 3
    },
    {
      "x": -4,
      "y": 12,
      "z": 4,
      "name": "Cloth_Roof_White_Vertical",
      "rotation": 3
    },
    {
      "x": -4,
      "y": 13,
      "z": 4,
      "name": "Cloth_Roof_White",
      "rotation": 1
    },
    {
      "x": -4,
      "y": 14,
      "z": 4,
      "name": "Cloth_Block_Wool_White"
    },
    {
      "x": -4,
      "y": 15,
      "z": 4,
      "name": "Cloth_Roof_White",
      "rotation": 3
    },
    {
      "x": -4,
      "y": 16,
      "z": 4,
      "name": "Cloth_Roof_White_Vertical",
      "rotation": 3
    },
    {
      "x": -4,
      "y": 6,
      "z": 5,
      "name": "Wood_Softwood_Planks_Half",
      "rotation": 7
    },
    {
      "x": -4,
      "y": 7,
      "z": 5,
      "name": "Wood_Softwood_Planks"
    },
    {
      "x": -4,
      "y": 8,
      "z": 5,
      "name": "Wood_Softwood_Planks"
    },
    {
      "x": -4,
      "y": 9,
      "z": 5,
      "name": "*Wood_Softwood_Stairs_State_Definitions_Inverted_Corner_Left",
      "rotation": 2
    },
    {
      "x": -4,
      "y": 12,
      "z": 5,
      "name": "Wood_Softwood_Stairs",
      "rotation": 9
    },
    {
      "x": -4,
      "y": 13,
      "z": 5,
      "name": "Wood_Softwood_Planks",
      "support": 15,
      "rotation": 2
    },
    {
      "x": -4,
      "y": 14,
      "z": 5,
      "name": "Wood_Softwood_Planks_Half",
      "rotation": 5
    },
    {
      "x": -4,
      "y": 15,
      "z": 5,
      "name": "Wood_Softwood_Planks",
      "support": 15,
      "rotation": 2
    },
    {
      "x": -4,
      "y": 16,
      "z": 5,
      "name": "Wood_Softwood_Stairs",
      "rotation": 3
    },
    {
      "x": -4,
      "y": 6,
      "z": 6,
      "name": "Wood_Softwood_Planks_Half",
      "rotation": 7
    },
    {
      "x": -4,
      "y": 7,
      "z": 6,
      "name": "Wood_Softwood_Planks"
    },
    {
      "x": -4,
      "y": 8,
      "z": 6,
      "name": "Wood_Softwood_Planks"
    },
    {
      "x": -4,
      "y": 9,
      "z": 6,
      "name": "Wood_Softwood_Planks"
    },
    {
      "x": -4,
      "y": 12,
      "z": 6,
      "name": "Cloth_Roof_White_Vertical",
      "rotation": 3
    },
    {
      "x": -4,
      "y": 13,
      "z": 6,
      "name": "Cloth_Roof_White",
      "rotation": 1
    },
    {
      "x": -4,
      "y": 15,
      "z": 6,
      "name": "Cloth_Roof_White",
      "rotation": 3
    },
    {
      "x": -4,
      "y": 16,
      "z": 6,
      "name": "Cloth_Roof_White_Vertical",
      "rotation": 3
    },
    {
      "x": -4,
      "y": 7,
      "z": 7,
      "name": "Wood_Softwood_Stairs",
      "rotation": 10
    },
    {
      "x": -4,
      "y": 8,
      "z": 7,
      "name": "Wood_Softwood_Planks"
    },
    {
      "x": -4,
      "y": 9,
      "z": 7,
      "name": "Wood_Softwood_Planks"
    },
    {
      "x": -4,
      "y": 12,
      "z": 7,
      "name": "Cloth_Roof_White_Steep",
      "rotation": 1
    },
    {
      "x": -4,
      "y": 13,
      "z": 7,
      "name": "Cloth_Roof_White_Steep",
      "filler": 1024,
      "rotation": 1
    },
    {
      "x": -4,
      "y": 15,
      "z": 7,
      "name": "Cloth_Roof_White_Steep",
      "rotation": 3
    },
    {
      "x": -4,
      "y": 16,
      "z": 7,
      "name": "Cloth_Roof_White_Steep",
      "filler": 1024,
      "rotation": 3
    },
    {
      "x": -4,
      "y": 7,
      "z": 8,
      "name": "Wood_Softwood_Planks_Half",
      "rotation": 8
    },
    {
      "x": -4,
      "y": 8,
      "z": 8,
      "name": "Wood_Softwood_Planks"
    },
    {
      "x": -4,
      "y": 9,
      "z": 8,
      "name": "Wood_Softwood_Planks"
    },
    {
      "x": -4,
      "y": 12,
      "z": 8,
      "name": "Cloth_Roof_White_Vertical",
      "rotation": 3
    },
    {
      "x": -4,
      "y": 13,
      "z": 8,
      "name": "Cloth_Roof_White",
      "rotation": 1
    },
    {
      "x": -4,
      "y": 14,
      "z": 8,
      "name": "Wood_Softwood_Planks_Half",
      "rotation": 5
    },
    {
      "x": -4,
      "y": 15,
      "z": 8,
      "name": "Cloth_Roof_White",
      "rotation": 3
    },
    {
      "x": -4,
      "y": 16,
      "z": 8,
      "name": "Cloth_Roof_White_Vertical",
      "rotation": 3
    },
    {
      "x": -4,
      "y": 8,
      "z": 9,
      "name": "Wood_Softwood_Stairs",
      "rotation": 9
    },
    {
      "x": -4,
      "y": 9,
      "z": 9,
      "name": "Wood_Softwood_Stairs",
      "rotation": 3
    },
    {
      "x": -4,
      "y": 12,
      "z": 9,
      "name": "Wood_Softwood_Stairs",
      "rotation": 9
    },
    {
      "x": -4,
      "y": 13,
      "z": 9,
      "name": "Wood_Softwood_Planks",
      "support": 15,
      "rotation": 7
    },
    {
      "x": -4,
      "y": 14,
      "z": 9,
      "name": "Wood_Softwood_Planks_Half",
      "rotation": 5
    },
    {
      "x": -4,
      "y": 15,
      "z": 9,
      "name": "Wood_Softwood_Planks",
      "support": 15,
      "rotation": 2
    },
    {
      "x": -4,
      "y": 16,
      "z": 9,
      "name": "Wood_Softwood_Stairs",
      "rotation": 3
    },
    {
      "x": -4,
      "y": 12,
      "z": 10,
      "name": "Cloth_Roof_White_Vertical",
      "rotation": 3
    },
    {
      "x": -4,
      "y": 13,
      "z": 10,
      "name": "Cloth_Roof_White",
      "rotation": 1
    },
    {
      "x": -4,
      "y": 15,
      "z": 10,
      "name": "Cloth_Roof_White",
      "rotation": 3
    },
    {
      "x": -4,
      "y": 16,
      "z": 10,
      "name": "Cloth_Roof_White_Vertical",
      "rotation": 3
    },
    {
      "x": -4,
      "y": 12,
      "z": 11,
      "name": "Cloth_Roof_White_Steep",
      "rotation": 1
    },
    {
      "x": -4,
      "y": 13,
      "z": 11,
      "name": "Cloth_Roof_White_Steep",
      "filler": 1024,
      "rotation": 1
    },
    {
      "x": -4,
      "y": 14,
      "z": 11,
      "name": "Cloth_Block_Wool_White"
    },
    {
      "x": -4,
      "y": 15,
      "z": 11,
      "name": "Cloth_Roof_White_Steep",
      "rotation": 3
    },
    {
      "x": -4,
      "y": 16,
      "z": 11,
      "name": "Cloth_Roof_White_Steep",
      "filler": 1024,
      "rotation": 3
    },
    {
      "x": -4,
      "y": 12,
      "z": 12,
      "name": "Cloth_Roof_White_Steep",
      "rotation": 1
    },
    {
      "x": -4,
      "y": 13,
      "z": 12,
      "name": "Cloth_Roof_White_Steep",
      "filler": 1024,
      "rotation": 1
    },
    {
      "x": -4,
      "y": 15,
      "z": 12,
      "name": "Cloth_Roof_White_Steep",
      "rotation": 3
    },
    {
      "x": -4,
      "y": 16,
      "z": 12,
      "name": "Cloth_Roof_White_Steep",
      "filler": 1024,
      "rotation": 3
    },
    {
      "x": -4,
      "y": 12,
      "z": 13,
      "name": "Cloth_Roof_White_Steep",
      "rotation": 1
    },
    {
      "x": -4,
      "y": 13,
      "z": 13,
      "name": "Cloth_Roof_White_Steep",
      "filler": 1024,
      "rotation": 1
    },
    {
      "x": -4,
      "y": 14,
      "z": 13,
      "name": "Cloth_Block_Wool_White"
    },
    {
      "x": -4,
      "y": 15,
      "z": 13,
      "name": "Cloth_Roof_White_Steep",
      "rotation": 3
    },
    {
      "x": -4,
      "y": 16,
      "z": 13,
      "name": "Cloth_Roof_White_Steep",
      "filler": 1024,
      "rotation": 3
    },
    {
      "x": -4,
      "y": 12,
      "z": 14,
      "name": "*Cloth_Roof_White_Steep_State_Definitions_Inverted_Corner_Right",
      "rotation": 2
    },
    {
      "x": -4,
      "y": 13,
      "z": 14,
      "name": "*Cloth_Roof_White_Steep_State_Definitions_Inverted_Corner_Right",
      "filler": 1024,
      "rotation": 2
    },
    {
      "x": -4,
      "y": 14,
      "z": 14,
      "name": "Cloth_Block_Wool_White"
    },
    {
      "x": -4,
      "y": 15,
      "z": 14,
      "name": "*Cloth_Roof_White_Steep_State_Definitions_Corner_Right"
    },
    {
      "x": -4,
      "y": 16,
      "z": 14,
      "name": "*Cloth_Roof_White_Steep_State_Definitions_Corner_Right",
      "filler": 1024
    },
    {
      "x": -4,
      "y": 14,
      "z": 15,
      "name": "Cloth_Roof_White_Vertical"
    },
    {
      "x": -3,
      "y": 14,
      "z": -9,
      "name": "Cloth_Roof_White_Vertical",
      "rotation": 2
    },
    {
      "x": -3,
      "y": 12,
      "z": -8,
      "name": "Cloth_Roof_White_Steep",
      "filler": 31744,
      "rotation": 8
    },
    {
      "x": -3,
      "y": 13,
      "z": -8,
      "name": "Cloth_Roof_White_Steep",
      "rotation": 8
    },
    {
      "x": -3,
      "y": 14,
      "z": -8,
      "name": "Cloth_Block_Wool_White"
    },
    {
      "x": -3,
      "y": 15,
      "z": -8,
      "name": "Cloth_Roof_White_Steep",
      "rotation": 2
    },
    {
      "x": -3,
      "y": 16,
      "z": -8,
      "name": "Cloth_Roof_White_Steep",
      "filler": 1024,
      "rotation": 2
    },
    {
      "x": -3,
      "y": 6,
      "z": -7,
      "name": "Wood_Softwood_Planks_Half",
      "rotation": 7
    },
    {
      "x": -3,
      "y": 7,
      "z": -7,
      "name": "Wood_Softwood_Stairs",
      "rotation": 9
    },
    {
      "x": -3,
      "y": 8,
      "z": -7,
      "name": "Wood_Softwood_Planks_Half"
    },
    {
      "x": -3,
      "y": 11,
      "z": -7,
      "name": "*Cloth_Roof_White_State_Definitions_Inverted_Corner_Right",
      "rotation": 1
    },
    {
      "x": -3,
      "y": 12,
      "z": -7,
      "name": "Cloth_Block_Wool_White"
    },
    {
      "x": -3,
      "y": 13,
      "z": -7,
      "name": "Cloth_Block_Wool_White"
    },
    {
      "x": -3,
      "y": 14,
      "z": -7,
      "name": "Cloth_Block_Wool_White"
    },
    {
      "x": -3,
      "y": 15,
      "z": -7,
      "name": "Cloth_Block_Wool_White"
    },
    {
      "x": -3,
      "y": 16,
      "z": -7,
      "name": "Cloth_Block_Wool_White"
    },
    {
      "x": -3,
      "y": 17,
      "z": -7,
      "name": "*Cloth_Roof_White_State_Definitions_Corner_Right",
      "rotation": 3
    },
    {
      "x": -3,
      "y": 4,
      "z": -6,
      "name": "*Wood_Softwood_Stairs_State_Definitions_Corner_Right",
      "rotation": 8
    },
    {
      "x": -3,
      "y": 5,
      "z": -6,
      "name": "Wood_Softwood_Planks_Half",
      "rotation": 7
    },
    {
      "x": -3,
      "y": 6,
      "z": -6,
      "name": "Wood_Softwood_Stairs",
      "rotation": 9
    },
    {
      "x": -3,
      "y": 7,
      "z": -6,
      "name": "Wood_Softwood_Planks"
    },
    {
      "x": -3,
      "y": 8,
      "z": -6,
      "name": "Wood_Softwood_Planks_Half"
    },
    {
      "x": -3,
      "y": 11,
      "z": -6,
      "name": "Cloth_Roof_White",
      "rotation": 1
    },
    {
      "x": -3,
      "y": 12,
      "z": -6,
      "name": "Cloth_Block_Wool_White"
    },
    {
      "x": -3,
      "y": 13,
      "z": -6,
      "name": "Cloth_Block_Wool_White"
    },
    {
      "x": -3,
      "y": 14,
      "z": -6,
      "name": "Cloth_Block_Wool_White"
    },
    {
      "x": -3,
      "y": 15,
      "z": -6,
      "name": "Cloth_Block_Wool_White"
    },
    {
      "x": -3,
      "y": 16,
      "z": -6,
      "name": "Cloth_Block_Wool_White"
    },
    {
      "x": -3,
      "y": 17,
      "z": -6,
      "name": "Cloth_Roof_White",
      "rotation": 3
    },
    {
      "x": -3,
      "y": 4,
      "z": -5,
      "name": "Wood_Softwood_Stairs",
      "rotation": 9
    },
    {
      "x": -3,
      "y": 5,
      "z": -5,
      "name": "Furniture_Crude_Window",
      "rotation": 1
    },
    {
      "x": -3,
      "y": 6,
      "z": -5,
      "name": "Wood_Softwood_Stairs",
      "rotation": 9
    },
    {
      "x": -3,
      "y": 7,
      "z": -5,
      "name": "Wood_Softwood_Fence",
      "rotation": 3
    },
    {
      "x": -3,
      "y": 11,
      "z": -5,
      "name": "Cloth_Roof_White",
      "rotation": 1
    },
    {
      "x": -3,
      "y": 12,
      "z": -5,
      "name": "Cloth_Block_Wool_White"
    },
    {
      "x": -3,
      "y": 13,
      "z": -5,
      "name": "Cloth_Block_Wool_White"
    },
    {
      "x": -3,
      "y": 14,
      "z": -5,
      "name": "Cloth_Block_Wool_White"
    },
    {
      "x": -3,
      "y": 15,
      "z": -5,
      "name": "Cloth_Block_Wool_White"
    },
    {
      "x": -3,
      "y": 16,
      "z": -5,
      "name": "Cloth_Block_Wool_White"
    },
    {
      "x": -3,
      "y": 17,
      "z": -5,
      "name": "Cloth_Roof_White",
      "rotation": 3
    },
    {
      "x": -3,
      "y": 4,
      "z": -4,
      "name": "Wood_Softwood_Stairs",
      "rotation": 9
    },
    {
      "x": -3,
      "y": 5,
      "z": -4,
      "name": "Furniture_Crude_Window",
      "rotation": 1
    },
    {
      "x": -3,
      "y": 6,
      "z": -4,
      "name": "Wood_Softwood_Planks"
    },
    {
      "x": -3,
      "y": 7,
      "z": -4,
      "name": "*Wood_Softwood_Fence_State_Definitions_Corner",
      "rotation": 3
    },
    {
      "x": -3,
      "y": 11,
      "z": -4,
      "name": "Cloth_Roof_White",
      "rotation": 1
    },
    {
      "x": -3,
      "y": 12,
      "z": -4,
      "name": "Cloth_Block_Wool_White"
    },
    {
      "x": -3,
      "y": 13,
      "z": -4,
      "name": "Cloth_Block_Wool_White"
    },
    {
      "x": -3,
      "y": 14,
      "z": -4,
      "name": "Cloth_Block_Wool_White"
    },
    {
      "x": -3,
      "y": 15,
      "z": -4,
      "name": "Cloth_Block_Wool_White"
    },
    {
      "x": -3,
      "y": 16,
      "z": -4,
      "name": "Cloth_Block_Wool_White"
    },
    {
      "x": -3,
      "y": 17,
      "z": -4,
      "name": "Cloth_Roof_White",
      "rotation": 3
    },
    {
      "x": -3,
      "y": 4,
      "z": -3,
      "name": "*Wood_Softwood_Stairs_State_Definitions_Inverted_Corner_Right",
      "rotation": 8
    },
    {
      "x": -3,
      "y": 5,
      "z": -3,
      "name": "Wood_Softwood_Planks"
    },
    {
      "x": -3,
      "y": 6,
      "z": -3,
      "name": "Wood_Softwood_Planks"
    },
    {
      "x": -3,
      "y": 11,
      "z": -3,
      "name": "Wood_Softwood_Stairs",
      "rotation": 9
    },
    {
      "x": -3,
      "y": 12,
      "z": -3,
      "name": "Cloth_Block_Wool_White"
    },
    {
      "x": -3,
      "y": 13,
      "z": -3,
      "name": "Cloth_Block_Wool_White"
    },
    {
      "x": -3,
      "y": 14,
      "z": -3,
      "name": "Cloth_Block_Wool_White"
    },
    {
      "x": -3,
      "y": 15,
      "z": -3,
      "name": "Cloth_Block_Wool_White"
    },
    {
      "x": -3,
      "y": 16,
      "z": -3,
      "name": "Cloth_Block_Wool_White"
    },
    {
      "x": -3,
      "y": 17,
      "z": -3,
      "name": "Wood_Softwood_Stairs",
      "rotation": 3
    },
    {
      "x": -3,
      "y": 4,
      "z": -2,
      "name": "Wood_Softwood_Planks"
    },
    {
      "x": -3,
      "y": 5,
      "z": -2,
      "name": "Wood_Softwood_Planks"
    },
    {
      "x": -3,
      "y": 6,
      "z": -2,
      "name": "Wood_Softwood_Planks"
    },
    {
      "x": -3,
      "y": 11,
      "z": -2,
      "name": "Cloth_Roof_White",
      "rotation": 1
    },
    {
      "x": -3,
      "y": 12,
      "z": -2,
      "name": "Cloth_Block_Wool_White"
    },
    {
      "x": -3,
      "y": 13,
      "z": -2,
      "name": "Cloth_Block_Wool_White"
    },
    {
      "x": -3,
      "y": 14,
      "z": -2,
      "name": "Cloth_Block_Wool_White"
    },
    {
      "x": -3,
      "y": 15,
      "z": -2,
      "name": "Cloth_Block_Wool_White"
    },
    {
      "x": -3,
      "y": 16,
      "z": -2,
      "name": "Cloth_Block_Wool_White"
    },
    {
      "x": -3,
      "y": 17,
      "z": -2,
      "name": "Cloth_Roof_White",
      "rotation": 3
    },
    {
      "x": -3,
      "y": 4,
      "z": -1,
      "name": "Wood_Softwood_Planks"
    },
    {
      "x": -3,
      "y": 5,
      "z": -1,
      "name": "Wood_Softwood_Planks"
    },
    {
      "x": -3,
      "y": 6,
      "z": -1,
      "name": "Wood_Softwood_Planks"
    },
    {
      "x": -3,
      "y": 11,
      "z": -1,
      "name": "Cloth_Roof_White",
      "rotation": 1
    },
    {
      "x": -3,
      "y": 12,
      "z": -1,
      "name": "Cloth_Block_Wool_White"
    },
    {
      "x": -3,
      "y": 13,
      "z": -1,
      "name": "Cloth_Block_Wool_White"
    },
    {
      "x": -3,
      "y": 14,
      "z": -1,
      "name": "Cloth_Block_Wool_White"
    },
    {
      "x": -3,
      "y": 15,
      "z": -1,
      "name": "Cloth_Block_Wool_White"
    },
    {
      "x": -3,
      "y": 16,
      "z": -1,
      "name": "Cloth_Block_Wool_White"
    },
    {
      "x": -3,
      "y": 17,
      "z": -1,
      "name": "Cloth_Roof_White",
      "rotation": 3
    },
    {
      "x": -3,
      "y": 4,
      "z": 0,
      "name": "Wood_Softwood_Planks"
    },
    {
      "x": -3,
      "y": 5,
      "z": 0,
      "name": "Wood_Softwood_Planks"
    },
    {
      "x": -3,
      "y": 6,
      "z": 0,
      "name": "Wood_Softwood_Planks"
    },
    {
      "x": -3,
      "y": 11,
      "z": 0,
      "name": "Cloth_Roof_White",
      "rotation": 1
    },
    {
      "x": -3,
      "y": 12,
      "z": 0,
      "name": "Cloth_Block_Wool_White"
    },
    {
      "x": -3,
      "y": 13,
      "z": 0,
      "name": "Cloth_Block_Wool_White"
    },
    {
      "x": -3,
      "y": 14,
      "z": 0,
      "name": "Cloth_Block_Wool_White"
    },
    {
      "x": -3,
      "y": 15,
      "z": 0,
      "name": "Cloth_Block_Wool_White"
    },
    {
      "x": -3,
      "y": 16,
      "z": 0,
      "name": "Cloth_Block_Wool_White"
    },
    {
      "x": -3,
      "y": 17,
      "z": 0,
      "name": "Cloth_Roof_White",
      "rotation": 3
    },
    {
      "x": -3,
      "y": 4,
      "z": 1,
      "name": "Wood_Softwood_Planks"
    },
    {
      "x": -3,
      "y": 5,
      "z": 1,
      "name": "Wood_Softwood_Planks"
    },
    {
      "x": -3,
      "y": 6,
      "z": 1,
      "name": "Wood_Softwood_Planks"
    },
    {
      "x": -3,
      "y": 11,
      "z": 1,
      "name": "Wood_Softwood_Stairs",
      "rotation": 9
    },
    {
      "x": -3,
      "y": 12,
      "z": 1,
      "name": "Cloth_Block_Wool_White"
    },
    {
      "x": -3,
      "y": 13,
      "z": 1,
      "name": "Cloth_Block_Wool_White"
    },
    {
      "x": -3,
      "y": 14,
      "z": 1,
      "name": "Cloth_Block_Wool_White"
    },
    {
      "x": -3,
      "y": 15,
      "z": 1,
      "name": "Cloth_Block_Wool_White"
    },
    {
      "x": -3,
      "y": 16,
      "z": 1,
      "name": "Cloth_Block_Wool_White"
    },
    {
      "x": -3,
      "y": 17,
      "z": 1,
      "name": "Wood_Softwood_Stairs",
      "rotation": 3
    },
    {
      "x": -3,
      "y": 4,
      "z": 2,
      "name": "Wood_Softwood_Planks"
    },
    {
      "x": -3,
      "y": 5,
      "z": 2,
      "name": "Wood_Softwood_Planks"
    },
    {
      "x": -3,
      "y": 6,
      "z": 2,
      "name": "Wood_Softwood_Planks"
    },
    {
      "x": -3,
      "y": 7,
      "z": 2,
      "name": "Wood_Softwood_Planks_Half",
      "rotation": 6
    },
    {
      "x": -3,
      "y": 8,
      "z": 2,
      "name": "Wood_Softwood_Planks_Half",
      "rotation": 6
    },
    {
      "x": -3,
      "y": 9,
      "z": 2,
      "name": "Wood_Softwood_Planks_Half",
      "rotation": 6
    },
    {
      "x": -3,
      "y": 11,
      "z": 2,
      "name": "Cloth_Roof_White",
      "rotation": 1
    },
    {
      "x": -3,
      "y": 12,
      "z": 2,
      "name": "Cloth_Block_Wool_White"
    },
    {
      "x": -3,
      "y": 13,
      "z": 2,
      "name": "Cloth_Block_Wool_White"
    },
    {
      "x": -3,
      "y": 14,
      "z": 2,
      "name": "Cloth_Block_Wool_White"
    },
    {
      "x": -3,
      "y": 15,
      "z": 2,
      "name": "Cloth_Block_Wool_White"
    },
    {
      "x": -3,
      "y": 16,
      "z": 2,
      "name": "Cloth_Block_Wool_White"
    },
    {
      "x": -3,
      "y": 17,
      "z": 2,
      "name": "Cloth_Roof_White",
      "rotation": 3
    },
    {
      "x": -3,
      "y": 4,
      "z": 3,
      "name": "Wood_Softwood_Planks"
    },
    {
      "x": -3,
      "y": 5,
      "z": 3,
      "name": "Wood_Softwood_Planks"
    },
    {
      "x": -3,
      "y": 6,
      "z": 3,
      "name": "Wood_Softwood_Planks"
    },
    {
      "x": -3,
      "y": 7,
      "z": 3,
      "name": "Wood_Softwood_Planks"
    },
    {
      "x": -3,
      "y": 8,
      "z": 3,
      "name": "Wood_Softwood_Planks_Half",
      "rotation": 5
    },
    {
      "x": -3,
      "y": 9,
      "z": 3,
      "name": "Wood_Softwood_Planks_Half",
      "rotation": 5
    },
    {
      "x": -3,
      "y": 10,
      "z": 3,
      "name": "Wood_Softwood_Stairs",
      "rotation": 3
    },
    {
      "x": -3,
      "y": 11,
      "z": 3,
      "name": "Cloth_Roof_White",
      "rotation": 1
    },
    {
      "x": -3,
      "y": 12,
      "z": 3,
      "name": "Cloth_Block_Wool_White"
    },
    {
      "x": -3,
      "y": 13,
      "z": 3,
      "name": "Cloth_Block_Wool_White"
    },
    {
      "x": -3,
      "y": 14,
      "z": 3,
      "name": "Cloth_Block_Wool_White"
    },
    {
      "x": -3,
      "y": 15,
      "z": 3,
      "name": "Cloth_Block_Wool_White"
    },
    {
      "x": -3,
      "y": 16,
      "z": 3,
      "name": "Cloth_Block_Wool_White"
    },
    {
      "x": -3,
      "y": 17,
      "z": 3,
      "name": "Cloth_Roof_White",
      "rotation": 3
    },
    {
      "x": -3,
      "y": 4,
      "z": 4,
      "name": "Wood_Softwood_Stairs",
      "rotation": 9
    },
    {
      "x": -3,
      "y": 5,
      "z": 4,
      "name": "Wood_Softwood_Planks"
    },
    {
      "x": -3,
      "y": 6,
      "z": 4,
      "name": "Wood_Softwood_Planks"
    },
    {
      "x": -3,
      "y": 7,
      "z": 4,
      "name": "Wood_Softwood_Planks"
    },
    {
      "x": -3,
      "y": 8,
      "z": 4,
      "name": "Furniture_Temple_Wind_Pot"
    },
    {
      "x": -3,
      "y": 9,
      "z": 4,
      "name": "Furniture_Temple_Wind_Pot",
      "filler": 1024
    },
    {
      "x": -3,
      "y": 10,
      "z": 4,
      "name": "Wood_Softwood_Stairs",
      "rotation": 3
    },
    {
      "x": -3,
      "y": 11,
      "z": 4,
      "name": "Cloth_Roof_White",
      "rotation": 1
    },
    {
      "x": -3,
      "y": 12,
      "z": 4,
      "name": "Cloth_Block_Wool_White"
    },
    {
      "x": -3,
      "y": 13,
      "z": 4,
      "name": "Cloth_Block_Wool_White"
    },
    {
      "x": -3,
      "y": 14,
      "z": 4,
      "name": "Cloth_Block_Wool_White"
    },
    {
      "x": -3,
      "y": 15,
      "z": 4,
      "name": "Cloth_Block_Wool_White"
    },
    {
      "x": -3,
      "y": 16,
      "z": 4,
      "name": "Cloth_Block_Wool_White"
    },
    {
      "x": -3,
      "y": 17,
      "z": 4,
      "name": "Cloth_Roof_White",
      "rotation": 3
    },
    {
      "x": -3,
      "y": 4,
      "z": 5,
      "name": "Wood_Softwood_Stairs",
      "rotation": 9
    },
    {
      "x": -3,
      "y": 5,
      "z": 5,
      "name": "Wood_Softwood_Planks"
    },
    {
      "x": -3,
      "y": 6,
      "z": 5,
      "name": "Wood_Softwood_Planks"
    },
    {
      "x": -3,
      "y": 7,
      "z": 5,
      "name": "Wood_Softwood_Planks"
    },
    {
      "x": -3,
      "y": 8,
      "z": 5,
      "name": "Furniture_Tavern_Shelf",
      "rotation": 1
    },
    {
      "x": -3,
      "y": 9,
      "z": 5,
      "name": "Deco_Coral_Shell_Purple"
    },
    {
      "x": -3,
      "y": 10,
      "z": 5,
      "name": "Wood_Softwood_Stairs",
      "rotation": 3
    },
    {
      "x": -3,
      "y": 11,
      "z": 5,
      "name": "Wood_Softwood_Stairs",
      "rotation": 9
    },
    {
      "x": -3,
      "y": 12,
      "z": 5,
      "name": "Cloth_Block_Wool_White"
    },
    {
      "x": -3,
      "y": 13,
      "z": 5,
      "name": "Cloth_Block_Wool_White"
    },
    {
      "x": -3,
      "y": 14,
      "z": 5,
      "name": "Cloth_Block_Wool_White"
    },
    {
      "x": -3,
      "y": 15,
      "z": 5,
      "name": "Cloth_Block_Wool_White"
    },
    {
      "x": -3,
      "y": 16,
      "z": 5,
      "name": "Cloth_Block_Wool_White"
    },
    {
      "x": -3,
      "y": 17,
      "z": 5,
      "name": "Wood_Softwood_Stairs",
      "rotation": 3
    },
    {
      "x": -3,
      "y": 4,
      "z": 6,
      "name": "Wood_Softwood_Stairs",
      "rotation": 9
    },
    {
      "x": -3,
      "y": 5,
      "z": 6,
      "name": "Wood_Softwood_Planks"
    },
    {
      "x": -3,
      "y": 6,
      "z": 6,
      "name": "Wood_Softwood_Planks"
    },
    {
      "x": -3,
      "y": 7,
      "z": 6,
      "name": "Wood_Softwood_Planks"
    },
    {
      "x": -3,
      "y": 8,
      "z": 6,
      "name": "Furniture_Tavern_Shelf",
      "rotation": 1
    },
    {
      "x": -3,
      "y": 9,
      "z": 6,
      "name": "Deco_Coral_Shell_Swirly"
    },
    {
      "x": -3,
      "y": 10,
      "z": 6,
      "name": "Wood_Softwood_Stairs",
      "rotation": 3
    },
    {
      "x": -3,
      "y": 11,
      "z": 6,
      "name": "Cloth_Roof_White",
      "rotation": 1
    },
    {
      "x": -3,
      "y": 12,
      "z": 6,
      "name": "Cloth_Block_Wool_White"
    },
    {
      "x": -3,
      "y": 13,
      "z": 6,
      "name": "Cloth_Block_Wool_White"
    },
    {
      "x": -3,
      "y": 14,
      "z": 6,
      "name": "Cloth_Block_Wool_White"
    },
    {
      "x": -3,
      "y": 15,
      "z": 6,
      "name": "Cloth_Block_Wool_White"
    },
    {
      "x": -3,
      "y": 16,
      "z": 6,
      "name": "Cloth_Block_Wool_White"
    },
    {
      "x": -3,
      "y": 17,
      "z": 6,
      "name": "Cloth_Roof_White",
      "rotation": 3
    },
    {
      "x": -3,
      "y": 5,
      "z": 7,
      "name": "Wood_Softwood_Planks_Half",
      "rotation": 7
    },
    {
      "x": -3,
      "y": 6,
      "z": 7,
      "name": "Wood_Softwood_Planks"
    },
    {
      "x": -3,
      "y": 7,
      "z": 7,
      "name": "Wood_Softwood_Planks"
    },
    {
      "x": -3,
      "y": 8,
      "z": 7,
      "name": "Furniture_Tavern_Shelf",
      "rotation": 1
    },
    {
      "x": -3,
      "y": 9,
      "z": 7,
      "name": "Deco_Scroll",
      "rotation": 1
    },
    {
      "x": -3,
      "y": 10,
      "z": 7,
      "name": "Wood_Softwood_Stairs",
      "rotation": 3
    },
    {
      "x": -3,
      "y": 11,
      "z": 7,
      "name": "Cloth_Roof_White",
      "rotation": 1
    },
    {
      "x": -3,
      "y": 12,
      "z": 7,
      "name": "Cloth_Block_Wool_White"
    },
    {
      "x": -3,
      "y": 13,
      "z": 7,
      "name": "Cloth_Block_Wool_White"
    },
    {
      "x": -3,
      "y": 14,
      "z": 7,
      "name": "Cloth_Block_Wool_White"
    },
    {
      "x": -3,
      "y": 15,
      "z": 7,
      "name": "Cloth_Block_Wool_White"
    },
    {
      "x": -3,
      "y": 16,
      "z": 7,
      "name": "Cloth_Block_Wool_White"
    },
    {
      "x": -3,
      "y": 17,
      "z": 7,
      "name": "Cloth_Roof_White",
      "rotation": 3
    },
    {
      "x": -3,
      "y": 6,
      "z": 8,
      "name": "Wood_Softwood_Planks_Half",
      "rotation": 7
    },
    {
      "x": -3,
      "y": 7,
      "z": 8,
      "name": "Wood_Softwood_Planks"
    },
    {
      "x": -3,
      "y": 8,
      "z": 8,
      "name": "Furniture_Tavern_Shelf",
      "rotation": 1
    },
    {
      "x": -3,
      "y": 9,
      "z": 8,
      "name": "Deco_Mug"
    },
    {
      "x": -3,
      "y": 10,
      "z": 8,
      "name": "Wood_Softwood_Stairs",
      "rotation": 3
    },
    {
      "x": -3,
      "y": 11,
      "z": 8,
      "name": "Cloth_Roof_White",
      "rotation": 1
    },
    {
      "x": -3,
      "y": 12,
      "z": 8,
      "name": "Cloth_Block_Wool_White"
    },
    {
      "x": -3,
      "y": 13,
      "z": 8,
      "name": "Cloth_Block_Wool_White"
    },
    {
      "x": -3,
      "y": 14,
      "z": 8,
      "name": "Cloth_Block_Wool_White"
    },
    {
      "x": -3,
      "y": 15,
      "z": 8,
      "name": "Cloth_Block_Wool_White"
    },
    {
      "x": -3,
      "y": 16,
      "z": 8,
      "name": "Cloth_Block_Wool_White"
    },
    {
      "x": -3,
      "y": 17,
      "z": 8,
      "name": "Cloth_Roof_White",
      "rotation": 3
    },
    {
      "x": -3,
      "y": 7,
      "z": 9,
      "name": "Wood_Softwood_Stairs",
      "rotation": 9
    },
    {
      "x": -3,
      "y": 8,
      "z": 9,
      "name": "Furniture_Tavern_Shelf",
      "rotation": 1
    },
    {
      "x": -3,
      "y": 9,
      "z": 9,
      "name": "Furniture_Ancient_Sack",
      "rotation": 1
    },
    {
      "x": -3,
      "y": 10,
      "z": 9,
      "name": "Wood_Softwood_Stairs",
      "rotation": 3
    },
    {
      "x": -3,
      "y": 11,
      "z": 9,
      "name": "Wood_Softwood_Stairs",
      "rotation": 9
    },
    {
      "x": -3,
      "y": 12,
      "z": 9,
      "name": "Cloth_Block_Wool_White"
    },
    {
      "x": -3,
      "y": 13,
      "z": 9,
      "name": "Cloth_Block_Wool_White"
    },
    {
      "x": -3,
      "y": 14,
      "z": 9,
      "name": "Cloth_Block_Wool_White"
    },
    {
      "x": -3,
      "y": 15,
      "z": 9,
      "name": "Cloth_Block_Wool_White"
    },
    {
      "x": -3,
      "y": 16,
      "z": 9,
      "name": "Cloth_Block_Wool_White"
    },
    {
      "x": -3,
      "y": 17,
      "z": 9,
      "name": "Wood_Softwood_Stairs",
      "rotation": 3
    },
    {
      "x": -3,
      "y": 8,
      "z": 10,
      "name": "Wood_Softwood_Planks_Half",
      "rotation": 4
    },
    {
      "x": -3,
      "y": 9,
      "z": 10,
      "name": "Wood_Softwood_Planks_Half",
      "rotation": 4
    },
    {
      "x": -3,
      "y": 11,
      "z": 10,
      "name": "Cloth_Roof_White",
      "rotation": 1
    },
    {
      "x": -3,
      "y": 12,
      "z": 10,
      "name": "Cloth_Block_Wool_White"
    },
    {
      "x": -3,
      "y": 13,
      "z": 10,
      "name": "Cloth_Block_Wool_White"
    },
    {
      "x": -3,
      "y": 14,
      "z": 10,
      "name": "Cloth_Block_Wool_White"
    },
    {
      "x": -3,
      "y": 15,
      "z": 10,
      "name": "Cloth_Block_Wool_White"
    },
    {
      "x": -3,
      "y": 16,
      "z": 10,
      "name": "Cloth_Block_Wool_White"
    },
    {
      "x": -3,
      "y": 17,
      "z": 10,
      "name": "Cloth_Roof_White",
      "rotation": 3
    },
    {
      "x": -3,
      "y": 11,
      "z": 11,
      "name": "Cloth_Roof_White",
      "rotation": 1
    },
    {
      "x": -3,
      "y": 12,
      "z": 11,
      "name": "Cloth_Block_Wool_White"
    },
    {
      "x": -3,
      "y": 13,
      "z": 11,
      "name": "Cloth_Block_Wool_White"
    },
    {
      "x": -3,
      "y": 14,
      "z": 11,
      "name": "Cloth_Block_Wool_White"
    },
    {
      "x": -3,
      "y": 15,
      "z": 11,
      "name": "Cloth_Block_Wool_White"
    },
    {
      "x": -3,
      "y": 16,
      "z": 11,
      "name": "Cloth_Block_Wool_White"
    },
    {
      "x": -3,
      "y": 17,
      "z": 11,
      "name": "Cloth_Roof_White",
      "rotation": 3
    },
    {
      "x": -3,
      "y": 11,
      "z": 12,
      "name": "Cloth_Roof_White",
      "rotation": 1
    },
    {
      "x": -3,
      "y": 12,
      "z": 12,
      "name": "Cloth_Block_Wool_White"
    },
    {
      "x": -3,
      "y": 13,
      "z": 12,
      "name": "Cloth_Block_Wool_White"
    },
    {
      "x": -3,
      "y": 14,
      "z": 12,
      "name": "Cloth_Block_Wool_White"
    },
    {
      "x": -3,
      "y": 15,
      "z": 12,
      "name": "Cloth_Block_Wool_White"
    },
    {
      "x": -3,
      "y": 16,
      "z": 12,
      "name": "Cloth_Block_Wool_White"
    },
    {
      "x": -3,
      "y": 17,
      "z": 12,
      "name": "Cloth_Roof_White",
      "rotation": 3
    },
    {
      "x": -3,
      "y": 11,
      "z": 13,
      "name": "*Cloth_Roof_White_State_Definitions_Inverted_Corner_Left",
      "rotation": 1
    },
    {
      "x": -3,
      "y": 12,
      "z": 13,
      "name": "Cloth_Block_Wool_White"
    },
    {
      "x": -3,
      "y": 13,
      "z": 13,
      "name": "Cloth_Block_Wool_White"
    },
    {
      "x": -3,
      "y": 14,
      "z": 13,
      "name": "Cloth_Block_Wool_White"
    },
    {
      "x": -3,
      "y": 15,
      "z": 13,
      "name": "Cloth_Block_Wool_White"
    },
    {
      "x": -3,
      "y": 16,
      "z": 13,
      "name": "Cloth_Block_Wool_White"
    },
    {
      "x": -3,
      "y": 17,
      "z": 13,
      "name": "*Cloth_Roof_White_State_Definitions_Corner_Left",
      "rotation": 3
    },
    {
      "x": -3,
      "y": 12,
      "z": 14,
      "name": "Cloth_Roof_White_Steep",
      "rotation": 2
    },
    {
      "x": -3,
      "y": 13,
      "z": 14,
      "name": "Cloth_Roof_White_Steep",
      "filler": 1024,
      "rotation": 2
    },
    {
      "x": -3,
      "y": 14,
      "z": 14,
      "name": "Cloth_Roof_White_Flap"
    },
    {
      "x": -3,
      "y": 15,
      "z": 14,
      "name": "Cloth_Roof_White_Steep"
    },
    {
      "x": -3,
      "y": 16,
      "z": 14,
      "name": "Cloth_Roof_White_Steep",
      "filler": 1024
    },
    {
      "x": -3,
      "y": 14,
      "z": 15,
      "name": "Cloth_Roof_White_Vertical"
    },
    {
      "x": -2,
      "y": 6,
      "z": -10,
      "name": "Wood_Softwood_Planks_Half",
      "rotation": 7
    },
    {
      "x": -2,
      "y": 7,
      "z": -10,
      "name": "Wood_Softwood_Stairs",
      "rotation": 3
    },
    {
      "x": -2,
      "y": 8,
      "z": -10,
      "name": "Wood_Softwood_Planks_Half",
      "rotation": 7
    },
    {
      "x": -2,
      "y": 5,
      "z": -9,
      "name": "Wood_Softwood_Planks_Half",
      "rotation": 7
    },
    {
      "x": -2,
      "y": 6,
      "z": -9,
      "name": "Wood_Softwood_Fence",
      "rotation": 3
    },
    {
      "x": -2,
      "y": 7,
      "z": -9,
      "name": "Wood_Softwood_Planks"
    },
    {
      "x": -2,
      "y": 8,
      "z": -9,
      "name": "Wood_Softwood_Stairs",
      "rotation": 3
    },
    {
      "x": -2,
      "y": 14,
      "z": -9,
      "name": "Cloth_Roof_White_Vertical",
      "rotation": 2
    },
    {
      "x": -2,
      "y": 5,
      "z": -8,
      "name": "Wood_Softwood_Planks_Half",
      "rotation": 6
    },
    {
      "x": -2,
      "y": 6,
      "z": -8,
      "name": "Wood_Softwood_Planks"
    },
    {
      "x": -2,
      "y": 7,
      "z": -8,
      "name": "Wood_Softwood_Planks"
    },
    {
      "x": -2,
      "y": 8,
      "z": -8,
      "name": "*Wood_Softwood_Stairs_State_Definitions_Corner_Right"
    },
    {
      "x": -2,
      "y": 12,
      "z": -8,
      "name": "Cloth_Roof_White_Steep"
    },
    {
      "x": -2,
      "y": 13,
      "z": -8,
      "name": "Cloth_Roof_White_Steep",
      "filler": 1024
    },
    {
      "x": -2,
      "y": 14,
      "z": -8,
      "name": "Cloth_Roof_White_Vertical",
      "rotation": 2
    },
    {
      "x": -2,
      "y": 15,
      "z": -8,
      "name": "Cloth_Roof_White_Steep",
      "rotation": 2
    },
    {
      "x": -2,
      "y": 16,
      "z": -8,
      "name": "Cloth_Roof_White_Steep",
      "filler": 1024,
      "rotation": 2
    },
    {
      "x": -2,
      "y": 4,
      "z": -7,
      "name": "Wood_Softwood_Planks_Half",
      "rotation": 6
    },
    {
      "x": -2,
      "y": 5,
      "z": -7,
      "name": "Wood_Softwood_Planks"
    },
    {
      "x": -2,
      "y": 6,
      "z": -7,
      "name": "Wood_Softwood_Planks"
    },
    {
      "x": -2,
      "y": 11,
      "z": -7,
      "name": "Cloth_Roof_White"
    },
    {
      "x": -2,
      "y": 12,
      "z": -7,
      "name": "Cloth_Block_Wool_White"
    },
    {
      "x": -2,
      "y": 13,
      "z": -7,
      "name": "Cloth_Block_Wool_White"
    },
    {
      "x": -2,
      "y": 14,
      "z": -7,
      "name": "Cloth_Block_Wool_White"
    },
    {
      "x": -2,
      "y": 15,
      "z": -7,
      "name": "Cloth_Block_Wool_White"
    },
    {
      "x": -2,
      "y": 16,
      "z": -7,
      "name": "Cloth_Block_Wool_White"
    },
    {
      "x": -2,
      "y": 17,
      "z": -7,
      "name": "Cloth_Roof_White",
      "rotation": 2
    },
    {
      "x": -2,
      "y": 3,
      "z": -6,
      "name": "Wood_Softwood_Stairs",
      "rotation": 9
    },
    {
      "x": -2,
      "y": 4,
      "z": -6,
      "name": "Wood_Softwood_Planks"
    },
    {
      "x": -2,
      "y": 5,
      "z": -6,
      "name": "Wood_Softwood_Planks"
    },
    {
      "x": -2,
      "y": 6,
      "z": -6,
      "name": "Wood_Softwood_Planks"
    },
    {
      "x": -2,
      "y": 11,
      "z": -6,
      "name": "Cloth_Roof_White_Flat"
    },
    {
      "x": -2,
      "y": 12,
      "z": -6,
      "name": "Cloth_Block_Wool_White"
    },
    {
      "x": -2,
      "y": 13,
      "z": -6,
      "name": "Cloth_Block_Wool_White"
    },
    {
      "x": -2,
      "y": 14,
      "z": -6,
      "name": "Cloth_Block_Wool_White"
    },
    {
      "x": -2,
      "y": 15,
      "z": -6,
      "name": "Cloth_Block_Wool_White"
    },
    {
      "x": -2,
      "y": 16,
      "z": -6,
      "name": "Cloth_Block_Wool_White"
    },
    {
      "x": -2,
      "y": 17,
      "z": -6,
      "name": "Cloth_Block_Wool_White"
    },
    {
      "x": -2,
      "y": 18,
      "z": -6,
      "name": "Cloth_Roof_White_Flat"
    },
    {
      "x": -2,
      "y": 3,
      "z": -5,
      "name": "*Wood_Softwood_Planks_Half_State_Definitions_Block",
      "rotation": 7
    },
    {
      "x": -2,
      "y": 4,
      "z": -5,
      "name": "Furniture_Crude_Bed",
      "components": {
        "Components": {
          "RespawnBlock": {}
        }
      }
    },
    {
      "x": -2,
      "y": 5,
      "z": -5,
      "name": "*Furniture_Crude_Trapdoor_State_Definitions_CloseDoorOut",
      "rotation": 1
    },
    {
      "x": -2,
      "y": 6,
      "z": -5,
      "name": "Wood_Softwood_Planks"
    },
    {
      "x": -2,
      "y": 11,
      "z": -5,
      "name": "Cloth_Roof_White_Flat"
    },
    {
      "x": -2,
      "y": 12,
      "z": -5,
      "name": "Cloth_Block_Wool_White"
    },
    {
      "x": -2,
      "y": 17,
      "z": -5,
      "name": "Cloth_Block_Wool_White"
    },
    {
      "x": -2,
      "y": 18,
      "z": -5,
      "name": "Cloth_Roof_White_Flat"
    },
    {
      "x": -2,
      "y": 3,
      "z": -4,
      "name": "*Wood_Softwood_Planks_Half_State_Definitions_Block",
      "rotation": 7
    },
    {
      "x": -2,
      "y": 4,
      "z": -4,
      "name": "Furniture_Crude_Bed",
      "filler": 32
    },
    {
      "x": -2,
      "y": 5,
      "z": -4,
      "name": "*Furniture_Crude_Trapdoor_State_Definitions_CloseDoorOut",
      "rotation": 1
    },
    {
      "x": -2,
      "y": 6,
      "z": -4,
      "name": "Wood_Softwood_Planks"
    },
    {
      "x": -2,
      "y": 11,
      "z": -4,
      "name": "Cloth_Roof_White_Flat"
    },
    {
      "x": -2,
      "y": 12,
      "z": -4,
      "name": "Cloth_Block_Wool_White"
    },
    {
      "x": -2,
      "y": 17,
      "z": -4,
      "name": "Cloth_Block_Wool_White"
    },
    {
      "x": -2,
      "y": 18,
      "z": -4,
      "name": "Cloth_Roof_White_Flat"
    },
    {
      "x": -2,
      "y": 3,
      "z": -3,
      "name": "*Wood_Softwood_Planks_Half_State_Definitions_Block",
      "rotation": 7
    },
    {
      "x": -2,
      "y": 4,
      "z": -3,
      "name": "Furniture_Crude_Chest_Large",
      "filler": 31
    },
    {
      "x": -2,
      "y": 5,
      "z": -3,
      "name": "*Furniture_Crude_Chest_Large_State_Definitions_CloseWindow",
      "filler": 31
    },
    {
      "x": -2,
      "y": 6,
      "z": -3,
      "name": "Wood_Softwood_Planks"
    },
    {
      "x": -2,
      "y": 10,
      "z": -3,
      "name": "Wood_Softwood_Planks_Half",
      "rotation": 8
    },
    {
      "x": -2,
      "y": 11,
      "z": -3,
      "name": "Cloth_Block_Wool_White"
    },
    {
      "x": -2,
      "y": 15,
      "z": -3,
      "name": "Deco_SpiderWeb_Full",
      "support": 15
    },
    {
      "x": -2,
      "y": 17,
      "z": -3,
      "name": "Cloth_Block_Wool_White"
    },
    {
      "x": -2,
      "y": 18,
      "z": -3,
      "name": "Wood_Softwood_Planks_Half",
      "rotation": 2
    },
    {
      "x": -2,
      "y": 3,
      "z": -2,
      "name": "Wood_Softwood_Stairs",
      "rotation": 9
    },
    {
      "x": -2,
      "y": 4,
      "z": -2,
      "name": "Bench_Salvage",
      "components": {
        "Components": {
          "BenchBlock": {
            "TierLevel": 1,
            "UpgradeItems": []
          },
          "ProcessingBenchBlock": {
            "InputContainer": {
              "Id": "Simple",
              "Capacity": 1,
              "Items": {}
            },
            "FuelContainer": {
              "Id": "Empty"
            },
            "OutputContainer": {
              "Id": "Simple",
              "Capacity": 4,
              "Items": {}
            },
            "Progress": 0.0,
            "FuelTime": 0.0,
            "Active": true,
            "NextExtra": 2,
            "LastTickGameTime": "0001-01-06T12:03:47.622150798Z"
          }
        }
      },
      "rotation": 1
    },
    {
      "x": -2,
      "y": 5,
      "z": -2,
      "name": "Bench_Salvage",
      "filler": 1024,
      "rotation": 1
    },
    {
      "x": -2,
      "y": 6,
      "z": -2,
      "name": "Wood_Softwood_Stairs",
      "rotation": 11
    },
    {
      "x": -2,
      "y": 11,
      "z": -2,
      "name": "Cloth_Roof_White_Flat"
    },
    {
      "x": -2,
      "y": 12,
      "z": -2,
      "name": "Cloth_Block_Wool_White"
    },
    {
      "x": -2,
      "y": 14,
      "z": -2,
      "name": "Deco_SpiderWeb",
      "support": 15,
      "rotation": 1
    },
    {
      "x": -2,
      "y": 16,
      "z": -2,
      "name": "Deco_SpiderWeb_Full",
      "support": 15
    },
    {
      "x": -2,
      "y": 17,
      "z": -2,
      "name": "Cloth_Block_Wool_White"
    },
    {
      "x": -2,
      "y": 18,
      "z": -2,
      "name": "Cloth_Roof_White_Flat",
      "rotation": 2
    },
    {
      "x": -2,
      "y": 3,
      "z": -1,
      "name": "Wood_Softwood_Stairs",
      "rotation": 9
    },
    {
      "x": -2,
      "y": 4,
      "z": -1,
      "name": "Bench_Tannery",
      "components": {
        "Components": {
          "BenchBlock": {
            "TierLevel": 1,
            "UpgradeItems": []
          },
          "ProcessingBenchBlock": {
            "InputContainer": {
              "Id": "Simple",
              "Capacity": 2,
              "Items": {}
            },
            "FuelContainer": {
              "Id": "Empty"
            },
            "OutputContainer": {
              "Id": "Simple",
              "Capacity": 2,
              "Items": {}
            },
            "Progress": 0.0,
            "FuelTime": 0.0,
            "Active": true,
            "NextExtra": 0,
            "LastTickGameTime": "0001-01-06T12:03:47.622150798Z"
          }
        }
      },
      "rotation": 1
    },
    {
      "x": -2,
      "y": 5,
      "z": -1,
      "name": "Bench_Tannery",
      "filler": 1024,
      "rotation": 1
    },
    {
      "x": -2,
      "y": 6,
      "z": -1,
      "name": "Wood_Softwood_Stairs",
      "rotation": 11
    },
    {
      "x": -2,
      "y": 11,
      "z": -1,
      "name": "Cloth_Roof_White_Flat"
    },
    {
      "x": -2,
      "y": 12,
      "z": -1,
      "name": "Cloth_Block_Wool_White"
    },
    {
      "x": -2,
      "y": 13,
      "z": -1,
      "name": "Deco_SpiderWeb_Full",
      "support": 15
    },
    {
      "x": -2,
      "y": 15,
      "z": -1,
      "name": "Deco_SpiderWeb",
      "support": 15,
      "rotation": 1
    },
    {
      "x": -2,
      "y": 17,
      "z": -1,
      "name": "Cloth_Block_Wool_White"
    },
    {
      "x": -2,
      "y": 18,
      "z": -1,
      "name": "Cloth_Roof_White_Flat",
      "rotation": 2
    },
    {
      "x": -2,
      "y": 3,
      "z": 0,
      "name": "Wood_Softwood_Stairs",
      "rotation": 9
    },
    {
      "x": -2,
      "y": 4,
      "z": 0,
      "name": "Bench_Tannery",
      "filler": 32,
      "rotation": 1
    },
    {
      "x": -2,
      "y": 5,
      "z": 0,
      "name": "Bench_Tannery",
      "filler": 1056,
      "rotation": 1
    },
    {
      "x": -2,
      "y": 6,
      "z": 0,
      "name": "Wood_Softwood_Stairs",
      "rotation": 11
    },
    {
      "x": -2,
      "y": 11,
      "z": 0,
      "name": "Cloth_Roof_White_Flat"
    },
    {
      "x": -2,
      "y": 12,
      "z": 0,
      "name": "Cloth_Block_Wool_White"
    },
    {
      "x": -2,
      "y": 13,
      "z": 0,
      "name": "Deco_SpiderWeb_Full",
      "support": 15
    },
    {
      "x": -2,
      "y": 14,
      "z": 0,
      "name": "Deco_SpiderWeb_Full",
      "support": 15
    },
    {
      "x": -2,
      "y": 16,
      "z": 0,
      "name": "Deco_SpiderWeb_Full",
      "support": 15
    },
    {
      "x": -2,
      "y": 17,
      "z": 0,
      "name": "Cloth_Block_Wool_White"
    },
    {
      "x": -2,
      "y": 18,
      "z": 0,
      "name": "Cloth_Roof_White_Flat",
      "rotation": 2
    },
    {
      "x": -2,
      "y": 3,
      "z": 1,
      "name": "Wood_Softwood_Stairs",
      "rotation": 9
    },
    {
      "x": -2,
      "y": 4,
      "z": 1,
      "name": "Bench_Farming",
      "components": {
        "Components": {
          "BenchBlock": {
            "TierLevel": 1,
            "UpgradeItems": []
          }
        }
      },
      "rotation": 1
    },
    {
      "x": -2,
      "y": 5,
      "z": 1,
      "name": "Bench_Farming",
      "filler": 1024,
      "rotation": 1
    },
    {
      "x": -2,
      "y": 6,
      "z": 1,
      "name": "Wood_Softwood_Planks_Half",
      "rotation": 8
    },
    {
      "x": -2,
      "y": 7,
      "z": 1,
      "name": "Wood_Softwood_Planks_Half"
    },
    {
      "x": -2,
      "y": 8,
      "z": 1,
      "name": "Lobby_Wall_Poster_Small01",
      "rotation": 2
    },
    {
      "x": -2,
      "y": 9,
      "z": 1,
      "name": "Lobby_Wall_Poster01",
      "rotation": 2
    },
    {
      "x": -2,
      "y": 10,
      "z": 1,
      "name": "Wood_Softwood_Planks_Half",
      "rotation": 8
    },
    {
      "x": -2,
      "y": 11,
      "z": 1,
      "name": "Cloth_Block_Wool_White"
    },
    {
      "x": -2,
      "y": 17,
      "z": 1,
      "name": "Cloth_Block_Wool_White"
    },
    {
      "x": -2,
      "y": 18,
      "z": 1,
      "name": "Wood_Softwood_Planks_Half",
      "rotation": 2
    },
    {
      "x": -2,
      "y": 3,
      "z": 2,
      "name": "Wood_Softwood_Stairs",
      "rotation": 9
    },
    {
      "x": -2,
      "y": 4,
      "z": 2,
      "name": "Bench_Farming",
      "filler": 32,
      "rotation": 1
    },
    {
      "x": -2,
      "y": 5,
      "z": 2,
      "name": "Bench_Farming",
      "filler": 1056,
      "rotation": 1
    },
    {
      "x": -2,
      "y": 6,
      "z": 2,
      "name": "Furniture_Kweebec_Painting",
      "rotation": 1
    },
    {
      "x": -2,
      "y": 7,
      "z": 2,
      "name": "*Wood_Softwood_Planks_Half_State_Definitions_Block",
      "rotation": 6
    },
    {
      "x": -2,
      "y": 8,
      "z": 2,
      "name": "*Wood_Softwood_Planks_Half_State_Definitions_Block",
      "rotation": 6
    },
    {
      "x": -2,
      "y": 9,
      "z": 2,
      "name": "*Wood_Softwood_Planks_Half_State_Definitions_Block"
    },
    {
      "x": -2,
      "y": 10,
      "z": 2,
      "name": "*Wood_Softwood_Planks_Half_State_Definitions_Block",
      "rotation": 6
    },
    {
      "x": -2,
      "y": 11,
      "z": 2,
      "name": "Cloth_Block_Wool_White"
    },
    {
      "x": -2,
      "y": 16,
      "z": 2,
      "name": "Deco_SpiderWeb_Full",
      "support": 15
    },
    {
      "x": -2,
      "y": 17,
      "z": 2,
      "name": "Cloth_Block_Wool_White"
    },
    {
      "x": -2,
      "y": 18,
      "z": 2,
      "name": "Cloth_Roof_White_Flat",
      "rotation": 2
    },
    {
      "x": -2,
      "y": 3,
      "z": 3,
      "name": "Wood_Softwood_Planks"
    },
    {
      "x": -2,
      "y": 4,
      "z": 3,
      "name": "Furniture_Village_Planter"
    },
    {
      "x": -2,
      "y": 5,
      "z": 3,
      "name": "Bench_Campfire",
      "components": {
        "Components": {
          "BenchBlock": {
            "TierLevel": 1,
            "UpgradeItems": []
          },
          "ProcessingBenchBlock": {
            "InputContainer": {
              "Id": "Simple",
              "Capacity": 2,
              "Items": {}
            },
            "FuelContainer": {
              "Id": "Simple",
              "Capacity": 1,
              "Items": {}
            },
            "OutputContainer": {
              "Id": "Simple",
              "Capacity": 4,
              "Items": {}
            },
            "Progress": 0.0,
            "FuelTime": 0.0,
            "Active": false,
            "NextExtra": 2,
            "LastTickGameTime": "0001-01-06T12:03:47.622150798Z"
          }
        }
      },
      "rotation": 1
    },
    {
      "x": -2,
      "y": 6,
      "z": 3,
      "name": "Furniture_Kweebec_Painting",
      "rotation": 1
    },
    {
      "x": -2,
      "y": 7,
      "z": 3,
      "name": "Wood_Softwood_Planks"
    },
    {
      "x": -2,
      "y": 8,
      "z": 3,
      "name": "Furniture_Village_Counter",
      "filler": 31
    },
    {
      "x": -2,
      "y": 9,
      "z": 3,
      "name": "*Furniture_Temple_Wind_Chest_Small_State_Definitions_CloseWindow",
      "components": {
        "Components": {
          "ItemContainerBlock": {
            "ItemContainer": {
              "Capacity": 18,
              "Items": {}
            },
            "Capacity": 18
          }
        }
      }
    },
    {
      "x": -2,
      "y": 10,
      "z": 3,
      "name": "Wood_Softwood_Planks_Half",
      "rotation": 8
    },
    {
      "x": -2,
      "y": 11,
      "z": 3,
      "name": "Cloth_Block_Wool_White"
    },
    {
      "x": -2,
      "y": 14,
      "z": 3,
      "name": "Deco_SpiderWeb_Full",
      "support": 15
    },
    {
      "x": -2,
      "y": 17,
      "z": 3,
      "name": "Cloth_Block_Wool_White"
    },
    {
      "x": -2,
      "y": 18,
      "z": 3,
      "name": "Cloth_Roof_White_Flat"
    },
    {
      "x": -2,
      "y": 3,
      "z": 4,
      "name": "Wood_Softwood_Planks"
    },
    {
      "x": -2,
      "y": 4,
      "z": 4,
      "name": "Bench_Cooking",
      "components": {
        "Components": {
          "BenchBlock": {
            "TierLevel": 1,
            "UpgradeItems": []
          }
        }
      },
      "rotation": 1
    },
    {
      "x": -2,
      "y": 5,
      "z": 4,
      "name": "Bench_Cooking",
      "filler": 1024,
      "rotation": 1
    },
    {
      "x": -2,
      "y": 6,
      "z": 4,
      "name": "Deco_Lantern_Ceiling"
    },
    {
      "x": -2,
      "y": 7,
      "z": 4,
      "name": "Wood_Softwood_Planks"
    },
    {
      "x": -2,
      "y": 10,
      "z": 4,
      "name": "Deco_Wallchain",
      "rotation": 1
    },
    {
      "x": -2,
      "y": 11,
      "z": 4,
      "name": "Cloth_Block_Wool_White"
    },
    {
      "x": -2,
      "y": 12,
      "z": 4,
      "name": "Cloth_Block_Wool_White"
    },
    {
      "x": -2,
      "y": 13,
      "z": 4,
      "name": "Deco_SpiderWeb",
      "support": 15,
      "rotation": 1
    },
    {
      "x": -2,
      "y": 16,
      "z": 4,
      "name": "Deco_SpiderWeb_Full",
      "support": 15
    },
    {
      "x": -2,
      "y": 17,
      "z": 4,
      "name": "Cloth_Block_Wool_White"
    },
    {
      "x": -2,
      "y": 18,
      "z": 4,
      "name": "Cloth_Roof_White_Flat",
      "rotation": 2
    },
    {
      "x": -2,
      "y": 3,
      "z": 5,
      "name": "Wood_Softwood_Planks"
    },
    {
      "x": -2,
      "y": 4,
      "z": 5,
      "name": "Bench_Cooking",
      "filler": 32,
      "rotation": 1
    },
    {
      "x": -2,
      "y": 5,
      "z": 5,
      "name": "Bench_Cooking",
      "filler": 1056,
      "rotation": 1
    },
    {
      "x": -2,
      "y": 6,
      "z": 5,
      "name": "Deco_Halloween_Lights",
      "rotation": 1
    },
    {
      "x": -2,
      "y": 7,
      "z": 5,
      "name": "Wood_Softwood_Planks"
    },
    {
      "x": -2,
      "y": 11,
      "z": 5,
      "name": "Cloth_Block_Wool_White"
    },
    {
      "x": -2,
      "y": 12,
      "z": 5,
      "name": "Cloth_Block_Wool_White"
    },
    {
      "x": -2,
      "y": 14,
      "z": 5,
      "name": "Deco_SpiderWeb_Full",
      "support": 15
    },
    {
      "x": -2,
      "y": 17,
      "z": 5,
      "name": "Cloth_Block_Wool_White"
    },
    {
      "x": -2,
      "y": 18,
      "z": 5,
      "name": "Wood_Softwood_Planks_Half",
      "rotation": 2
    },
    {
      "x": -2,
      "y": 3,
      "z": 6,
      "name": "Wood_Softwood_Planks"
    },
    {
      "x": -2,
      "y": 4,
      "z": 6,
      "name": "Wood_Softwood_Planks"
    },
    {
      "x": -2,
      "y": 5,
      "z": 6,
      "name": "Wood_Softwood_Planks"
    },
    {
      "x": -2,
      "y": 6,
      "z": 6,
      "name": "Wood_Softwood_Planks"
    },
    {
      "x": -2,
      "y": 7,
      "z": 6,
      "name": "Wood_Softwood_Planks"
    },
    {
      "x": -2,
      "y": 8,
      "z": 6,
      "name": "Cloth_Roof_Leather_Flat"
    },
    {
      "x": -2,
      "y": 10,
      "z": 6,
      "name": "Deco_Wallchain",
      "rotation": 1
    },
    {
      "x": -2,
      "y": 11,
      "z": 6,
      "name": "Cloth_Block_Wool_White"
    },
    {
      "x": -2,
      "y": 12,
      "z": 6,
      "name": "Cloth_Block_Wool_White"
    },
    {
      "x": -2,
      "y": 14,
      "z": 6,
      "name": "Deco_SpiderWeb_Full",
      "support": 15
    },
    {
      "x": -2,
      "y": 16,
      "z": 6,
      "name": "Deco_SpiderWeb_Full",
      "support": 15
    },
    {
      "x": -2,
      "y": 17,
      "z": 6,
      "name": "Cloth_Block_Wool_White"
    },
    {
      "x": -2,
      "y": 18,
      "z": 6,
      "name": "Cloth_Roof_White_Flat",
      "rotation": 2
    },
    {
      "x": -2,
      "y": 3,
      "z": 7,
      "name": "Wood_Softwood_Planks_Half",
      "rotation": 7
    },
    {
      "x": -2,
      "y": 4,
      "z": 7,
      "name": "Wood_Softwood_Planks"
    },
    {
      "x": -2,
      "y": 5,
      "z": 7,
      "name": "Wood_Softwood_Planks"
    },
    {
      "x": -2,
      "y": 6,
      "z": 7,
      "name": "Wood_Softwood_Planks"
    },
    {
      "x": -2,
      "y": 7,
      "z": 7,
      "name": "Wood_Softwood_Planks"
    },
    {
      "x": -2,
      "y": 8,
      "z": 7,
      "name": "Cloth_Roof_Leather_Flat"
    },
    {
      "x": -2,
      "y": 11,
      "z": 7,
      "name": "Cloth_Block_Wool_White"
    },
    {
      "x": -2,
      "y": 12,
      "z": 7,
      "name": "Cloth_Block_Wool_White"
    },
    {
      "x": -2,
      "y": 14,
      "z": 7,
      "name": "Deco_SpiderWeb",
      "support": 15,
      "rotation": 1
    },
    {
      "x": -2,
      "y": 17,
      "z": 7,
      "name": "Cloth_Block_Wool_White"
    },
    {
      "x": -2,
      "y": 18,
      "z": 7,
      "name": "Cloth_Roof_White_Flat",
      "rotation": 2
    },
    {
      "x": -2,
      "y": 4,
      "z": 8,
      "name": "Wood_Softwood_Planks_Half",
      "rotation": 7
    },
    {
      "x": -2,
      "y": 5,
      "z": 8,
      "name": "Wood_Softwood_Planks"
    },
    {
      "x": -2,
      "y": 6,
      "z": 8,
      "name": "Wood_Softwood_Planks"
    },
    {
      "x": -2,
      "y": 7,
      "z": 8,
      "name": "Wood_Softwood_Planks"
    },
    {
      "x": -2,
      "y": 8,
      "z": 8,
      "name": "Cloth_Roof_Leather_Flat"
    },
    {
      "x": -2,
      "y": 10,
      "z": 8,
      "name": "Deco_Wallchain",
      "rotation": 1
    },
    {
      "x": -2,
      "y": 11,
      "z": 8,
      "name": "Cloth_Block_Wool_White"
    },
    {
      "x": -2,
      "y": 12,
      "z": 8,
      "name": "Cloth_Block_Wool_White"
    },
    {
      "x": -2,
      "y": 16,
      "z": 8,
      "name": "Deco_SpiderWeb",
      "support": 15,
      "rotation": 11
    },
    {
      "x": -2,
      "y": 17,
      "z": 8,
      "name": "Cloth_Block_Wool_White"
    },
    {
      "x": -2,
      "y": 18,
      "z": 8,
      "name": "Cloth_Roof_White_Flat",
      "rotation": 2
    },
    {
      "x": -2,
      "y": 5,
      "z": 9,
      "name": "Wood_Softwood_Planks"
    },
    {
      "x": -2,
      "y": 6,
      "z": 9,
      "name": "Wood_Softwood_Planks"
    },
    {
      "x": -2,
      "y": 7,
      "z": 9,
      "name": "Wood_Softwood_Planks"
    },
    {
      "x": -2,
      "y": 9,
      "z": 9,
      "name": "Cloth_Roof_Leather_Flap",
      "rotation": 2
    },
    {
      "x": -2,
      "y": 10,
      "z": 9,
      "name": "Wood_Softwood_Planks_Half",
      "rotation": 8
    },
    {
      "x": -2,
      "y": 11,
      "z": 9,
      "name": "Cloth_Block_Wool_White"
    },
    {
      "x": -2,
      "y": 15,
      "z": 9,
      "name": "Deco_SpiderWeb_Full",
      "support": 15
    },
    {
      "x": -2,
      "y": 16,
      "z": 9,
      "name": "Deco_SpiderWeb_Full",
      "support": 15
    },
    {
      "x": -2,
      "y": 17,
      "z": 9,
      "name": "Cloth_Block_Wool_White"
    },
    {
      "x": -2,
      "y": 18,
      "z": 9,
      "name": "Wood_Softwood_Planks_Half",
      "rotation": 2
    },
    {
      "x": -2,
      "y": 6,
      "z": 10,
      "name": "Wood_Softwood_Stairs",
      "rotation": 10
    },
    {
      "x": -2,
      "y": 7,
      "z": 10,
      "name": "*Wood_Softwood_Planks_Half_State_Definitions_Block"
    },
    {
      "x": -2,
      "y": 8,
      "z": 10,
      "name": "Wood_Softwood_Planks"
    },
    {
      "x": -2,
      "y": 9,
      "z": 10,
      "name": "Wood_Softwood_Planks_Half",
      "rotation": 6
    },
    {
      "x": -2,
      "y": 10,
      "z": 10,
      "name": "Wood_Softwood_Stairs"
    },
    {
      "x": -2,
      "y": 11,
      "z": 10,
      "name": "Cloth_Roof_White_Flat"
    },
    {
      "x": -2,
      "y": 12,
      "z": 10,
      "name": "Cloth_Block_Wool_White"
    },
    {
      "x": -2,
      "y": 14,
      "z": 10,
      "name": "Deco_SpiderWeb",
      "support": 15,
      "rotation": 1
    },
    {
      "x": -2,
      "y": 17,
      "z": 10,
      "name": "Cloth_Block_Wool_White"
    },
    {
      "x": -2,
      "y": 18,
      "z": 10,
      "name": "Cloth_Roof_White_Flat",
      "rotation": 2
    },
    {
      "x": -2,
      "y": 11,
      "z": 11,
      "name": "Cloth_Roof_White_Flat"
    },
    {
      "x": -2,
      "y": 12,
      "z": 11,
      "name": "Cloth_Block_Wool_White"
    },
    {
      "x": -2,
      "y": 15,
      "z": 11,
      "name": "Deco_SpiderWeb_Full",
      "support": 15
    },
    {
      "x": -2,
      "y": 17,
      "z": 11,
      "name": "Cloth_Block_Wool_White"
    },
    {
      "x": -2,
      "y": 18,
      "z": 11,
      "name": "Cloth_Roof_White_Flat",
      "rotation": 2
    },
    {
      "x": -2,
      "y": 11,
      "z": 12,
      "name": "Cloth_Roof_White_Flat"
    },
    {
      "x": -2,
      "y": 12,
      "z": 12,
      "name": "Cloth_Block_Wool_White"
    },
    {
      "x": -2,
      "y": 13,
      "z": 12,
      "name": "Cloth_Block_Wool_White"
    },
    {
      "x": -2,
      "y": 14,
      "z": 12,
      "name": "Cloth_Block_Wool_White"
    },
    {
      "x": -2,
      "y": 15,
      "z": 12,
      "name": "Cloth_Block_Wool_White"
    },
    {
      "x": -2,
      "y": 16,
      "z": 12,
      "name": "Cloth_Block_Wool_White"
    },
    {
      "x": -2,
      "y": 17,
      "z": 12,
      "name": "Cloth_Block_Wool_White"
    },
    {
      "x": -2,
      "y": 18,
      "z": 12,
      "name": "Cloth_Roof_White_Flat",
      "rotation": 2
    },
    {
      "x": -2,
      "y": 11,
      "z": 13,
      "name": "Cloth_Roof_White",
      "rotation": 2
    },
    {
      "x": -2,
      "y": 12,
      "z": 13,
      "name": "Cloth_Block_Wool_White"
    },
    {
      "x": -2,
      "y": 13,
      "z": 13,
      "name": "Cloth_Block_Wool_White"
    },
    {
      "x": -2,
      "y": 14,
      "z": 13,
      "name": "Cloth_Block_Wool_White"
    },
    {
      "x": -2,
      "y": 15,
      "z": 13,
      "name": "Cloth_Block_Wool_White"
    },
    {
      "x": -2,
      "y": 16,
      "z": 13,
      "name": "Cloth_Block_Wool_White"
    },
    {
      "x": -2,
      "y": 17,
      "z": 13,
      "name": "Cloth_Roof_White"
    },
    {
      "x": -2,
      "y": 12,
      "z": 14,
      "name": "Cloth_Roof_White_Steep",
      "rotation": 2
    },
    {
      "x": -2,
      "y": 13,
      "z": 14,
      "name": "Cloth_Roof_White_Steep",
      "filler": 1024,
      "rotation": 2
    },
    {
      "x": -2,
      "y": 14,
      "z": 14,
      "name": "Cloth_Block_Wool_White"
    },
    {
      "x": -2,
      "y": 15,
      "z": 14,
      "name": "Cloth_Roof_White_Steep"
    },
    {
      "x": -2,
      "y": 16,
      "z": 14,
      "name": "Cloth_Roof_White_Steep",
      "filler": 1024
    },
    {
      "x": -2,
      "y": 14,
      "z": 15,
      "name": "Cloth_Roof_White_Flap"
    },
    {
      "x": -1,
      "y": 8,
      "z": -13,
      "name": "Wood_Softwood_Stairs",
      "rotation": 9
    },
    {
      "x": -1,
      "y": 8,
      "z": -12,
      "name": "Wood_Softwood_Stairs",
      "rotation": 9
    },
    {
      "x": -1,
      "y": 7,
      "z": -11,
      "name": "Wood_Softwood_Planks_Half",
      "rotation": 7
    },
    {
      "x": -1,
      "y": 8,
      "z": -11,
      "name": "*Wood_Softwood_Stairs_State_Definitions_Inverted_Corner_Right",
      "rotation": 8
    },
    {
      "x": -1,
      "y": 6,
      "z": -10,
      "name": "Wood_Softwood_Planks"
    },
    {
      "x": -1,
      "y": 7,
      "z": -10,
      "name": "Wood_Softwood_Planks"
    },
    {
      "x": -1,
      "y": 8,
      "z": -10,
      "name": "Airship_Lever",
      "rotation": 2
    },
    {
      "x": -1,
      "y": 5,
      "z": -9,
      "name": "Wood_Softwood_Planks"
    },
    {
      "x": -1,
      "y": 6,
      "z": -9,
      "name": "Wood_Softwood_Planks"
    },
    {
      "x": -1,
      "y": 7,
      "z": -9,
      "name": "Wood_Softwood_Planks"
    },
    {
      "x": -1,
      "y": 14,
      "z": -9,
      "name": "Cloth_Roof_White_Vertical",
      "rotation": 2
    },
    {
      "x": -1,
      "y": 4,
      "z": -8,
      "name": "Wood_Softwood_Planks_Half",
      "rotation": 7
    },
    {
      "x": -1,
      "y": 5,
      "z": -8,
      "name": "Wood_Softwood_Planks"
    },
    {
      "x": -1,
      "y": 6,
      "z": -8,
      "name": "Wood_Softwood_Planks"
    },
    {
      "x": -1,
      "y": 7,
      "z": -8,
      "name": "Wood_Softwood_Planks_Half",
      "rotation": 4
    },
    {
      "x": -1,
      "y": 12,
      "z": -8,
      "name": "Cloth_Roof_White_Vertical",
      "rotation": 2
    },
    {
      "x": -1,
      "y": 13,
      "z": -8,
      "name": "Cloth_Roof_White"
    },
    {
      "x": -1,
      "y": 14,
      "z": -8,
      "name": "Cloth_Block_Wool_White"
    },
    {
      "x": -1,
      "y": 15,
      "z": -8,
      "name": "Cloth_Roof_White",
      "rotation": 2
    },
    {
      "x": -1,
      "y": 16,
      "z": -8,
      "name": "Cloth_Roof_White_Vertical",
      "rotation": 2
    },
    {
      "x": -1,
      "y": 4,
      "z": -7,
      "name": "Wood_Softwood_Planks"
    },
    {
      "x": -1,
      "y": 5,
      "z": -7,
      "name": "Furniture_Crude_Chest_Small",
      "components": {
        "Components": {
          "ItemContainerBlock": {
            "ItemContainer": {
              "Capacity": 18,
              "Items": {}
            },
            "Capacity": 18
          }
        }
      }
    },
    {
      "x": -1,
      "y": 6,
      "z": -7,
      "name": "Wood_Softwood_Planks"
    },
    {
      "x": -1,
      "y": 11,
      "z": -7,
      "name": "Cloth_Roof_White"
    },
    {
      "x": -1,
      "y": 12,
      "z": -7,
      "name": "Cloth_Block_Wool_White"
    },
    {
      "x": -1,
      "y": 13,
      "z": -7,
      "name": "Cloth_Block_Wool_White"
    },
    {
      "x": -1,
      "y": 14,
      "z": -7,
      "name": "Cloth_Block_Wool_White"
    },
    {
      "x": -1,
      "y": 15,
      "z": -7,
      "name": "Cloth_Block_Wool_White"
    },
    {
      "x": -1,
      "y": 16,
      "z": -7,
      "name": "Cloth_Block_Wool_White"
    },
    {
      "x": -1,
      "y": 17,
      "z": -7,
      "name": "Cloth_Roof_White",
      "rotation": 2
    },
    {
      "x": -1,
      "y": 3,
      "z": -6,
      "name": "Wood_Softwood_Planks"
    },
    {
      "x": -1,
      "y": 4,
      "z": -6,
      "name": "Furniture_Crude_Chest_Large",
      "filler": 31
    },
    {
      "x": -1,
      "y": 6,
      "z": -6,
      "name": "Wood_Softwood_Planks"
    },
    {
      "x": -1,
      "y": 11,
      "z": -6,
      "name": "Cloth_Roof_White_Flat"
    },
    {
      "x": -1,
      "y": 12,
      "z": -6,
      "name": "Cloth_Block_Wool_White"
    },
    {
      "x": -1,
      "y": 13,
      "z": -6,
      "name": "Cloth_Block_Wool_White"
    },
    {
      "x": -1,
      "y": 14,
      "z": -6,
      "name": "Cloth_Block_Wool_White"
    },
    {
      "x": -1,
      "y": 15,
      "z": -6,
      "name": "Cloth_Block_Wool_White"
    },
    {
      "x": -1,
      "y": 16,
      "z": -6,
      "name": "Cloth_Block_Wool_White"
    },
    {
      "x": -1,
      "y": 17,
      "z": -6,
      "name": "Cloth_Block_Wool_White"
    },
    {
      "x": -1,
      "y": 18,
      "z": -6,
      "name": "Cloth_Roof_White_Flat"
    },
    {
      "x": -1,
      "y": 2,
      "z": -5,
      "name": "Wood_Softwood_Planks_Half",
      "rotation": 8
    },
    {
      "x": -1,
      "y": 3,
      "z": -5,
      "name": "Wood_Softwood_Planks_Half"
    },
    {
      "x": -1,
      "y": 6,
      "z": -5,
      "name": "Wood_Softwood_Planks"
    },
    {
      "x": -1,
      "y": 11,
      "z": -5,
      "name": "Cloth_Roof_White_Flat"
    },
    {
      "x": -1,
      "y": 12,
      "z": -5,
      "name": "Cloth_Block_Wool_White"
    },
    {
      "x": -1,
      "y": 17,
      "z": -5,
      "name": "Cloth_Block_Wool_White"
    },
    {
      "x": -1,
      "y": 18,
      "z": -5,
      "name": "Cloth_Roof_White_Flat"
    },
    {
      "x": -1,
      "y": 2,
      "z": -4,
      "name": "Wood_Softwood_Planks_Half",
      "rotation": 8
    },
    {
      "x": -1,
      "y": 3,
      "z": -4,
      "name": "Wood_Softwood_Planks_Half"
    },
    {
      "x": -1,
      "y": 6,
      "z": -4,
      "name": "Wood_Softwood_Planks"
    },
    {
      "x": -1,
      "y": 11,
      "z": -4,
      "name": "Cloth_Roof_White_Flat"
    },
    {
      "x": -1,
      "y": 12,
      "z": -4,
      "name": "Cloth_Block_Wool_White"
    },
    {
      "x": -1,
      "y": 17,
      "z": -4,
      "name": "Cloth_Block_Wool_White"
    },
    {
      "x": -1,
      "y": 18,
      "z": -4,
      "name": "Cloth_Roof_White_Flat"
    },
    {
      "x": -1,
      "y": 2,
      "z": -3,
      "name": "Wood_Softwood_Planks_Half",
      "rotation": 8
    },
    {
      "x": -1,
      "y": 3,
      "z": -3,
      "name": "Wood_Softwood_Planks"
    },
    {
      "x": -1,
      "y": 4,
      "z": -3,
      "name": "Furniture_Crude_Chest_Large",
      "components": {
        "Components": {
          "ItemContainerBlock": {
            "ItemContainer": {
              "Capacity": 36,
              "Items": {}
            },
            "Capacity": 36
          }
        }
      }
    },
    {
      "x": -1,
      "y": 5,
      "z": -3,
      "name": "*Furniture_Crude_Chest_Large_State_Definitions_CloseWindow",
      "components": {
        "Components": {
          "ItemContainerBlock": {
            "ItemContainer": {
              "Capacity": 36,
              "Items": {}
            },
            "Capacity": 36
          }
        }
      }
    },
    {
      "x": -1,
      "y": 6,
      "z": -3,
      "name": "Wood_Softwood_Planks"
    },
    {
      "x": -1,
      "y": 10,
      "z": -3,
      "name": "*Wood_Softwood_Planks_Half_State_Definitions_Block",
      "rotation": 7
    },
    {
      "x": -1,
      "y": 11,
      "z": -3,
      "name": "Cloth_Block_Wool_White"
    },
    {
      "x": -1,
      "y": 17,
      "z": -3,
      "name": "Cloth_Block_Wool_White"
    },
    {
      "x": -1,
      "y": 18,
      "z": -3,
      "name": "*Wood_Softwood_Planks_Half_State_Definitions_Block"
    },
    {
      "x": -1,
      "y": 2,
      "z": -2,
      "name": "Wood_Softwood_Planks_Half",
      "rotation": 8
    },
    {
      "x": -1,
      "y": 3,
      "z": -2,
      "name": "Wood_Softwood_Planks"
    },
    {
      "x": -1,
      "y": 6,
      "z": -2,
      "name": "Wood_Softwood_Stairs",
      "rotation": 9
    },
    {
      "x": -1,
      "y": 11,
      "z": -2,
      "name": "Cloth_Roof_White_Flat"
    },
    {
      "x": -1,
      "y": 12,
      "z": -2,
      "name": "Cloth_Block_Wool_White"
    },
    {
      "x": -1,
      "y": 14,
      "z": -2,
      "name": "Deco_SpiderWeb_Full",
      "support": 15
    },
    {
      "x": -1,
      "y": 17,
      "z": -2,
      "name": "Cloth_Block_Wool_White"
    },
    {
      "x": -1,
      "y": 18,
      "z": -2,
      "name": "Cloth_Roof_White_Flat",
      "rotation": 2
    },
    {
      "x": -1,
      "y": 2,
      "z": -1,
      "name": "Wood_Softwood_Planks_Half",
      "rotation": 8
    },
    {
      "x": -1,
      "y": 3,
      "z": -1,
      "name": "Wood_Softwood_Planks"
    },
    {
      "x": -1,
      "y": 6,
      "z": -1,
      "name": "*Wood_Softwood_Stairs_State_Definitions_Corner_Left",
      "rotation": 10
    },
    {
      "x": -1,
      "y": 11,
      "z": -1,
      "name": "Cloth_Roof_White_Flat"
    },
    {
      "x": -1,
      "y": 12,
      "z": -1,
      "name": "Cloth_Block_Wool_White"
    },
    {
      "x": -1,
      "y": 16,
      "z": -1,
      "name": "Deco_SpiderWeb_Full",
      "support": 15
    },
    {
      "x": -1,
      "y": 17,
      "z": -1,
      "name": "Cloth_Block_Wool_White"
    },
    {
      "x": -1,
      "y": 18,
      "z": -1,
      "name": "Cloth_Roof_White_Flat",
      "rotation": 2
    },
    {
      "x": -1,
      "y": 2,
      "z": 0,
      "name": "Wood_Softwood_Planks_Half",
      "rotation": 8
    },
    {
      "x": -1,
      "y": 3,
      "z": 0,
      "name": "Wood_Softwood_Planks"
    },
    {
      "x": -1,
      "y": 6,
      "z": 0,
      "name": "Wood_Softwood_Planks_Half",
      "rotation": 8
    },
    {
      "x": -1,
      "y": 11,
      "z": 0,
      "name": "Cloth_Roof_White_Flat"
    },
    {
      "x": -1,
      "y": 12,
      "z": 0,
      "name": "Cloth_Block_Wool_White"
    },
    {
      "x": -1,
      "y": 17,
      "z": 0,
      "name": "Cloth_Block_Wool_White"
    },
    {
      "x": -1,
      "y": 18,
      "z": 0,
      "name": "Cloth_Roof_White_Flat",
      "rotation": 2
    },
    {
      "x": -1,
      "y": 2,
      "z": 1,
      "name": "Wood_Softwood_Planks_Half",
      "rotation": 8
    },
    {
      "x": -1,
      "y": 3,
      "z": 1,
      "name": "Wood_Softwood_Planks"
    },
    {
      "x": -1,
      "y": 7,
      "z": 1,
      "name": "Wood_Softwood_Planks_Half"
    },
    {
      "x": -1,
      "y": 10,
      "z": 1,
      "name": "Wood_Softwood_Planks_Half",
      "rotation": 8
    },
    {
      "x": -1,
      "y": 11,
      "z": 1,
      "name": "Cloth_Block_Wool_White"
    },
    {
      "x": -1,
      "y": 16,
      "z": 1,
      "name": "Deco_SpiderWeb_Full",
      "support": 15
    },
    {
      "x": -1,
      "y": 17,
      "z": 1,
      "name": "Cloth_Block_Wool_White"
    },
    {
      "x": -1,
      "y": 18,
      "z": 1,
      "name": "*Wood_Softwood_Planks_Half_State_Definitions_Block"
    },
    {
      "x": -1,
      "y": 2,
      "z": 2,
      "name": "Wood_Softwood_Planks_Half",
      "rotation": 8
    },
    {
      "x": -1,
      "y": 3,
      "z": 2,
      "name": "Wood_Softwood_Planks"
    },
    {
      "x": -1,
      "y": 7,
      "z": 2,
      "name": "Wood_Softwood_Planks"
    },
    {
      "x": -1,
      "y": 8,
      "z": 2,
      "name": "Wood_Softwood_Planks_Half",
      "rotation": 6
    },
    {
      "x": -1,
      "y": 9,
      "z": 2,
      "name": "Wood_Softwood_Planks_Half",
      "rotation": 6
    },
    {
      "x": -1,
      "y": 10,
      "z": 2,
      "name": "Wood_Softwood_Planks_Half",
      "rotation": 6
    },
    {
      "x": -1,
      "y": 11,
      "z": 2,
      "name": "Cloth_Block_Wool_White"
    },
    {
      "x": -1,
      "y": 17,
      "z": 2,
      "name": "Cloth_Block_Wool_White"
    },
    {
      "x": -1,
      "y": 18,
      "z": 2,
      "name": "Cloth_Roof_White_Flat",
      "rotation": 2
    },
    {
      "x": -1,
      "y": 2,
      "z": 3,
      "name": "Wood_Softwood_Planks_Half",
      "rotation": 8
    },
    {
      "x": -1,
      "y": 3,
      "z": 3,
      "name": "Wood_Softwood_Planks"
    },
    {
      "x": -1,
      "y": 7,
      "z": 3,
      "name": "Wood_Softwood_Planks"
    },
    {
      "x": -1,
      "y": 8,
      "z": 3,
      "name": "Furniture_Village_Counter"
    },
    {
      "x": -1,
      "y": 9,
      "z": 3,
      "name": "Furniture_Kweebec_Statue"
    },
    {
      "x": -1,
      "y": 10,
      "z": 3,
      "name": "Wood_Softwood_Planks_Half",
      "rotation": 8
    },
    {
      "x": -1,
      "y": 11,
      "z": 3,
      "name": "Cloth_Block_Wool_White"
    },
    {
      "x": -1,
      "y": 17,
      "z": 3,
      "name": "Cloth_Block_Wool_White"
    },
    {
      "x": -1,
      "y": 18,
      "z": 3,
      "name": "Cloth_Roof_White_Flat"
    },
    {
      "x": -1,
      "y": 2,
      "z": 4,
      "name": "Wood_Softwood_Planks_Half",
      "rotation": 8
    },
    {
      "x": -1,
      "y": 3,
      "z": 4,
      "name": "Wood_Softwood_Planks"
    },
    {
      "x": -1,
      "y": 7,
      "z": 4,
      "name": "Wood_Softwood_Planks"
    },
    {
      "x": -1,
      "y": 11,
      "z": 4,
      "name": "Cloth_Block_Wool_White"
    },
    {
      "x": -1,
      "y": 12,
      "z": 4,
      "name": "Cloth_Block_Wool_White"
    },
    {
      "x": -1,
      "y": 17,
      "z": 4,
      "name": "Cloth_Block_Wool_White"
    },
    {
      "x": -1,
      "y": 18,
      "z": 4,
      "name": "Cloth_Roof_White_Flat",
      "rotation": 2
    },
    {
      "x": -1,
      "y": 2,
      "z": 5,
      "name": "Wood_Softwood_Planks_Half",
      "rotation": 8
    },
    {
      "x": -1,
      "y": 3,
      "z": 5,
      "name": "Wood_Softwood_Planks"
    },
    {
      "x": -1,
      "y": 7,
      "z": 5,
      "name": "Wood_Softwood_Planks"
    },
    {
      "x": -1,
      "y": 8,
      "z": 5,
      "name": "Cloth_Roof_Leather_Flat"
    },
    {
      "x": -1,
      "y": 11,
      "z": 5,
      "name": "Cloth_Block_Wool_White"
    },
    {
      "x": -1,
      "y": 12,
      "z": 5,
      "name": "Cloth_Block_Wool_White"
    },
    {
      "x": -1,
      "y": 17,
      "z": 5,
      "name": "Cloth_Block_Wool_White"
    },
    {
      "x": -1,
      "y": 18,
      "z": 5,
      "name": "*Wood_Softwood_Planks_Half_State_Definitions_Block"
    },
    {
      "x": -1,
      "y": 2,
      "z": 6,
      "name": "Wood_Softwood_Planks_Half",
      "rotation": 8
    },
    {
      "x": -1,
      "y": 3,
      "z": 6,
      "name": "Wood_Softwood_Planks"
    },
    {
      "x": -1,
      "y": 4,
      "z": 6,
      "name": "Bench_Furnace",
      "components": {
        "Components": {
          "BenchBlock": {
            "TierLevel": 1,
            "UpgradeItems": []
          },
          "ProcessingBenchBlock": {
            "InputContainer": {
              "Id": "Simple",
              "Capacity": 2,
              "Items": {}
            },
            "FuelContainer": {
              "Id": "Simple",
              "Capacity": 1,
              "Items": {}
            },
            "OutputContainer": {
              "Id": "Simple",
              "Capacity": 4,
              "Items": {}
            },
            "Progress": 0.0,
            "FuelTime": 0.0,
            "Active": false,
            "NextExtra": 2,
            "LastTickGameTime": "0001-01-06T12:03:47.622150798Z"
          }
        }
      },
      "rotation": 1
    },
    {
      "x": -1,
      "y": 5,
      "z": 6,
      "name": "Bench_Furnace",
      "filler": 1024,
      "rotation": 1
    },
    {
      "x": -1,
      "y": 7,
      "z": 6,
      "name": "Wood_Softwood_Planks"
    },
    {
      "x": -1,
      "y": 8,
      "z": 6,
      "name": "Cloth_Roof_Leather_Flat"
    },
    {
      "x": -1,
      "y": 10,
      "z": 6,
      "name": "*Furniture_Kweebec_Lantern_Ceiling_State_Definitions_On"
    },
    {
      "x": -1,
      "y": 11,
      "z": 6,
      "name": "Cloth_Block_Wool_White"
    },
    {
      "x": -1,
      "y": 12,
      "z": 6,
      "name": "Cloth_Block_Wool_White"
    },
    {
      "x": -1,
      "y": 15,
      "z": 6,
      "name": "Deco_SpiderWeb_Full",
      "support": 15
    },
    {
      "x": -1,
      "y": 16,
      "z": 6,
      "name": "Deco_SpiderWeb_Full",
      "support": 15
    },
    {
      "x": -1,
      "y": 17,
      "z": 6,
      "name": "Cloth_Block_Wool_White"
    },
    {
      "x": -1,
      "y": 18,
      "z": 6,
      "name": "Cloth_Roof_White_Flat",
      "rotation": 2
    },
    {
      "x": -1,
      "y": 2,
      "z": 7,
      "name": "Wood_Softwood_Planks_Half",
      "rotation": 8
    },
    {
      "x": -1,
      "y": 3,
      "z": 7,
      "name": "Wood_Softwood_Planks"
    },
    {
      "x": -1,
      "y": 4,
      "z": 7,
      "name": "Bench_Furnace",
      "filler": 32,
      "rotation": 1
    },
    {
      "x": -1,
      "y": 5,
      "z": 7,
      "name": "Bench_Furnace",
      "filler": 1056,
      "rotation": 1
    },
    {
      "x": -1,
      "y": 7,
      "z": 7,
      "name": "Wood_Softwood_Planks"
    },
    {
      "x": -1,
      "y": 8,
      "z": 7,
      "name": "Deco_Inkwell"
    },
    {
      "x": -1,
      "y": 11,
      "z": 7,
      "name": "Cloth_Block_Wool_White"
    },
    {
      "x": -1,
      "y": 12,
      "z": 7,
      "name": "Cloth_Block_Wool_White"
    },
    {
      "x": -1,
      "y": 14,
      "z": 7,
      "name": "Deco_SpiderWeb_Full",
      "support": 15
    },
    {
      "x": -1,
      "y": 15,
      "z": 7,
      "name": "Deco_SpiderWeb_Full",
      "support": 15
    },
    {
      "x": -1,
      "y": 16,
      "z": 7,
      "name": "Deco_SpiderWeb_Full",
      "support": 15
    },
    {
      "x": -1,
      "y": 17,
      "z": 7,
      "name": "Cloth_Block_Wool_White"
    },
    {
      "x": -1,
      "y": 18,
      "z": 7,
      "name": "Cloth_Roof_White_Flat",
      "rotation": 2
    },
    {
      "x": -1,
      "y": 3,
      "z": 8,
      "name": "Wood_Softwood_Stairs",
      "rotation": 10
    },
    {
      "x": -1,
      "y": 4,
      "z": 8,
      "name": "Metal_Iron_Pipe_Large_Corner",
      "support": 15,
      "rotation": 11
    },
    {
      "x": -1,
      "y": 5,
      "z": 8,
      "name": "Metal_Iron_Pipe_Large_Mouthpiece",
      "support": 15
    },
    {
      "x": -1,
      "y": 6,
      "z": 8,
      "name": "Metal_Iron_Pipe_Large_Corner",
      "support": 15
    },
    {
      "x": -1,
      "y": 7,
      "z": 8,
      "name": "Wood_Softwood_Planks"
    },
    {
      "x": -1,
      "y": 8,
      "z": 8,
      "name": "Furniture_Village_Bookcase",
      "rotation": 3
    },
    {
      "x": -1,
      "y": 11,
      "z": 8,
      "name": "Cloth_Block_Wool_White"
    },
    {
      "x": -1,
      "y": 12,
      "z": 8,
      "name": "Cloth_Block_Wool_White"
    },
    {
      "x": -1,
      "y": 16,
      "z": 8,
      "name": "Deco_SpiderWeb_Full",
      "support": 15
    },
    {
      "x": -1,
      "y": 17,
      "z": 8,
      "name": "Cloth_Block_Wool_White"
    },
    {
      "x": -1,
      "y": 18,
      "z": 8,
      "name": "Cloth_Roof_White_Flat",
      "rotation": 2
    },
    {
      "x": -1,
      "y": 4,
      "z": 9,
      "name": "Wood_Softwood_Planks"
    },
    {
      "x": -1,
      "y": 5,
      "z": 9,
      "name": "Metal_Iron_Pipe_Large_Corner",
      "support": 15,
      "rotation": 10
    },
    {
      "x": -1,
      "y": 6,
      "z": 9,
      "name": "Metal_Iron_Ornate"
    },
    {
      "x": -1,
      "y": 7,
      "z": 9,
      "name": "Wood_Softwood_Planks"
    },
    {
      "x": -1,
      "y": 9,
      "z": 9,
      "name": "Cloth_Roof_Leather_Flap",
      "rotation": 2
    },
    {
      "x": -1,
      "y": 10,
      "z": 9,
      "name": "Wood_Softwood_Planks_Half",
      "rotation": 8
    },
    {
      "x": -1,
      "y": 11,
      "z": 9,
      "name": "Cloth_Block_Wool_White"
    },
    {
      "x": -1,
      "y": 17,
      "z": 9,
      "name": "Cloth_Block_Wool_White"
    },
    {
      "x": -1,
      "y": 18,
      "z": 9,
      "name": "*Wood_Softwood_Planks_Half_State_Definitions_Block"
    },
    {
      "x": -1,
      "y": 5,
      "z": 10,
      "name": "Metal_Iron_Pipe_Large_Mouthpiece",
      "support": 15,
      "rotation": 4
    },
    {
      "x": -1,
      "y": 6,
      "z": 10,
      "name": "*Wood_Softwood_Planks_Half_State_Definitions_Block",
      "rotation": 7
    },
    {
      "x": -1,
      "y": 8,
      "z": 10,
      "name": "Wood_Softwood_Stairs",
      "rotation": 2
    },
    {
      "x": -1,
      "y": 9,
      "z": 10,
      "name": "Wood_Softwood_Planks_Half",
      "rotation": 6
    },
    {
      "x": -1,
      "y": 10,
      "z": 10,
      "name": "Wood_Softwood_Stairs"
    },
    {
      "x": -1,
      "y": 11,
      "z": 10,
      "name": "Cloth_Roof_White_Flat"
    },
    {
      "x": -1,
      "y": 12,
      "z": 10,
      "name": "Cloth_Block_Wool_White"
    },
    {
      "x": -1,
      "y": 17,
      "z": 10,
      "name": "Cloth_Block_Wool_White"
    },
    {
      "x": -1,
      "y": 18,
      "z": 10,
      "name": "Cloth_Roof_White_Flat"
    },
    {
      "x": -1,
      "y": 5,
      "z": 11,
      "name": "Metal_Iron_Pipe_Large_Mouthpiece",
      "support": 15,
      "rotation": 4
    },
    {
      "x": -1,
      "y": 7,
      "z": 11,
      "name": "Metal_Bronze_Pipe_Large_Corner",
      "support": 15,
      "rotation": 8
    },
    {
      "x": -1,
      "y": 8,
      "z": 11,
      "name": "Metal_Bronze_Pipe_Large",
      "support": 15,
      "rotation": 8
    },
    {
      "x": -1,
      "y": 9,
      "z": 11,
      "name": "Metal_Bronze_Pipe_Large_Corner",
      "support": 15
    },
    {
      "x": -1,
      "y": 11,
      "z": 11,
